Workbook

Sheet Resumen
C2: Pibank: caso de captación 2027
C4: Escenario seleccionado | D4: =Supuestos!D5 -> Base
C5: ILUSTRACIÓN CONDICIONADA. Preparación interna. No es forecast aprobado ni compromiso de aperturas.
C7: Resultado de seis meses | D7: Caso activo | E7: Unidad
C8: Visitas adicionales | D8: =IF(COUNT(Mensual!F13:K13)=6,SUM(Mensual!F13:K13),"N/D") -> 1067.625 | E8: visitas
C9: Aperturas incrementales | D9: =IF(COUNT(Mensual!F19:K19)=6,SUM(Mensual!F19:K19),"N/D") -> 21.3525 | E9: cuentas
C10: Primer fondeo incremental | D10: =IF(COUNT(Mensual!F23:K23)=6,SUM(Mensual!F23:K23),"N/D") -> 13.879125 | E10: cuentas
C11: Entrada inicial bruta USD equivalente | D11: =IF(COUNT(D10,Supuestos!D10)=2,D10*Supuestos!D10,"N/D") -> 34697.812 | E11: USD eq.
C12: Saldo incremental al cierre | D12: =Mensual!K25 -> 32867.859 | E12: USD eq.
C13: Saldo externo incremental al cierre | D13: =Mensual!K26 -> 23007.502 | E13: USD eq.
C14: Escala / meta cuentas provisional | D14: =IF(AND(COUNT(D10,Supuestos!D8)=2,Supuestos!D8>0),D10/Supuestos!D8,"N/D") -> 0.00091310033 | E14: %
C16: Costo completo programa | D16: =Supuestos!D20 -> N/D | E16: USD
C17: Costo / fondeada incremental | D17: =IF(AND(Supuestos!D16="Sí",COUNT(D16,D10)=2,D16>0,D10>0),D16/D10,"N/D") -> N/D | E17: USD
C18: Valor mínimo / fondeada para equilibrio | D18: =IF(AND(COUNT(D16,D10)=2,D16>0,D10>0),D16/D10,"N/D") -> N/D | E18: USD en 6m
C19: ROI seis meses | D19: =Mensual!K31 -> N/D | E19: %
C20: Payback dentro de seis meses | D20: =IF(COUNT(Mensual!F34:K34)=6,IFERROR(MATCH(1,Mensual!F34:K34,0),"No en 6m"),"N/D") -> N/D | E20: mes
C22: ROI y payback N/D hasta Finance, valor económico y costos completos validados. Saldo no es revenue.
C24: Mes | D24: Visitas extra | E24: Fondeadas extra | F24: Saldo cierre USD eq. | G24: Saldo externo USD eq.
C25: =Mensual!F8 -> 46388 | D25: =Mensual!F13 -> 14.625 | E25: =Mensual!F23 -> 0.190125 | F25: =Mensual!F25 -> 475.3125 | G25: =Mensual!F26 -> 332.71875
C26: =Mensual!G8 -> 46419 | D26: =Mensual!G13 -> 43.875 | E26: =Mensual!G23 -> 0.570375 | F26: =Mensual!G25 -> 1877.4844 | G26: =Mensual!G26 -> 1314.2391
C27: =Mensual!H8 -> 46447 | D27: =Mensual!H13 -> 102.375 | E27: =Mensual!H23 -> 1.330875 | F27: =Mensual!H25 -> 5109.6094 | G27: =Mensual!H26 -> 3576.7266
C28: =Mensual!I8 -> 46478 | D28: =Mensual!I13 -> 175.5 | E28: =Mensual!I23 -> 2.2815 | F28: =Mensual!I25 -> 10551.938 | G28: =Mensual!I26 -> 7386.3562
C29: =Mensual!J8 -> 46508 | D29: =Mensual!J13 -> 292.5 | E29: =Mensual!J23 -> 3.8025 | F29: =Mensual!J25 -> 19535.344 | G29: =Mensual!J26 -> 13674.741
C30: =Mensual!K8 -> 46539 | D30: =Mensual!K13 -> 438.75 | E30: =Mensual!K23 -> 5.70375 | F30: =Mensual!K25 -> 32867.859 | G30: =Mensual!K26 -> 23007.502
C32: Inicio enero 2027 y seis meses son calendario de prueba. Meta USD inferida; moneda y periodo sin confirmación.
C33: Producto público Soles. USD es equivalencia aritmética; no supone cuenta en dólares ni tipo de cambio.
C34: Demanda 3.900 es proxy histórico, no forecast 2027. Relevancia 75%, referencia, captura y embudo son ilustrativos.
C36: Cambiar selector en Supuestos D4 para recalcular Conservador/Base/Favorable con el mismo build.

Sheet Supuestos
C2: Inputs editables y escenarios
C4: Selector escenario (1 / 2 / 3) | D4: 2
C5: Nombre activo | D5: =CHOOSE(D4,"Conservador","Base","Favorable") -> Base
C6: 1 Conservador, 2 Base, 3 Favorable. Los nombres distinguen pruebas ilustrativas, no probabilidades.
C8: Meta cuentas provisional | D8: 15200
C9: Meta USD provisional | D9: 38000000
C10: Ticket USD equivalente provisional | D10: 2500
C11: Inicio ilustrativo | D11: 46388
C12: Meta USD inferida de 15.200 × US$2.500. Moneda y periodo de la meta no confirmados.
C13: Factor relevancia/eligibilidad ilustrativo | D13: 0.75
C14: Finance validó contribución neta | D14: No
C15: Contribución neta anual / USD externo
C16: Costos validados | D16: No
C17: Capacidad con reserva (horas) | D17: 995.9
F18: =EDATE($D$11,0) -> 46388 | G18: =EDATE($D$11,1) -> 46419 | H18: =EDATE($D$11,2) -> 46447 | I18: =EDATE($D$11,3) -> 46478 | J18: =EDATE($D$11,4) -> 46508 | K18: =EDATE($D$11,5) -> 46539
C19: Inversión cliente USD / mes (pendiente)
C20: Inversión seis meses, si completa | D20: =IF(COUNT(F19:K19)=6,SUM(F19:K19),"N/D") -> N/D
C21: Costo interno Efeonce USD (pendiente)
C23: Captura adicional de demanda activo | F23: =IF(CHOOSE($D$4,COUNT(F24),COUNT(F25),COUNT(F26))=1,CHOOSE($D$4,F24,F25,F26),"N/D") -> 0.005 | G23: =IF(CHOOSE($D$4,COUNT(G24),COUNT(G25),COUNT(G26))=1,CHOOSE($D$4,G24,G25,G26),"N/D") -> 0.015 | H23: =IF(CHOOSE($D$4,COUNT(H24),COUNT(H25),COUNT(H26))=1,CHOOSE($D$4,H24,H25,H26),"N/D") -> 0.035 | I23: =IF(CHOOSE($D$4,COUNT(I24),COUNT(I25),COUNT(I26))=1,CHOOSE($D$4,I24,I25,I26),"N/D") -> 0.06 | J23: =IF(CHOOSE($D$4,COUNT(J24),COUNT(J25),COUNT(J26))=1,CHOOSE($D$4,J24,J25,J26),"N/D") -> 0.1 | K23: =IF(CHOOSE($D$4,COUNT(K24),COUNT(K25),COUNT(K26))=1,CHOOSE($D$4,K24,K25,K26),"N/D") -> 0.15
C24: Conservador | F24: 0.0025 | G24: 0.005 | H24: 0.0125 | I24: 0.025 | J24: 0.04 | K24: 0.06
C25: Base | F25: 0.005 | G25: 0.015 | H25: 0.035 | I25: 0.06 | J25: 0.1 | K25: 0.15
C26: Favorable | F26: 0.01 | G26: 0.025 | H26: 0.05 | I26: 0.1 | J26: 0.175 | K26: 0.25
C28: Captura referencia sin programa activo | F28: =IF(CHOOSE($D$4,COUNT(F29),COUNT(F30),COUNT(F31))=1,CHOOSE($D$4,F29,F30,F31),"N/D") -> 0.01 | G28: =IF(CHOOSE($D$4,COUNT(G29),COUNT(G30),COUNT(G31))=1,CHOOSE($D$4,G29,G30,G31),"N/D") -> 0.01 | H28: =IF(CHOOSE($D$4,COUNT(H29),COUNT(H30),COUNT(H31))=1,CHOOSE($D$4,H29,H30,H31),"N/D") -> 0.01 | I28: =IF(CHOOSE($D$4,COUNT(I29),COUNT(I30),COUNT(I31))=1,CHOOSE($D$4,I29,I30,I31),"N/D") -> 0.01 | J28: =IF(CHOOSE($D$4,COUNT(J29),COUNT(J30),COUNT(J31))=1,CHOOSE($D$4,J29,J30,J31),"N/D") -> 0.01 | K28: =IF(CHOOSE($D$4,COUNT(K29),COUNT(K30),COUNT(K31))=1,CHOOSE($D$4,K29,K30,K31),"N/D") -> 0.01
C29: Conservador | F29: 0.01 | G29: 0.01 | H29: 0.01 | I29: 0.01 | J29: 0.01 | K29: 0.01
C30: Base | F30: 0.01 | G30: 0.01 | H30: 0.01 | I30: 0.01 | J30: 0.01 | K30: 0.01
C31: Favorable | F31: 0.01 | G31: 0.01 | H31: 0.01 | I31: 0.01 | J31: 0.01 | K31: 0.01
C33: Visita a apertura completada activo | F33: =IF(CHOOSE($D$4,COUNT(F34),COUNT(F35),COUNT(F36))=1,CHOOSE($D$4,F34,F35,F36),"N/D") -> 0.02 | G33: =IF(CHOOSE($D$4,COUNT(G34),COUNT(G35),COUNT(G36))=1,CHOOSE($D$4,G34,G35,G36),"N/D") -> 0.02 | H33: =IF(CHOOSE($D$4,COUNT(H34),COUNT(H35),COUNT(H36))=1,CHOOSE($D$4,H34,H35,H36),"N/D") -> 0.02 | I33: =IF(CHOOSE($D$4,COUNT(I34),COUNT(I35),COUNT(I36))=1,CHOOSE($D$4,I34,I35,I36),"N/D") -> 0.02 | J33: =IF(CHOOSE($D$4,COUNT(J34),COUNT(J35),COUNT(J36))=1,CHOOSE($D$4,J34,J35,J36),"N/D") -> 0.02 | K33: =IF(CHOOSE($D$4,COUNT(K34),COUNT(K35),COUNT(K36))=1,CHOOSE($D$4,K34,K35,K36),"N/D") -> 0.02
C34: Conservador | F34: 0.01 | G34: 0.01 | H34: 0.01 | I34: 0.01 | J34: 0.01 | K34: 0.01
C35: Base | F35: 0.02 | G35: 0.02 | H35: 0.02 | I35: 0.02 | J35: 0.02 | K35: 0.02
C36: Favorable | F36: 0.03 | G36: 0.03 | H36: 0.03 | I36: 0.03 | J36: 0.03 | K36: 0.03
C38: Apertura a primer fondeo activo | F38: =IF(CHOOSE($D$4,COUNT(F39),COUNT(F40),COUNT(F41))=1,CHOOSE($D$4,F39,F40,F41),"N/D") -> 0.65 | G38: =IF(CHOOSE($D$4,COUNT(G39),COUNT(G40),COUNT(G41))=1,CHOOSE($D$4,G39,G40,G41),"N/D") -> 0.65 | H38: =IF(CHOOSE($D$4,COUNT(H39),COUNT(H40),COUNT(H41))=1,CHOOSE($D$4,H39,H40,H41),"N/D") -> 0.65 | I38: =IF(CHOOSE($D$4,COUNT(I39),COUNT(I40),COUNT(I41))=1,CHOOSE($D$4,I39,I40,I41),"N/D") -> 0.65 | J38: =IF(CHOOSE($D$4,COUNT(J39),COUNT(J40),COUNT(J41))=1,CHOOSE($D$4,J39,J40,J41),"N/D") -> 0.65 | K38: =IF(CHOOSE($D$4,COUNT(K39),COUNT(K40),COUNT(K41))=1,CHOOSE($D$4,K39,K40,K41),"N/D") -> 0.65
C39: Conservador | F39: 0.5 | G39: 0.5 | H39: 0.5 | I39: 0.5 | J39: 0.5 | K39: 0.5
C40: Base | F40: 0.65 | G40: 0.65 | H40: 0.65 | I40: 0.65 | J40: 0.65 | K40: 0.65
C41: Favorable | F41: 0.75 | G41: 0.75 | H41: 0.75 | I41: 0.75 | J41: 0.75 | K41: 0.75
C43: Demanda mensual (búsquedas, no personas) activo | F43: =IF(CHOOSE($D$4,COUNT(F44),COUNT(F45),COUNT(F46))=1,CHOOSE($D$4,F44,F45,F46),"N/D") -> 3900 | G43: =IF(CHOOSE($D$4,COUNT(G44),COUNT(G45),COUNT(G46))=1,CHOOSE($D$4,G44,G45,G46),"N/D") -> 3900 | H43: =IF(CHOOSE($D$4,COUNT(H44),COUNT(H45),COUNT(H46))=1,CHOOSE($D$4,H44,H45,H46),"N/D") -> 3900 | I43: =IF(CHOOSE($D$4,COUNT(I44),COUNT(I45),COUNT(I46))=1,CHOOSE($D$4,I44,I45,I46),"N/D") -> 3900 | J43: =IF(CHOOSE($D$4,COUNT(J44),COUNT(J45),COUNT(J46))=1,CHOOSE($D$4,J44,J45,J46),"N/D") -> 3900 | K43: =IF(CHOOSE($D$4,COUNT(K44),COUNT(K45),COUNT(K46))=1,CHOOSE($D$4,K44,K45,K46),"N/D") -> 3900
C44: Conservador | F44: 3900 | G44: 3900 | H44: 3900 | I44: 3900 | J44: 3900 | K44: 3900
C45: Base | F45: 3900 | G45: 3900 | H45: 3900 | I45: 3900 | J45: 3900 | K45: 3900
C46: Favorable | F46: 3900 | G46: 3900 | H46: 3900 | I46: 3900 | J46: 3900 | K46: 3900
C48: Saldo relativo a 30 días activo | F48: =IF(CHOOSE($D$4,COUNT(F49),COUNT(F50),COUNT(F51))=1,CHOOSE($D$4,F49,F50,F51),"N/D") -> 0.95 | G48: =IF(CHOOSE($D$4,COUNT(G49),COUNT(G50),COUNT(G51))=1,CHOOSE($D$4,G49,G50,G51),"N/D") -> 0.95 | H48: =IF(CHOOSE($D$4,COUNT(H49),COUNT(H50),COUNT(H51))=1,CHOOSE($D$4,H49,H50,H51),"N/D") -> 0.95 | I48: =IF(CHOOSE($D$4,COUNT(I49),COUNT(I50),COUNT(I51))=1,CHOOSE($D$4,I49,I50,I51),"N/D") -> 0.95 | J48: =IF(CHOOSE($D$4,COUNT(J49),COUNT(J50),COUNT(J51))=1,CHOOSE($D$4,J49,J50,J51),"N/D") -> 0.95 | K48: =IF(CHOOSE($D$4,COUNT(K49),COUNT(K50),COUNT(K51))=1,CHOOSE($D$4,K49,K50,K51),"N/D") -> 0.95
C49: Conservador | F49: 0.9 | G49: 0.9 | H49: 0.9 | I49: 0.9 | J49: 0.9 | K49: 0.9
...

Sheet Mensual
C2: Captación incremental: seis meses
C4: Escenario seleccionado | D4: =Supuestos!D5 -> Base
C7: Indicador | D7: Unidad | F7: Mes 1 | G7: Mes 2 | H7: Mes 3 | I7: Mes 4 | J7: Mes 5 | K7: Mes 6
F8: =Supuestos!F18 -> 46388 | G8: =Supuestos!G18 -> 46419 | H8: =Supuestos!H18 -> 46447 | I8: =Supuestos!I18 -> 46478 | J8: =Supuestos!J18 -> 46508 | K8: =Supuestos!K18 -> 46539
C9: Proxy demanda histórica trasladada | D9: búsquedas | F9: =Supuestos!F43 -> 3900 | G9: =Supuestos!G43 -> 3900 | H9: =Supuestos!H43 -> 3900 | I9: =Supuestos!I43 -> 3900 | J9: =Supuestos!J43 -> 3900 | K9: =Supuestos!K43 -> 3900
C10: Captura referencia | D10: % | F10: =Supuestos!F28 -> 0.01 | G10: =Supuestos!G28 -> 0.01 | H10: =Supuestos!H28 -> 0.01 | I10: =Supuestos!I28 -> 0.01 | J10: =Supuestos!J28 -> 0.01 | K10: =Supuestos!K28 -> 0.01
C11: Captura adicional programa | D11: % | F11: =Supuestos!F23 -> 0.005 | G11: =Supuestos!G23 -> 0.015 | H11: =Supuestos!H23 -> 0.035 | I11: =Supuestos!I23 -> 0.06 | J11: =Supuestos!J23 -> 0.1 | K11: =Supuestos!K23 -> 0.15
C12: Visitas referencia | D12: visitas | F12: =IF(COUNT(F15,F10)=2,F15*F10,"N/D") -> 29.25 | G12: =IF(COUNT(G15,G10)=2,G15*G10,"N/D") -> 29.25 | H12: =IF(COUNT(H15,H10)=2,H15*H10,"N/D") -> 29.25 | I12: =IF(COUNT(I15,I10)=2,I15*I10,"N/D") -> 29.25 | J12: =IF(COUNT(J15,J10)=2,J15*J10,"N/D") -> 29.25 | K12: =IF(COUNT(K15,K10)=2,K15*K10,"N/D") -> 29.25
C13: Visitas adicionales | D13: visitas | F13: =IF(COUNT(F15,F11)=2,F15*F11,"N/D") -> 14.625 | G13: =IF(COUNT(G15,G11)=2,G15*G11,"N/D") -> 43.875 | H13: =IF(COUNT(H15,H11)=2,H15*H11,"N/D") -> 102.375 | I13: =IF(COUNT(I15,I11)=2,I15*I11,"N/D") -> 175.5 | J13: =IF(COUNT(J15,J11)=2,J15*J11,"N/D") -> 292.5 | K13: =IF(COUNT(K15,K11)=2,K15*K11,"N/D") -> 438.75
C14: Visitas con programa | D14: visitas | F14: =IF(COUNT(F12,F13)=2,SUM(F12:F13),"N/D") -> 43.875 | G14: =IF(COUNT(G12,G13)=2,SUM(G12:G13),"N/D") -> 73.125 | H14: =IF(COUNT(H12,H13)=2,SUM(H12:H13),"N/D") -> 131.625 | I14: =IF(COUNT(I12,I13)=2,SUM(I12:I13),"N/D") -> 204.75 | J14: =IF(COUNT(J12,J13)=2,SUM(J12:J13),"N/D") -> 321.75 | K14: =IF(COUNT(K12,K13)=2,SUM(K12:K13),"N/D") -> 468
C15: Demanda × relevancia ilustrativa | D15: búsquedas | F15: =IF(COUNT(F9,Supuestos!$D$13)=2,F9*Supuestos!$D$13,"N/D") -> 2925 | G15: =IF(COUNT(G9,Supuestos!$D$13)=2,G9*Supuestos!$D$13,"N/D") -> 2925 | H15: =IF(COUNT(H9,Supuestos!$D$13)=2,H9*Supuestos!$D$13,"N/D") -> 2925 | I15: =IF(COUNT(I9,Supuestos!$D$13)=2,I9*Supuestos!$D$13,"N/D") -> 2925 | J15: =IF(COUNT(J9,Supuestos!$D$13)=2,J9*Supuestos!$D$13,"N/D") -> 2925 | K15: =IF(COUNT(K9,Supuestos!$D$13)=2,K9*Supuestos!$D$13,"N/D") -> 2925
C16: Visita → apertura | D16: % | F16: =Supuestos!F33 -> 0.02 | G16: =Supuestos!G33 -> 0.02 | H16: =Supuestos!H33 -> 0.02 | I16: =Supuestos!I33 -> 0.02 | J16: =Supuestos!J33 -> 0.02 | K16: =Supuestos!K33 -> 0.02
C17: Aperturas referencia | D17: cuentas | F17: =IF(COUNT(F12,F16)=2,F12*F16,"N/D") -> 0.585 | G17: =IF(COUNT(G12,G16)=2,G12*G16,"N/D") -> 0.585 | H17: =IF(COUNT(H12,H16)=2,H12*H16,"N/D") -> 0.585 | I17: =IF(COUNT(I12,I16)=2,I12*I16,"N/D") -> 0.585 | J17: =IF(COUNT(J12,J16)=2,J12*J16,"N/D") -> 0.585 | K17: =IF(COUNT(K12,K16)=2,K12*K16,"N/D") -> 0.585
C18: Aperturas con programa | D18: cuentas | F18: =IF(COUNT(F14,F16)=2,F14*F16,"N/D") -> 0.8775 | G18: =IF(COUNT(G14,G16)=2,G14*G16,"N/D") -> 1.4625 | H18: =IF(COUNT(H14,H16)=2,H14*H16,"N/D") -> 2.6325 | I18: =IF(COUNT(I14,I16)=2,I14*I16,"N/D") -> 4.095 | J18: =IF(COUNT(J14,J16)=2,J14*J16,"N/D") -> 6.435 | K18: =IF(COUNT(K14,K16)=2,K14*K16,"N/D") -> 9.36
C19: Aperturas incrementales | D19: cuentas | F19: =IF(COUNT(F18,F17)=2,F18-F17,"N/D") -> 0.2925 | G19: =IF(COUNT(G18,G17)=2,G18-G17,"N/D") -> 0.8775 | H19: =IF(COUNT(H18,H17)=2,H18-H17,"N/D") -> 2.0475 | I19: =IF(COUNT(I18,I17)=2,I18-I17,"N/D") -> 3.51 | J19: =IF(COUNT(J18,J17)=2,J18-J17,"N/D") -> 5.85 | K19: =IF(COUNT(K18,K17)=2,K18-K17,"N/D") -> 8.775
C20: Apertura → fondeo | D20: % | F20: =Supuestos!F38 -> 0.65 | G20: =Supuestos!G38 -> 0.65 | H20: =Supuestos!H38 -> 0.65 | I20: =Supuestos!I38 -> 0.65 | J20: =Supuestos!J38 -> 0.65 | K20: =Supuestos!K38 -> 0.65
C21: Fondeadas referencia | D21: cuentas | F21: =IF(COUNT(F17,F20)=2,F17*F20,"N/D") -> 0.38025 | G21: =IF(COUNT(G17,G20)=2,G17*G20,"N/D") -> 0.38025 | H21: =IF(COUNT(H17,H20)=2,H17*H20,"N/D") -> 0.38025 | I21: =IF(COUNT(I17,I20)=2,I17*I20,"N/D") -> 0.38025 | J21: =IF(COUNT(J17,J20)=2,J17*J20,"N/D") -> 0.38025 | K21: =IF(COUNT(K17,K20)=2,K17*K20,"N/D") -> 0.38025
C22: Fondeadas con programa | D22: cuentas | F22: =IF(COUNT(F18,F20)=2,F18*F20,"N/D") -> 0.570375 | G22: =IF(COUNT(G18,G20)=2,G18*G20,"N/D") -> 0.950625 | H22: =IF(COUNT(H18,H20)=2,H18*H20,"N/D") -> 1.711125 | I22: =IF(COUNT(I18,I20)=2,I18*I20,"N/D") -> 2.66175 | J22: =IF(COUNT(J18,J20)=2,J18*J20,"N/D") -> 4.18275 | K22: =IF(COUNT(K18,K20)=2,K18*K20,"N/D") -> 6.084
C23: Fondeadas incrementales | D23: cuentas | F23: =IF(COUNT(F22,F21)=2,F22-F21,"N/D") -> 0.190125 | G23: =IF(COUNT(G22,G21)=2,G22-G21,"N/D") -> 0.570375 | H23: =IF(COUNT(H22,H21)=2,H22-H21,"N/D") -> 1.330875 | I23: =IF(COUNT(I22,I21)=2,I22-I21,"N/D") -> 2.2815 | J23: =IF(COUNT(J22,J21)=2,J22-J21,"N/D") -> 3.8025 | K23: =IF(COUNT(K22,K21)=2,K22-K21,"N/D") -> 5.70375
C25: Saldo incremental al cierre | D25: USD eq. | F25: =Cohortes!K15 -> 475.3125 | G25: =Cohortes!L15 -> 1877.4844 | H25: =Cohortes!M15 -> 5109.6094 | I25: =Cohortes!N15 -> 10551.938 | J25: =Cohortes!O15 -> 19535.344 | K25: =Cohortes!P15 -> 32867.859
C26: Saldo externo incremental | D26: USD eq. | F26: =IF(COUNT(F25,Supuestos!F63)=2,F25*Supuestos!F63,"N/D") -> 332.71875 | G26: =IF(COUNT(G25,Supuestos!G63)=2,G25*Supuestos!G63,"N/D") -> 1314.2391 | H26: =IF(COUNT(H25,Supuestos!H63)=2,H25*Supuestos!H63,"N/D") -> 3576.7266 | I26: =IF(COUNT(I25,Supuestos!I63)=2,I25*Supuestos!I63,"N/D") -> 7386.3562 | J26: =IF(COUNT(J25,Supuestos!J63)=2,J25*Supuestos!J63,"N/D") -> 13674.741 | K26: =IF(COUNT(K25,Supuestos!K63)=2,K25*Supuestos!K63,"N/D") -> 23007.502
C27: Inversión cliente pendiente | D27: USD | F27: =IF(COUNT(Supuestos!F19)=1,Supuestos!F19,"N/D") -> N/D | G27: =IF(COUNT(Supuestos!G19)=1,Supuestos!G19,"N/D") -> N/D | H27: =IF(COUNT(Supuestos!H19)=1,Supuestos!H19,"N/D") -> N/D | I27: =IF(COUNT(Supuestos!I19)=1,Supuestos!I19,"N/D") -> N/D | J27: =IF(COUNT(Supuestos!J19)=1,Supuestos!J19,"N/D") -> N/D | K27: =IF(COUNT(Supuestos!K19)=1,Supuestos!K19,"N/D") -> N/D
C28: Inversión acumulada | D28: USD | F28: =IF(COUNT($F27:F27)=1,SUM($F27:F27),"N/D") -> N/D | G28: =IF(COUNT($F27:G27)=2,SUM($F27:G27),"N/D") -> N/D | H28: =IF(COUNT($F27:H27)=3,SUM($F27:H27),"N/D") -> N/D | I28: =IF(COUNT($F27:I27)=4,SUM($F27:I27),"N/D") -> N/D | J28: =IF(COUNT($F27:J27)=5,SUM($F27:J27),"N/D") -> N/D | K28: =IF(COUNT($F27:K27)=6,SUM($F27:K27),"N/D") -> N/D
C29: Contribución neta mensual | D29: USD | F29: =IF(AND(Supuestos!$D$14="Sí",COUNT(Supuestos!$D$15,F26)=2),F26*Supuestos!$D$15/12,"N/D") -> N/D | G29: =IF(AND(Supuestos!$D$14="Sí",COUNT(Supuestos!$D$15,G26)=2),G26*Supuestos!$D$15/12,"N/D") -> N/D | H29: =IF(AND(Supuestos!$D$14="Sí",COUNT(Supuestos!$D$15,H26)=2),H26*Supuestos!$D$15/12,"N/D") -> N/D | I29: =IF(AND(Supuestos!$D$14="Sí",COUNT(Supuestos!$D$15,I26)=2),I26*Supuestos!$D$15/12,"N/D") -> N/D | J29: =IF(AND(Supuestos!$D$14="Sí",COUNT(Supuestos!$D$15,J26)=2),J26*Supuestos!$D$15/12,"N/D") -> N/D | K29: =IF(AND(Supuestos!$D$14="Sí",COUNT(Supuestos!$D$15,K26)=2),K26*Supuestos!$D$15/12,"N/D") -> N/D
C30: Contribución acumulada | D30: USD | F30: =IF(COUNT($F29:F29)=1,SUM($F29:F29),"N/D") -> N/D | G30: =IF(COUNT($F29:G29)=2,SUM($F29:G29),"N/D") -> N/D | H30: =IF(COUNT($F29:H29)=3,SUM($F29:H29),"N/D") -> N/D | I30: =IF(COUNT($F29:I29)=4,SUM($F29:I29),"N/D") -> N/D | J30: =IF(COUNT($F29:J29)=5,SUM($F29:J29),"N/D") -> N/D | K30: =IF(COUNT($F29:K29)=6,SUM($F29:K29),"N/D") -> N/D
C31: ROI acumulado | D31: % | F31: =IF(AND(Supuestos!$D$14="Sí",Supuestos!$D$16="Sí",COUNT(F28,F30)=2,F28>0),(F30-F28)/F28,"N/D") -> N/D | G31: =IF(AND(Supuestos!$D$14="Sí",Supuestos!$D$16="Sí",COUNT(G28,G30)=2,G28>0),(G30-G28)/G28,"N/D") -> N/D | H31: =IF(AND(Supuestos!$D$14="Sí",Supuestos!$D$16="Sí",COUNT(H28,H30)=2,H28>0),(H30-H28)/H28,"N/D") -> N/D | I31: =IF(AND(Supuestos!$D$14="Sí",Supuestos!$D$16="Sí",COUNT(I28,I30)=2,I28>0),(I30-I28)/I28,"N/D") -> N/D | J31: =IF(AND(Supuestos!$D$14="Sí",Supuestos!$D$16="Sí",COUNT(J28,J30)=2,J28>0),(J30-J28)/J28,"N/D") -> N/D | K31: =IF(AND(Supuestos!$D$14="Sí",Supuestos!$D$16="Sí",COUNT(K28,K30)=2,K28>0),(K30-K28)/K28,"N/D") -> N/D
C32: Valor menos inversión acumulado | D32: USD | F32: =IF(AND(Supuestos!$D$14="Sí",Supuestos!$D$16="Sí",COUNT(F28,F30)=2,F28>0),F30-F28,"N/D") -> N/D | G32: =IF(AND(Supuestos!$D$14="Sí",Supuestos!$D$16="Sí",COUNT(G28,G30)=2,G28>0),G30-G28,"N/D") -> N/D | H32: =IF(AND(Supuestos!$D$14="Sí",Supuestos!$D$16="Sí",COUNT(H28,H30)=2,H28>0),H30-H28,"N/D") -> N/D | I32: =IF(AND(Supuestos!$D$14="Sí",Supuestos!$D$16="Sí",COUNT(I28,I30)=2,I28>0),I30-I28,"N/D") -> N/D | J32: =IF(AND(Supuestos!$D$14="Sí",Supuestos!$D$16="Sí",COUNT(J28,J30)=2,J28>0),J30-J28,"N/D") -> N/D | K32: =IF(AND(Supuestos!$D$14="Sí",Supuestos!$D$16="Sí",COUNT(K28,K30)=2,K28>0),K30-K28,"N/D") -> N/D
C34: Recuperación alcanzada | D34: 0/1 | F34: =IF(COUNT(F32)=1,IF(F32>=0,1,0),"N/D") -> N/D | G34: =IF(COUNT(G32)=1,IF(G32>=0,1,0),"N/D") -> N/D | H34: =IF(COUNT(H32)=1,IF(H32>=0,1,0),"N/D") -> N/D | I34: =IF(COUNT(I32)=1,IF(I32>=0,1,0),"N/D") -> N/D | J34: =IF(COUNT(J32)=1,IF(J32>=0,1,0),"N/D") -> N/D | K34: =IF(COUNT(K32)=1,IF(K32>=0,1,0),"N/D") -> N/D
C36: Referencia también es ilustrativa. No representa tráfico actual ni pérdidas históricas desde el lanzamiento.
C37: Contribución valorada sólo sobre saldo externo. Ninguna apertura se atribuye a una cita de IA.

Sheet Cohortes
C2: Saldo de cohortes incrementales
C4: Escenario seleccionado | D4: =Supuestos!D5 -> Base
C7: Cohorte | D7: Fondeadas inc. | E7: Ticket USD eq. | F7: Relativo 30d | G7: Relativo 60d | H7: Relativo 90d | K7: M1 | L7: M2 | M7: M3 | N7: M4 | O7: M5 | P7: M6
C8: =Supuestos!F18 -> 46388 | D8: =Mensual!F23 -> 0.190125 | E8: =IF(COUNT(Supuestos!$D$10)=1,Supuestos!$D$10,"N/D") -> 2500 | F8: =Supuestos!F48 -> 0.95 | G8: =Supuestos!F53 -> 0.9 | H8: =Supuestos!F58 -> 0.85 | K8: =IF(COUNT($D8,$E8)=2,$D8*$E8,"N/D") -> 475.3125 | L8: =IF(COUNT($D8,$E8,$F8)=3,$D8*$E8*$F8,"N/D") -> 451.54688 | M8: =IF(COUNT($D8,$E8,$G8)=3,$D8*$E8*$G8,"N/D") -> 427.78125 | N8: =IF(COUNT($D8,$E8,$H8)=3,$D8*$E8*$H8,"N/D") -> 404.01562 | O8: =IF(COUNT($D8,$E8,$H8)=3,$D8*$E8*$H8,"N/D") -> 404.01562 | P8: =IF(COUNT($D8,$E8,$H8)=3,$D8*$E8*$H8,"N/D") -> 404.01562
C9: =Supuestos!G18 -> 46419 | D9: =Mensual!G23 -> 0.570375 | E9: =IF(COUNT(Supuestos!$D$10)=1,Supuestos!$D$10,"N/D") -> 2500 | F9: =Supuestos!G48 -> 0.95 | G9: =Supuestos!G53 -> 0.9 | H9: =Supuestos!G58 -> 0.85 | K9: =0 -> 0 | L9: =IF(COUNT($D9,$E9)=2,$D9*$E9,"N/D") -> 1425.9375 | M9: =IF(COUNT($D9,$E9,$F9)=3,$D9*$E9*$F9,"N/D") -> 1354.6406 | N9: =IF(COUNT($D9,$E9,$G9)=3,$D9*$E9*$G9,"N/D") -> 1283.3438 | O9: =IF(COUNT($D9,$E9,$H9)=3,$D9*$E9*$H9,"N/D") -> 1212.0469 | P9: =IF(COUNT($D9,$E9,$H9)=3,$D9*$E9*$H9,"N/D") -> 1212.0469
C10: =Supuestos!H18 -> 46447 | D10: =Mensual!H23 -> 1.330875 | E10: =IF(COUNT(Supuestos!$D$10)=1,Supuestos!$D$10,"N/D") -> 2500 | F10: =Supuestos!H48 -> 0.95 | G10: =Supuestos!H53 -> 0.9 | H10: =Supuestos!H58 -> 0.85 | K10: =0 -> 0 | L10: =0 -> 0 | M10: =IF(COUNT($D10,$E10)=2,$D10*$E10,"N/D") -> 3327.1875 | N10: =IF(COUNT($D10,$E10,$F10)=3,$D10*$E10*$F10,"N/D") -> 3160.8281 | O10: =IF(COUNT($D10,$E10,$G10)=3,$D10*$E10*$G10,"N/D") -> 2994.4688 | P10: =IF(COUNT($D10,$E10,$H10)=3,$D10*$E10*$H10,"N/D") -> 2828.1094
C11: =Supuestos!I18 -> 46478 | D11: =Mensual!I23 -> 2.2815 | E11: =IF(COUNT(Supuestos!$D$10)=1,Supuestos!$D$10,"N/D") -> 2500 | F11: =Supuestos!I48 -> 0.95 | G11: =Supuestos!I53 -> 0.9 | H11: =Supuestos!I58 -> 0.85 | K11: =0 -> 0 | L11: =0 -> 0 | M11: =0 -> 0 | N11: =IF(COUNT($D11,$E11)=2,$D11*$E11,"N/D") -> 5703.75 | O11: =IF(COUNT($D11,$E11,$F11)=3,$D11*$E11*$F11,"N/D") -> 5418.5625 | P11: =IF(COUNT($D11,$E11,$G11)=3,$D11*$E11*$G11,"N/D") -> 5133.375
C12: =Supuestos!J18 -> 46508 | D12: =Mensual!J23 -> 3.8025 | E12: =IF(COUNT(Supuestos!$D$10)=1,Supuestos!$D$10,"N/D") -> 2500 | F12: =Supuestos!J48 -> 0.95 | G12: =Supuestos!J53 -> 0.9 | H12: =Supuestos!J58 -> 0.85 | K12: =0 -> 0 | L12: =0 -> 0 | M12: =0 -> 0 | N12: =0 -> 0 | O12: =IF(COUNT($D12,$E12)=2,$D12*$E12,"N/D") -> 9506.25 | P12: =IF(COUNT($D12,$E12,$F12)=3,$D12*$E12*$F12,"N/D") -> 9030.9375
C13: =Supuestos!K18 -> 46539 | D13: =Mensual!K23 -> 5.70375 | E13: =IF(COUNT(Supuestos!$D$10)=1,Supuestos!$D$10,"N/D") -> 2500 | F13: =Supuestos!K48 -> 0.95 | G13: =Supuestos!K53 -> 0.9 | H13: =Supuestos!K58 -> 0.85 | K13: =0 -> 0 | L13: =0 -> 0 | M13: =0 -> 0 | N13: =0 -> 0 | O13: =0 -> 0 | P13: =IF(COUNT($D13,$E13)=2,$D13*$E13,"N/D") -> 14259.375
C15: Saldo cierre USD eq. | K15: =IF(COUNT(K8:K13)=6,SUM(K8:K13),"N/D") -> 475.3125 | L15: =IF(COUNT(L8:L13)=6,SUM(L8:L13),"N/D") -> 1877.4844 | M15: =IF(COUNT(M8:M13)=6,SUM(M8:M13),"N/D") -> 5109.6094 | N15: =IF(COUNT(N8:N13)=6,SUM(N8:N13),"N/D") -> 10551.938 | O15: =IF(COUNT(O8:O13)=6,SUM(O8:O13),"N/D") -> 19535.344 | P15: =IF(COUNT(P8:P13)=6,SUM(P8:P13),"N/D") -> 32867.859
C18: Saldo relativo incluye ceros/retiros por cuenta original. Curva ilustrativa; sin datos bancarios observados.
C21: Cohorte | D21: Cuentas iniciales | E21: Saldo a 30 días | F21: Saldo a 60 días | G21: Saldo a 90 días
C22: =C8 -> 46388 | D22: =D8 -> 0.190125 | E22: =IF(COUNT($D8,$E8,$F8)=3,$D8*$E8*$F8,"N/D") -> 451.54688 | F22: =IF(COUNT($D8,$E8,$G8)=3,$D8*$E8*$G8,"N/D") -> 427.78125 | G22: =IF(COUNT($D8,$E8,$H8)=3,$D8*$E8*$H8,"N/D") -> 404.01562
C23: =C9 -> 46419 | D23: =D9 -> 0.570375 | E23: =IF(COUNT($D9,$E9,$F9)=3,$D9*$E9*$F9,"N/D") -> 1354.6406 | F23: =IF(COUNT($D9,$E9,$G9)=3,$D9*$E9*$G9,"N/D") -> 1283.3438 | G23: =IF(COUNT($D9,$E9,$H9)=3,$D9*$E9*$H9,"N/D") -> 1212.0469
C24: =C10 -> 46447 | D24: =D10 -> 1.330875 | E24: =IF(COUNT($D10,$E10,$F10)=3,$D10*$E10*$F10,"N/D") -> 3160.8281 | F24: =IF(COUNT($D10,$E10,$G10)=3,$D10*$E10*$G10,"N/D") -> 2994.4688 | G24: =IF(COUNT($D10,$E10,$H10)=3,$D10*$E10*$H10,"N/D") -> 2828.1094
C25: =C11 -> 46478 | D25: =D11 -> 2.2815 | E25: =IF(COUNT($D11,$E11,$F11)=3,$D11*$E11*$F11,"N/D") -> 5418.5625 | F25: =IF(COUNT($D11,$E11,$G11)=3,$D11*$E11*$G11,"N/D") -> 5133.375 | G25: Fuera 6m
C26: =C12 -> 46508 | D26: =D12 -> 3.8025 | E26: =IF(COUNT($D12,$E12,$F12)=3,$D12*$E12*$F12,"N/D") -> 9030.9375 | F26: Fuera 6m | G26: Fuera 6m
C27: =C13 -> 46539 | D27: =D13 -> 5.70375 | E27: Fuera 6m | F27: Fuera 6m | G27: Fuera 6m
C29: 30/60/90 días son proxies mensuales desde primer fondeo. Los que caen después del semestre figuran Fuera 6m.
C30: La suma de depósitos iniciales es entrada bruta modelada. El saldo cierre es stock retenido; no se suman stocks.
C31: Cuentas fraccionarias son expectativas matemáticas. No representan personas reales ni cuentas observadas.

Sheet Sensibilidad
C2: Sensibilidad y escala requerida
C4: Escenario seleccionado | D4: =Supuestos!D5 -> Base
C7: Banda meta | D7: Cuentas requeridas | E7: Visitas necesarias | F7: Saldo entrada USD eq.
C8: 0.01 | D8: =C8*Supuestos!$D$8 -> 152 | E8: =IF(COUNT(Supuestos!$F$33,Supuestos!$F$38)=2,IF(Supuestos!$F$33*Supuestos!$F$38>0,D8/(Supuestos!$F$33*Supuestos!$F$38),"N/D"),"N/D") -> 11692.308 | F8: =D8*Supuestos!$D$10 -> 380000
C9: 0.05 | D9: =C9*Supuestos!$D$8 -> 760 | E9: =IF(COUNT(Supuestos!$F$33,Supuestos!$F$38)=2,IF(Supuestos!$F$33*Supuestos!$F$38>0,D9/(Supuestos!$F$33*Supuestos!$F$38),"N/D"),"N/D") -> 58461.538 | F9: =D9*Supuestos!$D$10 -> 1900000
C10: 0.1 | D10: =C10*Supuestos!$D$8 -> 1520 | E10: =IF(COUNT(Supuestos!$F$33,Supuestos!$F$38)=2,IF(Supuestos!$F$33*Supuestos!$F$38>0,D10/(Supuestos!$F$33*Supuestos!$F$38),"N/D"),"N/D") -> 116923.08 | F10: =D10*Supuestos!$D$10 -> 3800000
C12: Bandas de escala: no son compromiso de contribución. Tasas de M1 se usan sólo en este cálculo top-down.
C14: Sensibilidad: cuentas incrementales con las visitas adicionales del caso activo.
C16: Apertura / Fondeo | F16: 0.4 | G16: 0.5 | H16: 0.65 | I16: 0.75 | J16: 0.85
C17: 0.01 | F17: =IF(COUNT(Mensual!$F$13:$K$13)=6,SUM(Mensual!$F$13:$K$13)*$C17*F$16,"N/D") -> 4.2705 | G17: =IF(COUNT(Mensual!$F$13:$K$13)=6,SUM(Mensual!$F$13:$K$13)*$C17*G$16,"N/D") -> 5.338125 | H17: =IF(COUNT(Mensual!$F$13:$K$13)=6,SUM(Mensual!$F$13:$K$13)*$C17*H$16,"N/D") -> 6.9395625 | I17: =IF(COUNT(Mensual!$F$13:$K$13)=6,SUM(Mensual!$F$13:$K$13)*$C17*I$16,"N/D") -> 8.0071875 | J17: =IF(COUNT(Mensual!$F$13:$K$13)=6,SUM(Mensual!$F$13:$K$13)*$C17*J$16,"N/D") -> 9.0748125
C18: 0.015 | F18: =IF(COUNT(Mensual!$F$13:$K$13)=6,SUM(Mensual!$F$13:$K$13)*$C18*F$16,"N/D") -> 6.40575 | G18: =IF(COUNT(Mensual!$F$13:$K$13)=6,SUM(Mensual!$F$13:$K$13)*$C18*G$16,"N/D") -> 8.0071875 | H18: =IF(COUNT(Mensual!$F$13:$K$13)=6,SUM(Mensual!$F$13:$K$13)*$C18*H$16,"N/D") -> 10.409344 | I18: =IF(COUNT(Mensual!$F$13:$K$13)=6,SUM(Mensual!$F$13:$K$13)*$C18*I$16,"N/D") -> 12.010781 | J18: =IF(COUNT(Mensual!$F$13:$K$13)=6,SUM(Mensual!$F$13:$K$13)*$C18*J$16,"N/D") -> 13.612219
C19: 0.02 | F19: =IF(COUNT(Mensual!$F$13:$K$13)=6,SUM(Mensual!$F$13:$K$13)*$C19*F$16,"N/D") -> 8.541 | G19: =IF(COUNT(Mensual!$F$13:$K$13)=6,SUM(Mensual!$F$13:$K$13)*$C19*G$16,"N/D") -> 10.67625 | H19: =IF(COUNT(Mensual!$F$13:$K$13)=6,SUM(Mensual!$F$13:$K$13)*$C19*H$16,"N/D") -> 13.879125 | I19: =IF(COUNT(Mensual!$F$13:$K$13)=6,SUM(Mensual!$F$13:$K$13)*$C19*I$16,"N/D") -> 16.014375 | J19: =IF(COUNT(Mensual!$F$13:$K$13)=6,SUM(Mensual!$F$13:$K$13)*$C19*J$16,"N/D") -> 18.149625
C20: 0.025 | F20: =IF(COUNT(Mensual!$F$13:$K$13)=6,SUM(Mensual!$F$13:$K$13)*$C20*F$16,"N/D") -> 10.67625 | G20: =IF(COUNT(Mensual!$F$13:$K$13)=6,SUM(Mensual!$F$13:$K$13)*$C20*G$16,"N/D") -> 13.345313 | H20: =IF(COUNT(Mensual!$F$13:$K$13)=6,SUM(Mensual!$F$13:$K$13)*$C20*H$16,"N/D") -> 17.348906 | I20: =IF(COUNT(Mensual!$F$13:$K$13)=6,SUM(Mensual!$F$13:$K$13)*$C20*I$16,"N/D") -> 20.017969 | J20: =IF(COUNT(Mensual!$F$13:$K$13)=6,SUM(Mensual!$F$13:$K$13)*$C20*J$16,"N/D") -> 22.687031
C21: 0.03 | F21: =IF(COUNT(Mensual!$F$13:$K$13)=6,SUM(Mensual!$F$13:$K$13)*$C21*F$16,"N/D") -> 12.8115 | G21: =IF(COUNT(Mensual!$F$13:$K$13)=6,SUM(Mensual!$F$13:$K$13)*$C21*G$16,"N/D") -> 16.014375 | H21: =IF(COUNT(Mensual!$F$13:$K$13)=6,SUM(Mensual!$F$13:$K$13)*$C21*H$16,"N/D") -> 20.818687 | I21: =IF(COUNT(Mensual!$F$13:$K$13)=6,SUM(Mensual!$F$13:$K$13)*$C21*I$16,"N/D") -> 24.021563 | J21: =IF(COUNT(Mensual!$F$13:$K$13)=6,SUM(Mensual!$F$13:$K$13)*$C21*J$16,"N/D") -> 27.224438
C24: Retraso meses | D24: Visitas dentro 6m | E24: Cuentas fondeadas
C25: 0 | D25: =IF(AND(C25>=0,C25<6,COUNT(Mensual!$F$13:INDEX(Mensual!$F$13:$K$13,1,6-C25))=6-C25),SUM(Mensual!$F$13:INDEX(Mensual!$F$13:$K$13,1,6-C25)),"N/D") -> 1067.625 | E25: =IF(COUNT(D25,Supuestos!$F$33,Supuestos!$F$38)=3,D25*Supuestos!$F$33*Supuestos!$F$38,"N/D") -> 13.879125
C26: 1 | D26: =IF(AND(C26>=0,C26<6,COUNT(Mensual!$F$13:INDEX(Mensual!$F$13:$K$13,1,6-C26))=6-C26),SUM(Mensual!$F$13:INDEX(Mensual!$F$13:$K$13,1,6-C26)),"N/D") -> 628.875 | E26: =IF(COUNT(D26,Supuestos!$F$33,Supuestos!$F$38)=3,D26*Supuestos!$F$33*Supuestos!$F$38,"N/D") -> 8.175375
C27: 2 | D27: =IF(AND(C27>=0,C27<6,COUNT(Mensual!$F$13:INDEX(Mensual!$F$13:$K$13,1,6-C27))=6-C27),SUM(Mensual!$F$13:INDEX(Mensual!$F$13:$K$13,1,6-C27)),"N/D") -> 336.375 | E27: =IF(COUNT(D27,Supuestos!$F$33,Supuestos!$F$38)=3,D27*Supuestos!$F$33*Supuestos!$F$38,"N/D") -> 4.372875
C29: Retraso desplaza la curva y recorta los últimos meses dentro del horizonte. Conversiones M1 constantes en esta prueba.
C32: Origen externo | D32: Saldo externo cierre USD eq.
C33: 0.4 | D33: =IF(COUNT(Mensual!$K$25)=1,Mensual!$K$25*C33,"N/D") -> 13147.144
C34: 0.7 | D34: =IF(COUNT(Mensual!$K$25)=1,Mensual!$K$25*C34,"N/D") -> 23007.502
C35: 1 | D35: =IF(COUNT(Mensual!$K$25)=1,Mensual!$K$25*C35,"N/D") -> 32867.859
C37: Retención y ticket se editan en Supuestos y actualizan Cohortes/Resumen. No equivalen a margen o revenue.
C40: Inversión hipotética USD | D40: Valor por cuenta para equilibrio | E40: Naturaleza
C41: 10000 | D41: =IF(AND(COUNT(Resumen!$D$10)=1,Resumen!$D$10>0),C41/Resumen!$D$10,"N/D") -> 720.50652 | E41: Sensibilidad; no fee
C42: 25000 | D42: =IF(AND(COUNT(Resumen!$D$10)=1,Resumen!$D$10>0),C42/Resumen!$D$10,"N/D") -> 1801.2663 | E42: Sensibilidad; no fee
C43: 50000 | D43: =IF(AND(COUNT(Resumen!$D$10)=1,Resumen!$D$10>0),C43/Resumen!$D$10,"N/D") -> 3602.5326 | E43: Sensibilidad; no fee
C45: Esta matriz explora inversión hipotética total. No es cotización ni propuesta de fee. No produce ROI sin Finance.
C46: 75% relevancia/eligibilidad es supuesto de prueba común. Ajustar Supuestos D13 cambia todas las visitas y cohortes.
C49: Aceptación geo pool amplio | D49: Demanda adicional / mes | E49: Fondeadas extra 6m
C50: 0 | D50: =IF(COUNT(Supuestos!$D$13)=1,1600*C50*Supuestos!$D$13,"N/D") -> 0 | E50: =IF(COUNT(D50,Supuestos!$F$23:$K$23,Supuestos!$F$33,Supuestos!$F$38)=9,D50*SUM(Supuestos!$F$23:$K$23)*Supuestos!$F$33*Supuestos!$F$38,"N/D") -> 0
C51: 0.5 | D51: =IF(COUNT(Supuestos!$D$13)=1,1600*C51*Supuestos!$D$13,"N/D") -> 600 | E51: =IF(COUNT(D51,Supuestos!$F$23:$K$23,Supuestos!$F$33,Supuestos!$F$38)=9,D51*SUM(Supuestos!$F$23:$K$23)*Supuestos!$F$33*Supuestos!$F$38,"N/D") -> 2.847
C52: 1 | D52: =IF(COUNT(Supuestos!$D$13)=1,1600*C52*Supuestos!$D$13,"N/D") -> 1200 | E52: =IF(COUNT(D52,Supuestos!$F$23:$K$23,Supuestos!$F$33,Supuestos!$F$38)=9,D52*SUM(Supuestos!$F$23:$K$23)*Supuestos!$F$33*Supuestos!$F$38,"N/D") -> 5.694
C54: Pool alto rendimiento 1.600 excluido de caso activo por SERP geográfica mixta. Esta prueba no lo vuelve elegible.

Sheet Fuentes
C2: Procedencia y límites de inputs
C4: Escenario seleccionado | D4: =Supuestos!D5 -> Base
C7: ID | D7: Naturaleza | E7: Fuente | F7: Alcance | G7: Fecha | H7: Confianza
C8: CAPACIDAD | D8: Estimación de planificación | E8: ../propuesta/ALCANCE-Y-COSTEO-INTERNO.md §2 | F8: 866h + reserva15%=995,9h. No costo monetario, roster ni fee aprobado | G8: 2026-10-06 | H8: Pendiente Operations/Finance
C9: META | D9: Inferencia provisional | E9: MEETING-2026-10-06.md y conversación del operador | F9: Meta Pibank referida en reunión; moneda/horizonte/estado de cuenta no confirmados | G9: 2026-10-06 | H9: Alta aritmética; baja confirmación de meta
C10: PRODUCTO | D10: Observación pública | E10: https://pibank.pe/cuenta-soles-pibank/ | F10: Cuenta Soles, ahorro digital; no valida meta USD ni producto dólares | G10: 2026-10-06 | H10: Alta para página observada
C11: IDENTIDAD | D11: Observación pública | E11: https://pibank.pe/quienes-somos/ | F11: Pibank pertenece a Banco Pichincha Perú | G11: 2026-10-06 | H11: Alta para identidad declarada
C12: GOOGLE | D12: Documentación primaria | E12: https://developers.google.com/search/docs/appearance/ai-features | F12: Google: SEO fundamentos; sin requisitos técnicos extras ni aparición garantizada | G12: 2026-10-06 | H12: Alta para Google únicamente
C13: SIM | D13: Ejemplo aritmético | E13: Diseño del modelo de prueba; inputs.json | F13: Captura, referencia, apertura, fondeo, retención, origen externo no medidos | G13: 2026-10-06 | H13: No inferencia empírica
C14: DEMANDA | D14: Proxy editorial con estimaciones DataForSEO PE/es, suma MAX de seis grupos. Alto rendimiento1600 excluido por SERP mixta geográfica. Snapshot sept2026/últimos meses agosto; no TAM personas ni forecast2027 | E14: ../research/pibank-demand-2026-10-06/demand-inputs.json; keyword_overview/live + keyword_suggestions/live, consultado2026-10-06 | F14: Demanda mensual: cobertura y deduplicación deben corresponder al país/producto | G14: 2026-10-06 | H14: Provisional hasta validación de dataset
C15: RELEVANCIA | D15: Supuesto ilustrativo | E15: Inputs editables, sin conversión observada | F15: Factor de prueba 75% no medido sobre3900. Recorta relevancia/elegibilidad y solapamiento restante; sensibilizar, no personas únicas | G15: 2026-10-06 | H15: No inferencia empírica
C16: VALOR | D16: Pendiente Finance | E16: Sin método bancario validado | F16: Contribución neta anual por USD de saldo externo, método único | G16: 2026-10-06 | H16: No disponible
C17: COSTOS | D17: Pendiente oferta | E17: Inputs editables, sin quote aprobado | F17: Inversión cliente pendiente. No es cero. No fee ni quote aprobado Costo interno Efeonce separado, pendiente. | G17: 2026-10-06 | H17: No inferencia de precio
C20: Validación: Comercial confirma meta/horizonte; SEO deduplica demanda; banco aporta embudo; Finance valora fondeo.
C22: Todos los drivers SIM son ejemplos aritméticos. No hay tasas medidas, costos aprobados ni causalidad probada.

Sheet Demanda
C2: Estimaciones de mercado PE/es: fuente histórica
C4: Escenario seleccionado | D4: =Supuestos!D5 -> Base
C7: Grupo | D7: Consulta representativa | E7: Proxy mensual | F7: Usar | G7: Incluido
C8: G01_category | D8: cuenta de ahorros | E8: 2900 | F8: Sí | G8: =IF(F8="Sí",E8,0) -> 2900
C9: G02_high_yield | D9: cuenta de ahorros de alto rendimiento | E9: 1600 | F9: No | G9: =IF(F9="Sí",E9,0) -> 0
C10: G03_comparison | D10: mejor cuenta de ahorros peru | E10: 320 | F10: Sí | G10: =IF(F10="Sí",E10,0) -> 320
C11: G04_digital | D11: cuenta de ahorros digital | E11: 210 | F11: Sí | G11: =IF(F11="Sí",E11,0) -> 210
C12: G05_opening | D12: abrir cuenta de ahorros | E12: 210 | F12: Sí | G12: =IF(F12="Sí",E12,0) -> 210
C13: G06_no_maintenance | D13: cuenta de ahorros sin mantenimiento | E13: 50 | F13: Sí | G13: =IF(F13="Sí",E13,0) -> 50
C14: G07_interest | D14: cuenta de ahorros con intereses | E14: 210 | F14: Sí | G14: =IF(F14="Sí",E14,0) -> 210
C15: G08_usd_future | D15: cuenta de ahorros en dolares | E15: 210 | F15: No | G15: =IF(F15="Sí",E15,0) -> 0
C16: G09_term_substitute | D16: cuenta de ahorros a plazo fijo | E16: 390 | F16: No | G16: =IF(F16="Sí",E16,0) -> 0
C17: G10_definition | D17: cuenta de ahorros que es | E17: 590 | F17: No | G17: =IF(F17="Sí",E17,0) -> 0
C18: G11_current_vs_savings | D18: diferencia entre cuenta corriente y cuenta de ahorros | E18: 1600 | F18: No | G18: =IF(F18="Sí",E18,0) -> 0
C19: G12_trust_fsd | D19: fondo de seguro de depositos | E19: 1600 | F19: No | G19: =IF(F19="Sí",E19,0) -> 0
C20: G13_trea | D20: que es trea | E20: 880 | F20: No | G20: =IF(F20="Sí",E20,0) -> 0
C22: Proxy total mercado / mes | G22: =SUM(G8:G20) -> 3900
C24: Agregación MAX por grupo editorial. Persiste solapamiento entre grupos y relevancia internacional; no personas únicas.
C25: PE/es. Consulta 06/10/2026. Volúmenes snapshot sept2026, últimos monthly_searches agosto. No baseline post-launch.
C26: Marca Pibank, competidores, soporte, educación, plazo fijo y futuros dólares excluidos. Ausencias preservadas NULL en dataset.
C27: Source: demand-source.json (metadata/grupos + SHA256 original). DataForSEO keyword_overview y keyword_suggestions live.
