Workbook

Sheet LEER PRIMERO
A1: Tema | B1: Interpretación
A2: Estado | B2: Anexo de trabajo del 07-10-2026. Usa los volúmenes existentes de 19 familias; no reemplaza el Excel anterior.
A3: Meta preservada | B3: 15.200 cuentas con fondos × USD 2.500 = USD 38m de referencia. A 2% de apertura y 65% de fondeo: 1.169.231 visitas requeridas.
A4: Búsquedas rivales | B4: Incluidas las cinco familias existentes, con sus volúmenes originales y sin descuento automático por marca.
A5: Qué es nuevo | B5: Hipótesis editables de captura y maduración; conexión con recursos del calendario; costo del alcance ampliado.
A6: Lectura de resultados | B6: La suma del panel es sensibilidad aritmética antes de conciliar solapamiento. No es forecast del programa ni aporte incremental demostrado. Cifras pequeñas no invalidan el resto del programa; tampoco se inflan para alcanzar la meta.
A7: Otros mecanismos | B7: PR, comunidad, marca y referencias IA se miden con datos reales. La mejora sobre tráfico existente se compara con una referencia y no se duplica como canal.
A8: Costo propuesto | B8: USD 8,000/mes para revisión de Julio. Costos complementarios usan referencia seed, no cotizaciones. No es precio aprobado.
A9: Equipo | B9: Reserva propuesta: 50% redacción, 30% diseño, 100% SEO. Valentina/diseñadores existentes reducen caja adicional sólo si hay disponibilidad; conservan costo económico.
A10: Uso | B10: Azul = hipótesis editable. Inputs de búsquedas copiados de fuente. Fórmulas incluyen resultados calculados localmente; Excel Desktop no operado.
A11: Datos pendientes | B11: Conversiones, tráfico de referencia y periodo bancario; capacidades individuales, costos fully loaded y terceros. Fondos no equivalen a beneficio bancario.

Sheet Supuestos
A1: Variable | B1: Valor | C1: Procedencia
A2: opening | B2: 0.02 | C2: Conservado del modelo original
A3: funding | B3: 0.65 | C3: Conservado del modelo original
A4: goal | B4: 15200 | C4: Meta de cuentas con fondos aclarada por Julio
A5: ticket | B5: 2500 | C5: Referencia USD, no beneficio ni producto USD
A6: reserve | B6: 0.15 | C6: Nueva provisión de trabajo/costo
A7: loading | B7: 0.2 | C7: Provisión cargas; sustituir por costo real
A8: margin | B8: 0.4 | C8: Objetivo de margen propuesto
A9: fee | B9: 8000 | C9: Fee propuesto, no aprobado
A10: capture_prudente | B10: 0.02 | C10: Sensibilidad de captura efectiva; no dato medido
A11: capture_trabajo | B11: 0.05 | C11: Sensibilidad de captura efectiva; no dato medido
A12: capture_expansion | B12: 0.1 | C12: Sensibilidad de captura efectiva; no dato medido
A13: age_0 | B13: 0.1 | C13: Maduración hipotética desde recurso listo
... A37: other_alto | B37: 500 | C37: Provisión herramientas/otros mensual

Sheet Familias
A1: ID | B1: Familia | C1: Carril | D1: Consulta | E1: Volumen fuente mensual | F1: Mes listo | G1: Activo | H1: Fuente | I1: Fecha volumen
A2: G01 | B2: Cuenta de ahorro | C2: direct | D2: cuenta de ahorros | E2: 2900 | F2: 1 | G2: Pilar | H2: research/pibank-demand-2026-10-06/keyword-overview-provider.json | I2: 2026-09-17 05:09:54 +00:00
A3: G02 | B3: Intereses sobre ahorro | C3: direct | D3: cuenta de ahorro con intereses | E3: 210 | F3: 2 | G3: Calculadora / ART-03 | H3: research/pibank-expanded-2026-10-06/ranked-01-provider.json | I3: 2026-09-13 19:50:52 +00:00
A4: G03 | B4: Comparar cuentas en Perú | C4: direct | D4: mejores cuentas de ahorro peru | E4: 320 | F4: 3 | G4: ART-05 / Comparador | H4: research/pibank-expanded-2026-10-06/ranked-01-provider.json | I4: 2026-09-12 20:56:31 +00:00
A5: G04 | B5: Abrir una cuenta de ahorro | C5: direct | D5: abrir cuenta de ahorros | E5: 210 | F5: 1 | G5: ART-02 | H5: research/pibank-demand-2026-10-06/keyword-overview-provider.json | I5: 2026-09-14 12:25:03 +00:00
A6: G05 | B6: Costos de mantenimiento | C6: direct | D6: cuenta de ahorros sin mantenimiento | E6: 50 | F6: 1 | G6: Pilar | H6: research/pibank-demand-2026-10-06/keyword-overview-provider.json | I6: 2026-09-17 23:57:04 +00:00
A7: G06 | B7: Requisitos de apertura | C7: direct | D7: requisitos para abrir una cuenta de ahorros | E7: 50 | F7: 1 | G7: ART-02 | H7: research/pibank-expanded-2026-10-06/suggestion-01-provider.json | I7: 2026-09-17 10:31:22 +00:00
A8: C01 | B8: Ahorro de alto rendimiento | C8: conditional | D8: cuentas de ahorro de alto rendimiento | E8: 1600 | F8: 2 | G8: Pilar / ART-03 | H8: research/pibank-expanded-2026-10-06/ranked-01-provider.json | I8: 2026-09-14 10:11:37 +00:00
A9: C02 | B9: Cuenta digital | C9: conditional | D9: cuenta digital | E9: 1300 | F9: 1 | G9: Pilar / ART-02 | H9: research/pibank-expanded-2026-10-06/ranked-05-provider.json | I9: 2026-09-12 08:53:56 +00:00
A10: C03 | B10: Dónde ahorrar y ganar intereses | C10: conditional | D10: en que banco puedo ahorrar mi dinero y ganar intereses | E10: 390 | F10: 3 | G10: ART-05 | H10: research/pibank-expanded-2026-10-06/ranked-01-provider.json | I10: 2026-09-14 06:37:02 +00:00
A11: C04 | B11: Qué banco paga más intereses Perú | C11: conditional | D11: que banco paga mas intereses en peru | E11: 40 | F11: 3 | G11: ART-05 | H11: research/pibank-demand-2026-10-06/keyword-overview-provider.json | I11: 2026-09-16 04:22:34 +00:00
A12: B01 | B12: Ahorro BCP | C12: competitor | D12: cuenta de ahorro del bcp | E12: 6600 | F12: 7 | G12: ART-13 | H12: research/pibank-expanded-2026-10-06/ranked-08-provider.json | I12: 2026-09-13 15:51:41 +00:00
A13: B02 | B13: Súper Tasa Interbank | C13: competitor | D13: cuenta super tasa interbank | E13: 1900 | F13: 5 | G13: ART-10 | H13: research/pibank-demand-2026-10-06/keyword-overview-provider.json | I13: 2026-09-17 15:28:44 +00:00
... A20: E04 | B20: Cómo ahorrar dinero | C20: assisted | D20: como ahorrar dinero | E20: 590 | F20: 3 | G20: ART-06 | H20: research/pibank-expanded-2026-10-06/extra-related-01-provider.json | I20: 2026-09-16 20:21:11 +00:00

Sheet Trafico por mes
A1: Escenario | B1: Familia | C1: Mes | D1: Captura supuesto | E1: Madurez supuesto | F1: Visitas equivalentes de prueba | G1: Aperturas prueba | H1: Fondeadas prueba
A2: prudente | B2: G01 | C2: 1 | D2: =Supuestos!$B$10 -> 0.02 | E2: =IF(C2<Familias!F2,0,INDEX(Supuestos!$B$13:$B$19,MIN(C2-Familias!F2+1,7))) -> 0.1 | F2: =Familias!E2*D2*E2 -> 5.8 | G2: =F2*Supuestos!$B$2 -> 0.116 | H2: =G2*Supuestos!$B$3 -> 0.0754
A3: prudente | B3: G01 | C3: 2 | D3: =Supuestos!$B$10 -> 0.02 | E3: =IF(C3<Familias!F2,0,INDEX(Supuestos!$B$13:$B$19,MIN(C3-Familias!F2+1,7))) -> 0.2 | F3: =Familias!E2*D3*E3 -> 11.6 | G3: =F3*Supuestos!$B$2 -> 0.232 | H3: =G3*Supuestos!$B$3 -> 0.1508
A4: prudente | B4: G01 | C4: 3 | D4: =Supuestos!$B$10 -> 0.02 | E4: =IF(C4<Familias!F2,0,INDEX(Supuestos!$B$13:$B$19,MIN(C4-Familias!F2+1,7))) -> 0.35 | F4: =Familias!E2*D4*E4 -> 20.3 | G4: =F4*Supuestos!$B$2 -> 0.406 | H4: =G4*Supuestos!$B$3 -> 0.2639
A5: prudente | B5: G01 | C5: 4 | D5: =Supuestos!$B$10 -> 0.02 | E5: =IF(C5<Familias!F2,0,INDEX(Supuestos!$B$13:$B$19,MIN(C5-Familias!F2+1,7))) -> 0.5 | F5: =Familias!E2*D5*E5 -> 29 | G5: =F5*Supuestos!$B$2 -> 0.58 | H5: =G5*Supuestos!$B$3 -> 0.377
A6: prudente | B6: G01 | C6: 5 | D6: =Supuestos!$B$10 -> 0.02 | E6: =IF(C6<Familias!F2,0,INDEX(Supuestos!$B$13:$B$19,MIN(C6-Familias!F2+1,7))) -> 0.65 | F6: =Familias!E2*D6*E6 -> 37.7 | G6: =F6*Supuestos!$B$2 -> 0.754 | H6: =G6*Supuestos!$B$3 -> 0.4901
A7: prudente | B7: G01 | C7: 6 | D7: =Supuestos!$B$10 -> 0.02 | E7: =IF(C7<Familias!F2,0,INDEX(Supuestos!$B$13:$B$19,MIN(C7-Familias!F2+1,7))) -> 0.8 | F7: =Familias!E2*D7*E7 -> 46.4 | G7: =F7*Supuestos!$B$2 -> 0.928 | H7: =G7*Supuestos!$B$3 -> 0.6032
A8: prudente | B8: G01 | C8: 7 | D8: =Supuestos!$B$10 -> 0.02 | E8: =IF(C8<Familias!F2,0,INDEX(Supuestos!$B$13:$B$19,MIN(C8-Familias!F2+1,7))) -> 1 | F8: =Familias!E2*D8*E8 -> 58 | G8: =F8*Supuestos!$B$2 -> 1.16 | H8: =G8*Supuestos!$B$3 -> 0.754
A9: prudente | B9: G01 | C9: 8 | D9: =Supuestos!$B$10 -> 0.02 | E9: =IF(C9<Familias!F2,0,INDEX(Supuestos!$B$13:$B$19,MIN(C9-Familias!F2+1,7))) -> 1 | F9: =Familias!E2*D9*E9 -> 58 | G9: =F9*Supuestos!$B$2 -> 1.16 | H9: =G9*Supuestos!$B$3 -> 0.754
A10: prudente | B10: G01 | C10: 9 | D10: =Supuestos!$B$10 -> 0.02 | E10: =IF(C10<Familias!F2,0,INDEX(Supuestos!$B$13:$B$19,MIN(C10-Familias!F2+1,7))) -> 1 | F10: =Familias!E2*D10*E10 -> 58 | G10: =F10*Supuestos!$B$2 -> 1.16 | H10: =G10*Supuestos!$B$3 -> 0.754
A11: prudente | B11: G01 | C11: 10 | D11: =Supuestos!$B$10 -> 0.02 | E11: =IF(C11<Familias!F2,0,INDEX(Supuestos!$B$13:$B$19,MIN(C11-Familias!F2+1,7))) -> 1 | F11: =Familias!E2*D11*E11 -> 58 | G11: =F11*Supuestos!$B$2 -> 1.16 | H11: =G11*Supuestos!$B$3 -> 0.754
A12: prudente | B12: G01 | C12: 11 | D12: =Supuestos!$B$10 -> 0.02 | E12: =IF(C12<Familias!F2,0,INDEX(Supuestos!$B$13:$B$19,MIN(C12-Familias!F2+1,7))) -> 1 | F12: =Familias!E2*D12*E12 -> 58 | G12: =F12*Supuestos!$B$2 -> 1.16 | H12: =G12*Supuestos!$B$3 -> 0.754
A13: prudente | B13: G01 | C13: 12 | D13: =Supuestos!$B$10 -> 0.02 | E13: =IF(C13<Familias!F2,0,INDEX(Supuestos!$B$13:$B$19,MIN(C13-Familias!F2+1,7))) -> 1 | F13: =Familias!E2*D13*E13 -> 58 | G13: =F13*Supuestos!$B$2 -> 1.16 | H13: =G13*Supuestos!$B$3 -> 0.754
A14: prudente | B14: G02 | C14: 1 | D14: =Supuestos!$B$10 -> 0.02 | E14: =IF(C14<Familias!F3,0,INDEX(Supuestos!$B$13:$B$19,MIN(C14-Familias!F3+1,7))) -> 0 | F14: =Familias!E3*D14*E14 -> 0 | G14: =F14*Supuestos!$B$2 -> 0 | H14: =G14*Supuestos!$B$3 -> 0
A15: prudente | B15: G02 | C15: 2 | D15: =Supuestos!$B$10 -> 0.02 | E15: =IF(C15<Familias!F3,0,INDEX(Supuestos!$B$13:$B$19,MIN(C15-Familias!F3+1,7))) -> 0.1 | F15: =Familias!E3*D15*E15 -> 0.42 | G15: =F15*Supuestos!$B$2 -> 0.0084 | H15: =G15*Supuestos!$B$3 -> 0.00546
A16: prudente | B16: G02 | C16: 3 | D16: =Supuestos!$B$10 -> 0.02 | E16: =IF(C16<Familias!F3,0,INDEX(Supuestos!$B$13:$B$19,MIN(C16-Familias!F3+1,7))) -> 0.2 | F16: =Familias!E3*D16*E16 -> 0.84 | G16: =F16*Supuestos!$B$2 -> 0.0168 | H16: =G16*Supuestos!$B$3 -> 0.01092
A17: prudente | B17: G02 | C17: 4 | D17: =Supuestos!$B$10 -> 0.02 | E17: =IF(C17<Familias!F3,0,INDEX(Supuestos!$B$13:$B$19,MIN(C17-Familias!F3+1,7))) -> 0.35 | F17: =Familias!E3*D17*E17 -> 1.47 | G17: =F17*Supuestos!$B$2 -> 0.0294 | H17: =G17*Supuestos!$B$3 -> 0.01911
A18: prudente | B18: G02 | C18: 5 | D18: =Supuestos!$B$10 -> 0.02 | E18: =IF(C18<Familias!F3,0,INDEX(Supuestos!$B$13:$B$19,MIN(C18-Familias!F3+1,7))) -> 0.5 | F18: =Familias!E3*D18*E18 -> 2.1 | G18: =F18*Supuestos!$B$2 -> 0.042 | H18: =G18*Supuestos!$B$3 -> 0.0273
A19: prudente | B19: G02 | C19: 6 | D19: =Supuestos!$B$10 -> 0.02 | E19: =IF(C19<Familias!F3,0,INDEX(Supuestos!$B$13:$B$19,MIN(C19-Familias!F3+1,7))) -> 0.65 | F19: =Familias!E3*D19*E19 -> 2.73 | G19: =F19*Supuestos!$B$2 -> 0.0546 | H19: =G19*Supuestos!$B$3 -> 0.03549
A20: prudente | B20: G02 | C20: 7 | D20: =Supuestos!$B$10 -> 0.02 | E20: =IF(C20<Familias!F3,0,INDEX(Supuestos!$B$13:$B$19,MIN(C20-Familias!F3+1,7))) -> 0.8 | F20: =Familias!E3*D20*E20 -> 3.36 | G20: =F20*Supuestos!$B$2 -> 0.0672 | H20: =G20*Supuestos!$B$3 -> 0.04368
A21: prudente | B21: G02 | C21: 8 | D21: =Supuestos!$B$10 -> 0.02 | E21: =IF(C21<Familias!F3,0,INDEX(Supuestos!$B$13:$B$19,MIN(C21-Familias!F3+1,7))) -> 1 | F21: =Familias!E3*D21*E21 -> 4.2 | G21: =F21*Supuestos!$B$2 -> 0.084 | H21: =G21*Supuestos!$B$3 -> 0.0546
A22: prudente | B22: G02 | C22: 9 | D22: =Supuestos!$B$10 -> 0.02 | E22: =IF(C22<Familias!F3,0,INDEX(Supuestos!$B$13:$B$19,MIN(C22-Familias!F3+1,7))) -> 1 | F22: =Familias!E3*D22*E22 -> 4.2 | G22: =F22*Supuestos!$B$2 -> 0.084 | H22: =G22*Supuestos!$B$3 -> 0.0546
A23: prudente | B23: G02 | C23: 10 | D23: =Supuestos!$B$10 -> 0.02 | E23: =IF(C23<Familias!F3,0,INDEX(Supuestos!$B$13:$B$19,MIN(C23-Familias!F3+1,7))) -> 1 | F23: =Familias!E3*D23*E23 -> 4.2 | G23: =F23*Supuestos!$B$2 -> 0.084 | H23: =G23*Supuestos!$B$3 -> 0.0546
A24: prudente | B24: G02 | C24: 11 | D24: =Supuestos!$B$10 -> 0.02 | E24: =IF(C24<Familias!F3,0,INDEX(Supuestos!$B$13:$B$19,MIN(C24-Familias!F3+1,7))) -> 1 | F24: =Familias!E3*D24*E24 -> 4.2 | G24: =F24*Supuestos!$B$2 -> 0.084 | H24: =G24*Supuestos!$B$3 -> 0.0546
A25: prudente | B25: G02 | C25: 12 | D25: =Supuestos!$B$10 -> 0.02 | E25: =IF(C25<Familias!F3,0,INDEX(Supuestos!$B$13:$B$19,MIN(C25-Familias!F3+1,7))) -> 1 | F25: =Familias!E3*D25*E25 -> 4.2 | G25: =F25*Supuestos!$B$2 -> 0.084 | H25: =G25*Supuestos!$B$3 -> 0.0546
A26: prudente | B26: G03 | C26: 1 | D26: =Supuestos!$B$10 -> 0.02 | E26: =IF(C26<Familias!F4,0,INDEX(Supuestos!$B$13:$B$19,MIN(C26-Familias!F4+1,7))) -> 0 | F26: =Familias!E4*D26*E26 -> 0 | G26: =F26*Supuestos!$B$2 -> 0 | H26: =G26*Supuestos!$B$3 -> 0
A27: prudente | B27: G03 | C27: 2 | D27: =Supuestos!$B$10 -> 0.02 | E27: =IF(C27<Familias!F4,0,INDEX(Supuestos!$B$13:$B$19,MIN(C27-Familias!F4+1,7))) -> 0 | F27: =Familias!E4*D27*E27 -> 0 | G27: =F27*Supuestos!$B$2 -> 0 | H27: =G27*Supuestos!$B$3 -> 0
A28: prudente | B28: G03 | C28: 3 | D28: =Supuestos!$B$10 -> 0.02 | E28: =IF(C28<Familias!F4,0,INDEX(Supuestos!$B$13:$B$19,MIN(C28-Familias!F4+1,7))) -> 0.1 | F28: =Familias!E4*D28*E28 -> 0.64 | G28: =F28*Supuestos!$B$2 -> 0.0128 | H28: =G28*Supuestos!$B$3 -> 0.00832
A29: prudente | B29: G03 | C29: 4 | D29: =Supuestos!$B$10 -> 0.02 | E29: =IF(C29<Familias!F4,0,INDEX(Supuestos!$B$13:$B$19,MIN(C29-Familias!F4+1,7))) -> 0.2 | F29: =Familias!E4*D29*E29 -> 1.28 | G29: =F29*Supuestos!$B$2 -> 0.0256 | H29: =G29*Supuestos!$B$3 -> 0.01664
A30: prudente | B30: G03 | C30: 5 | D30: =Supuestos!$B$10 -> 0.02 | E30: =IF(C30<Familias!F4,0,INDEX(Supuestos!$B$13:$B$19,MIN(C30-Familias!F4+1,7))) -> 0.35 | F30: =Familias!E4*D30*E30 -> 2.24 | G30: =F30*Supuestos!$B$2 -> 0.0448 | H30: =G30*Supuestos!$B$3 -> 0.02912
A31: prudente | B31: G03 | C31: 6 | D31: =Supuestos!$B$10 -> 0.02 | E31: =IF(C31<Familias!F4,0,INDEX(Supuestos!$B$13:$B$19,MIN(C31-Familias!F4+1,7))) -> 0.5 | F31: =Familias!E4*D31*E31 -> 3.2 | G31: =F31*Supuestos!$B$2 -> 0.064 | H31: =G31*Supuestos!$B$3 -> 0.0416
A32: prudente | B32: G03 | C32: 7 | D32: =Supuestos!$B$10 -> 0.02 | E32: =IF(C32<Familias!F4,0,INDEX(Supuestos!$B$13:$B$19,MIN(C32-Familias!F4+1,7))) -> 0.65 | F32: =Familias!E4*D32*E32 -> 4.16 | G32: =F32*Supuestos!$B$2 -> 0.0832 | H32: =G32*Supuestos!$B$3 -> 0.05408
A33: prudente | B33: G03 | C33: 8 | D33: =Supuestos!$B$10 -> 0.02 | E33: =IF(C33<Familias!F4,0,INDEX(Supuestos!$B$13:$B$19,MIN(C33-Familias!F4+1,7))) -> 0.8 | F33: =Familias!E4*D33*E33 -> 5.12 | G33: =F33*Supuestos!$B$2 -> 0.1024 | H33: =G33*Supuestos!$B$3 -> 0.06656
A34: prudente | B34: G03 | C34: 9 | D34: =Supuestos!$B$10 -> 0.02 | E34: =IF(C34<Familias!F4,0,INDEX(Supuestos!$B$13:$B$19,MIN(C34-Familias!F4+1,7))) -> 1 | F34: =Familias!E4*D34*E34 -> 6.4 | G34: =F34*Supuestos!$B$2 -> 0.128 | H34: =G34*Supuestos!$B$3 -> 0.0832
A35: prudente | B35: G03 | C35: 10 | D35: =Supuestos!$B$10 -> 0.02 | E35: =IF(C35<Familias!F4,0,INDEX(Supuestos!$B$13:$B$19,MIN(C35-Familias!F4+1,7))) -> 1 | F35: =Familias!E4*D35*E35 -> 6.4 | G35: =F35*Supuestos!$B$2 -> 0.128 | H35: =G35*Supuestos!$B$3 -> 0.0832
A36: prudente | B36: G03 | C36: 11 | D36: =Supuestos!$B$10 -> 0.02 | E36: =IF(C36<Familias!F4,0,INDEX(Supuestos!$B$13:$B$19,MIN(C36-Familias!F4+1,7))) -> 1 | F36: =Familias!E4*D36*E36 -> 6.4 | G36: =F36*Supuestos!$B$2 -> 0.128 | H36: =G36*Supuestos!$B$3 -> 0.0832
A37: prudente | B37: G03 | C37: 12 | D37: =Supuestos!$B$10 -> 0.02 | E37: =IF(C37<Familias!F4,0,INDEX(Supuestos!$B$13:$B$19,MIN(C37-Familias!F4+1,7))) -> 1 | F37: =Familias!E4*D37*E37 -> 6.4 | G37: =F37*Supuestos!$B$2 -> 0.128 | H37: =G37*Supuestos!$B$3 -> 0.0832
A38: prudente | B38: G04 | C38: 1 | D38: =Supuestos!$B$10 -> 0.02 | E38: =IF(C38<Familias!F5,0,INDEX(Supuestos!$B$13:$B$19,MIN(C38-Familias!F5+1,7))) -> 0.1 | F38: =Familias!E5*D38*E38 -> 0.42 | G38: =F38*Supuestos!$B$2 -> 0.0084 | H38: =G38*Supuestos!$B$3 -> 0.00546
A39: prudente | B39: G04 | C39: 2 | D39: =Supuestos!$B$10 -> 0.02 | E39: =IF(C39<Familias!F5,0,INDEX(Supuestos!$B$13:$B$19,MIN(C39-Familias!F5+1,7))) -> 0.2 | F39: =Familias!E5*D39*E39 -> 0.84 | G39: =F39*Supuestos!$B$2 -> 0.0168 | H39: =G39*Supuestos!$B$3 -> 0.01092
A40: prudente | B40: G04 | C40: 3 | D40: =Supuestos!$B$10 -> 0.02 | E40: =IF(C40<Familias!F5,0,INDEX(Supuestos!$B$13:$B$19,MIN(C40-Familias!F5+1,7))) -> 0.35 | F40: =Familias!E5*D40*E40 -> 1.47 | G40: =F40*Supuestos!$B$2 -> 0.0294 | H40: =G40*Supuestos!$B$3 -> 0.01911
...

Sheet Panel resumen
A1: Escenario | B1: Visitas equivalentes | C1: Aperturas de prueba | D1: Fondeadas de prueba | E1: Lectura
A2: prudente | B2: =SUMIF('Trafico por mes'!$A$2:$A$685,A2,'Trafico por mes'!$F$2:$F$685) -> 2993.2 | C2: =SUMIF('Trafico por mes'!$A$2:$A$685,A2,'Trafico por mes'!$G$2:$G$685) -> 59.864 | D2: =SUMIF('Trafico por mes'!$A$2:$A$685,A2,'Trafico por mes'!$H$2:$H$685) -> 38.9116 | E2: Panel parcial con solapamiento residual. No resultado global de SEO/AEO + PR + comunidad ni forecast incremental. Lag de fondeo 0 conservado del modelo original.
A3: trabajo | B3: =SUMIF('Trafico por mes'!$A$2:$A$685,A3,'Trafico por mes'!$F$2:$F$685) -> 7483 | C3: =SUMIF('Trafico por mes'!$A$2:$A$685,A3,'Trafico por mes'!$G$2:$G$685) -> 149.66 | D3: =SUMIF('Trafico por mes'!$A$2:$A$685,A3,'Trafico por mes'!$H$2:$H$685) -> 97.279 | E3: Panel parcial con solapamiento residual. No resultado global de SEO/AEO + PR + comunidad ni forecast incremental. Lag de fondeo 0 conservado del modelo original.
A4: expansion | B4: =SUMIF('Trafico por mes'!$A$2:$A$685,A4,'Trafico por mes'!$F$2:$F$685) -> 14966 | C4: =SUMIF('Trafico por mes'!$A$2:$A$685,A4,'Trafico por mes'!$G$2:$G$685) -> 299.32 | D4: =SUMIF('Trafico por mes'!$A$2:$A$685,A4,'Trafico por mes'!$H$2:$H$685) -> 194.558 | E4: Panel parcial con solapamiento residual. No resultado global de SEO/AEO + PR + comunidad ni forecast incremental. Lag de fondeo 0 conservado del modelo original.

Sheet Costeo
A1: Escenario | B1: Grupo | C1: Horas base | D1: Costo unidad referencia | E1: Costo anual antes reserva | F1: Base del cálculo
A2: bajo | B2: automation | C2: 32 | D2: 11.383333 | E2: =C2*D2*Supuestos!$B$32 -> 364.26667 | F2: seed_hourly_cost_with_explicit_sensitivity_not_supplier_quote
A3: bajo | B3: community | C3: 192 | D3: 8.05 | E3: =C3*D3*Supuestos!$B$32 -> 1545.6 | F3: seed_hourly_cost_with_explicit_sensitivity_not_supplier_quote
A4: bajo | B4: coordination | C4: 72 | D4: 12.077778 | E4: =C4*D4*Supuestos!$B$32 -> 869.6 | F4: seed_hourly_cost_with_explicit_sensitivity_not_supplier_quote
A5: bajo | B5: designer | C5: 152 | D5: 950 | E5: =Supuestos!$B$25*Supuestos!$B$24*12*(1+Supuestos!$B$7) -> 4104 | F5: user_monthly_cost_times_allocation_plus_loading_allowance
A6: bajo | B6: development | C6: 232 | D6: 12.077778 | E6: =C6*D6*Supuestos!$B$32 -> 2802.0444 | F6: seed_hourly_cost_with_explicit_sensitivity_not_supplier_quote
A7: bajo | B7: direction | C7: 108 | D7: 10.827778 | E7: =C7*D7*Supuestos!$B$32 -> 1169.4 | F7: seed_hourly_cost_with_explicit_sensitivity_not_supplier_quote
A8: bajo | B8: pr | C8: 204 | D8: 10.272222 | E8: =C8*D8*Supuestos!$B$32 -> 2095.5333 | F8: seed_hourly_cost_with_explicit_sensitivity_not_supplier_quote
A9: bajo | B9: seo | C9: 512 | D9: 1500 | E9: =Supuestos!$B$29*Supuestos!$B$28*12*(1+Supuestos!$B$7) -> 21600 | F9: user_monthly_cost_times_allocation_plus_loading_allowance
A10: bajo | B10: session | C10: 32 | D10: 6.3833333 | E10: =C10*D10*Supuestos!$B$32 -> 204.26667 | F10: seed_hourly_cost_with_explicit_sensitivity_not_supplier_quote
A11: bajo | B11: wordpress | C11: 160 | D11: 9.1611111 | E11: =C11*D11*Supuestos!$B$32 -> 1465.7778 | F11: seed_hourly_cost_with_explicit_sensitivity_not_supplier_quote
A12: bajo | B12: writer | C12: 520 | D12: 600 | E12: =Supuestos!$B$21*Supuestos!$B$20*12*(1+Supuestos!$B$7) -> 4320 | F12: user_monthly_cost_times_allocation_plus_loading_allowance
A13: central | B13: automation | C13: 32 | D13: 11.383333 | E13: =C13*D13*Supuestos!$B$34 -> 455.33333 | F13: seed_hourly_cost_with_explicit_sensitivity_not_supplier_quote
A14: central | B14: community | C14: 192 | D14: 8.05 | E14: =C14*D14*Supuestos!$B$34 -> 1932 | F14: seed_hourly_cost_with_explicit_sensitivity_not_supplier_quote
A15: central | B15: coordination | C15: 72 | D15: 12.077778 | E15: =C15*D15*Supuestos!$B$34 -> 1087 | F15: seed_hourly_cost_with_explicit_sensitivity_not_supplier_quote
A16: central | B16: designer | C16: 152 | D16: 1075 | E16: =Supuestos!$B$26*Supuestos!$B$24*12*(1+Supuestos!$B$7) -> 4644 | F16: user_monthly_cost_times_allocation_plus_loading_allowance
A17: central | B17: development | C17: 232 | D17: 12.077778 | E17: =C17*D17*Supuestos!$B$34 -> 3502.5556 | F17: seed_hourly_cost_with_explicit_sensitivity_not_supplier_quote
A18: central | B18: direction | C18: 108 | D18: 10.827778 | E18: =C18*D18*Supuestos!$B$34 -> 1461.75 | F18: seed_hourly_cost_with_explicit_sensitivity_not_supplier_quote
A19: central | B19: pr | C19: 204 | D19: 10.272222 | E19: =C19*D19*Supuestos!$B$34 -> 2619.4167 | F19: seed_hourly_cost_with_explicit_sensitivity_not_supplier_quote
A20: central | B20: seo | C20: 512 | D20: 1500 | E20: =Supuestos!$B$30*Supuestos!$B$28*12*(1+Supuestos!$B$7) -> 21600 | F20: user_monthly_cost_times_allocation_plus_loading_allowance
A21: central | B21: session | C21: 32 | D21: 6.3833333 | E21: =C21*D21*Supuestos!$B$34 -> 255.33333 | F21: seed_hourly_cost_with_explicit_sensitivity_not_supplier_quote
A22: central | B22: wordpress | C22: 160 | D22: 9.1611111 | E22: =C22*D22*Supuestos!$B$34 -> 1832.2222 | F22: seed_hourly_cost_with_explicit_sensitivity_not_supplier_quote
A23: central | B23: writer | C23: 520 | D23: 750 | E23: =Supuestos!$B$22*Supuestos!$B$20*12*(1+Supuestos!$B$7) -> 5400 | F23: user_monthly_cost_times_allocation_plus_loading_allowance
A24: alto | B24: automation | C24: 32 | D24: 11.383333 | E24: =C24*D24*Supuestos!$B$36 -> 546.4 | F24: seed_hourly_cost_with_explicit_sensitivity_not_supplier_quote
A25: alto | B25: community | C25: 192 | D25: 8.05 | E25: =C25*D25*Supuestos!$B$36 -> 2318.4 | F25: seed_hourly_cost_with_explicit_sensitivity_not_supplier_quote
A26: alto | B26: coordination | C26: 72 | D26: 12.077778 | E26: =C26*D26*Supuestos!$B$36 -> 1304.4 | F26: seed_hourly_cost_with_explicit_sensitivity_not_supplier_quote
A27: alto | B27: designer | C27: 152 | D27: 1200 | E27: =Supuestos!$B$27*Supuestos!$B$24*12*(1+Supuestos!$B$7) -> 5184 | F27: user_monthly_cost_times_allocation_plus_loading_allowance
A28: alto | B28: development | C28: 232 | D28: 12.077778 | E28: =C28*D28*Supuestos!$B$36 -> 4203.0667 | F28: seed_hourly_cost_with_explicit_sensitivity_not_supplier_quote
A29: alto | B29: direction | C29: 108 | D29: 10.827778 | E29: =C29*D29*Supuestos!$B$36 -> 1754.1 | F29: seed_hourly_cost_with_explicit_sensitivity_not_supplier_quote
A30: alto | B30: pr | C30: 204 | D30: 10.272222 | E30: =C30*D30*Supuestos!$B$36 -> 3143.3 | F30: seed_hourly_cost_with_explicit_sensitivity_not_supplier_quote
A31: alto | B31: seo | C31: 512 | D31: 1500 | E31: =Supuestos!$B$31*Supuestos!$B$28*12*(1+Supuestos!$B$7) -> 21600 | F31: user_monthly_cost_times_allocation_plus_loading_allowance
A32: alto | B32: session | C32: 32 | D32: 6.3833333 | E32: =C32*D32*Supuestos!$B$36 -> 306.4 | F32: seed_hourly_cost_with_explicit_sensitivity_not_supplier_quote
A33: alto | B33: wordpress | C33: 160 | D33: 9.1611111 | E33: =C33*D33*Supuestos!$B$36 -> 2198.6667 | F33: seed_hourly_cost_with_explicit_sensitivity_not_supplier_quote
A34: alto | B34: writer | C34: 520 | D34: 900 | E34: =Supuestos!$B$23*Supuestos!$B$20*12*(1+Supuestos!$B$7) -> 6480 | F34: user_monthly_cost_times_allocation_plus_loading_allowance

Sheet Precio
A1: Escenario | B1: Costo laboral | C1: Reserva trabajo | D1: Herramientas/otros | E1: Costo anual | F1: Costo mensual | G1: Fee mensual al margen elegido | H1: Fee propuesto | I1: Margen al fee propuesto
A2: bajo | B2: =SUMIF(Costeo!A2:A34,A2,Costeo!E2:E34) -> 40540.489 | C2: =B2*Supuestos!$B$6 -> 6081.0733 | D2: =Supuestos!$B$33*12 -> 2400 | E2: =SUM(B2:D2) -> 49021.562 | F2: =E2/12 -> 4085.1302 | G2: =F2/(1-Supuestos!$B$8) -> 6808.5503 | H2: =Supuestos!$B$9 -> 8000 | I2: =(H2-F2)/H2 -> 0.48935873
A3: central | B3: =SUMIF(Costeo!A2:A34,A3,Costeo!E2:E34) -> 44789.611 | C3: =B3*Supuestos!$B$6 -> 6718.4417 | D3: =Supuestos!$B$35*12 -> 3600 | E3: =SUM(B3:D3) -> 55108.053 | F3: =E3/12 -> 4592.3377 | G3: =F3/(1-Supuestos!$B$8) -> 7653.8962 | H3: =Supuestos!$B$9 -> 8000 | I3: =(H3-F3)/H3 -> 0.42595778
A4: alto | B4: =SUMIF(Costeo!A2:A34,A4,Costeo!E2:E34) -> 49038.733 | C4: =B4*Supuestos!$B$6 -> 7355.81 | D4: =Supuestos!$B$37*12 -> 6000 | E4: =SUM(B4:D4) -> 62394.543 | F4: =E4/12 -> 5199.5453 | G4: =F4/(1-Supuestos!$B$8) -> 8665.9088 | H4: =Supuestos!$B$9 -> 8000 | I4: =(H4-F4)/H4 -> 0.35005684
A7: Costeo económico, no caja incremental confirmada. Referencia seed y provisiones no son costos fully loaded validados. Un fee en esta hoja no aprueba la oferta. El costo interno no se incorpora al deck del cliente.

Sheet Trabajo
A1: work_id | B1: work | C1: cost_group | D1: role_sku | E1: month | F1: base_hours
A2: D01 | B2: Dirección mensual | C2: direction | D2: ECG-001 | E2: 1 | F2: 6
A3: D01 | B3: Dirección mensual | C3: direction | D3: ECG-001 | E3: 2 | F3: 6
A4: D01 | B4: Dirección mensual | C4: direction | D4: ECG-001 | E4: 3 | F4: 6
A5: D01 | B5: Dirección mensual | C5: direction | D5: ECG-001 | E5: 4 | F5: 6
A6: D01 | B6: Dirección mensual | C6: direction | D6: ECG-001 | E6: 5 | F6: 6
A7: D01 | B7: Dirección mensual | C7: direction | D7: ECG-001 | E7: 6 | F7: 6
A8: D01 | B8: Dirección mensual | C8: direction | D8: ECG-001 | E8: 7 | F8: 6
A9: D01 | B9: Dirección mensual | C9: direction | D9: ECG-001 | E9: 8 | F9: 6
A10: D01 | B10: Dirección mensual | C10: direction | D10: ECG-001 | E10: 9 | F10: 6
A11: D01 | B11: Dirección mensual | C11: direction | D11: ECG-001 | E11: 10 | F11: 6
A12: D01 | B12: Dirección mensual | C12: direction | D12: ECG-001 | E12: 11 | F12: 6
A13: D01 | B13: Dirección mensual | C13: direction | D13: ECG-001 | E13: 12 | F13: 6
... A18: D03 | B18: Inicio | C18: direction | D18: ECG-001 | E18: 1 | F18: 4
A19: S01 | B19: SEO técnico inicial | C19: seo | E19: 1 | F19: 32
A20: S02 | B20: SEO seguimiento | C20: seo | E20: 2 | F20: 8
A21: S02 | B21: SEO seguimiento | C21: seo | E21: 3 | F21: 8
A22: S02 | B22: SEO seguimiento | C22: seo | E22: 4 | F22: 8
A23: S02 | B23: SEO seguimiento | C23: seo | E23: 5 | F23: 8
A24: S02 | B24: SEO seguimiento | C24: seo | E24: 6 | F24: 8
A25: S02 | B25: SEO seguimiento | C25: seo | E25: 7 | F25: 8
A26: S02 | B26: SEO seguimiento | C26: seo | E26: 8 | F26: 8
A27: S02 | B27: SEO seguimiento | C27: seo | E27: 9 | F27: 8
A28: S02 | B28: SEO seguimiento | C28: seo | E28: 10 | F28: 8
A29: S02 | B29: SEO seguimiento | C29: seo | E29: 11 | F29: 8
A30: S02 | B30: SEO seguimiento | C30: seo | E30: 12 | F30: 8
... A169: G04 | B169: Cuatro adaptaciones | C169: designer | E169: 12 | F169: 8
A170: W01 | B170: WordPress hub | C170: wordpress | D170: ECG-012 | E170: 1 | F170: 40
A171: W02 | B171: Carga artículos | C171: wordpress | D171: ECG-012 | E171: 1 | F171: 2
A172: W02 | B172: Carga artículos | C172: wordpress | D172: ECG-012 | E172: 2 | F172: 2
A173: W02 | B173: Carga artículos | C173: wordpress | D173: ECG-012 | E173: 3 | F173: 2
A174: W02 | B174: Carga artículos | C174: wordpress | D174: ECG-012 | E174: 4 | F174: 2
A175: W02 | B175: Carga artículos | C175: wordpress | D175: ECG-012 | E175: 5 | F175: 2
A176: W02 | B176: Carga artículos | C176: wordpress | D176: ECG-012 | E176: 6 | F176: 2
A177: W02 | B177: Carga artículos | C177: wordpress | D177: ECG-012 | E177: 7 | F177: 2
A178: W02 | B178: Carga artículos | C178: wordpress | D178: ECG-012 | E178: 8 | F178: 2
A179: W02 | B179: Carga artículos | C179: wordpress | D179: ECG-012 | E179: 9 | F179: 2
A180: W02 | B180: Carga artículos | C180: wordpress | D180: ECG-012 | E180: 10 | F180: 2
A181: W02 | B181: Carga artículos | C181: wordpress | D181: ECG-012 | E181: 11 | F181: 2
... A296: M01 | B296: Coordinación | C296: coordination | D296: ECG-016 | E296: 12 | F296: 6

Sheet Asignacion
A1: group | B1: month | C1: base_hours | D1: hours_with_reserve | E1: productive_capacity_assumed | F1: headroom_hours | G1: status
A2: writer | B2: 1 | C2: 42 | D2: 48.3 | E2: 60 | F2: 11.7 | G2: proposed_allocation_not_confirmed_availability_or_competencies
A3: writer | B3: 2 | C3: 42 | D3: 48.3 | E3: 60 | F3: 11.7 | G3: proposed_allocation_not_confirmed_availability_or_competencies
A4: writer | B4: 3 | C4: 46 | D4: 52.9 | E4: 60 | F4: 7.1 | G4: proposed_allocation_not_confirmed_availability_or_competencies
A5: writer | B5: 4 | C5: 42 | D5: 48.3 | E5: 60 | F5: 11.7 | G5: proposed_allocation_not_confirmed_availability_or_competencies
A6: writer | B6: 5 | C6: 46 | D6: 52.9 | E6: 60 | F6: 7.1 | G6: proposed_allocation_not_confirmed_availability_or_competencies
A7: writer | B7: 6 | C7: 42 | D7: 48.3 | E7: 60 | F7: 11.7 | G7: proposed_allocation_not_confirmed_availability_or_competencies
A8: writer | B8: 7 | C8: 42 | D8: 48.3 | E8: 60 | F8: 11.7 | G8: proposed_allocation_not_confirmed_availability_or_competencies
A9: writer | B9: 8 | C9: 46 | D9: 52.9 | E9: 60 | F9: 7.1 | G9: proposed_allocation_not_confirmed_availability_or_competencies
A10: writer | B10: 9 | C10: 42 | D10: 48.3 | E10: 60 | F10: 11.7 | G10: proposed_allocation_not_confirmed_availability_or_competencies
A11: writer | B11: 10 | C11: 42 | D11: 48.3 | E11: 60 | F11: 11.7 | G11: proposed_allocation_not_confirmed_availability_or_competencies
A12: writer | B12: 11 | C12: 46 | D12: 52.9 | E12: 60 | F12: 7.1 | G12: proposed_allocation_not_confirmed_availability_or_competencies
A13: writer | B13: 12 | C13: 42 | D13: 48.3 | E13: 60 | F13: 11.7 | G13: proposed_allocation_not_confirmed_availability_or_competencies
... A37: seo | B37: 12 | C37: 28 | D37: 32.2 | E37: 120 | F37: 87.8 | G37: proposed_allocation_not_confirmed_availability_or_competencies

Sheet Conversion existente
A1: existing_visits_example | B1: opening_rate_test | C1: funding_rate_test | D1: funded_reference_test | E1: funded_improved_test | F1: difference_test | G1: nature
A2: 10000 | B2: 0.03 | C2: 0.65 | D2: 130 | E2: 195 | F2: 65 | G2: sensitivity_not_observed_volume_not_causal_lift_not_added_to_panel
A3: 10000 | B3: 0.02 | C3: 0.75 | D3: 130 | E3: 150 | F3: 20 | G3: sensitivity_not_observed_volume_not_causal_lift_not_added_to_panel
A4: 10000 | B4: 0.03 | C4: 0.75 | D4: 130 | E4: 225 | F4: 95 | G4: sensitivity_not_observed_volume_not_causal_lift_not_added_to_panel
A5: 100000 | B5: 0.03 | C5: 0.65 | D5: 1300 | E5: 1950 | F5: 650 | G5: sensitivity_not_observed_volume_not_causal_lift_not_added_to_panel
A6: 100000 | B6: 0.02 | C6: 0.75 | D6: 1300 | E6: 1500 | F6: 200 | G6: sensitivity_not_observed_volume_not_causal_lift_not_added_to_panel
A7: 100000 | B7: 0.03 | C7: 0.75 | D7: 1300 | E7: 2250 | F7: 950 | G7: sensitivity_not_observed_volume_not_causal_lift_not_added_to_panel

Sheet Aporte por familia
A1: scenario | B1: family_id | C1: family | D1: lane | E1: annual_visit_equivalents_test | F1: openings_test | G1: funded_test | H1: ready_month | I1: asset
A2: prudente | B2: G01 | C2: Cuenta de ahorro | D2: direct | E2: 498.8 | F2: 9.976 | G2: 6.4844 | H2: 1 | I2: Pilar
A3: prudente | B3: G02 | C3: Intereses sobre ahorro | D3: direct | E3: 31.92 | F3: 0.6384 | G3: 0.41496 | H3: 2 | I3: Calculadora / ART-03
A4: prudente | B4: G03 | C4: Comparar cuentas en Perú | D4: direct | E4: 42.24 | F4: 0.8448 | G4: 0.54912 | H4: 3 | I4: ART-05 / Comparador
A5: prudente | B5: G04 | C5: Abrir una cuenta de ahorro | D5: direct | E5: 36.12 | F5: 0.7224 | G5: 0.46956 | H5: 1 | I5: ART-02
A6: prudente | B6: G05 | C6: Costos de mantenimiento | D6: direct | E6: 8.6 | F6: 0.172 | G6: 0.1118 | H6: 1 | I6: Pilar
A7: prudente | B7: G06 | C7: Requisitos de apertura | D7: direct | E7: 8.6 | F7: 0.172 | G7: 0.1118 | H7: 1 | I7: ART-02
A8: prudente | B8: C01 | C8: Ahorro de alto rendimiento | D8: conditional | E8: 243.2 | F8: 4.864 | G8: 3.1616 | H8: 2 | I8: Pilar / ART-03
A9: prudente | B9: C02 | C9: Cuenta digital | D9: conditional | E9: 223.6 | F9: 4.472 | G9: 2.9068 | H9: 1 | I9: Pilar / ART-02
A10: prudente | B10: C03 | C10: Dónde ahorrar y ganar intereses | D10: conditional | E10: 51.48 | F10: 1.0296 | G10: 0.66924 | H10: 3 | I10: ART-05
A11: prudente | B11: C04 | C11: Qué banco paga más intereses Perú | D11: conditional | E11: 5.28 | F11: 0.1056 | G11: 0.06864 | H11: 3 | I11: ART-05
A12: prudente | B12: B01 | C12: Ahorro BCP | D12: competitor | E12: 343.2 | F12: 6.864 | G12: 4.4616 | H12: 7 | I12: ART-13
A13: prudente | B13: B02 | C13: Súper Tasa Interbank | D13: competitor | E13: 174.8 | F13: 3.496 | G13: 2.2724 | H13: 5 | I13: ART-10
... A58: expansion | B58: E04 | C58: Cómo ahorrar dinero | D58: assisted | E58: 389.4 | F58: 7.788 | G58: 5.0622 | H58: 3 | I58: ART-06

Sheet 24 articulos
A1: id | B1: mes_propuesto | C1: territorio | D1: tema_candidato | E1: trabajo_usuario | F1: siguiente_paso | G1: estado | H1: condicion | I1: version | J1: families_measured | K1: traffic_credit | L1: proposed_priority_month | M1: priority_change_status
A2: ART-01 | B2: 1 | C2: Rendimiento | D2: Cómo interpretar la TREA y las condiciones de una cuenta | E2: Comprender | F2: Calculadora/producto | G2: Candidato no publicado ni costeado | H2: Fuentes y revisión Producto/Cumplimiento; comprobar intención distinta y no duplicar URL existente | I2: v0.7 | J2: E01 | K2: Only through mapped family; no extra traffic per article | L2: 1 | M2: Recommendation only; source calendar and baseline sensitivity unchanged
A3: ART-02 | B3: 1 | C3: Apertura | D3: Qué revisar antes de abrir una cuenta de ahorro digital | E3: Decidir | F3: Pilar/registro | G3: Candidato no publicado ni costeado | H3: Fuentes y revisión Producto/Cumplimiento; comprobar intención distinta y no duplicar URL existente | I3: v0.7 | J3: G04;G06;C02 | K3: Only through mapped family; no extra traffic per article | L3: 1 | M3: Recommendation only; source calendar and baseline sensitivity unchanged
A4: ART-03 | B4: 2 | C4: Rendimiento | D4: Cómo calcular intereses con un ejemplo reproducible | E4: Aplicar | F4: Calculadora | G4: Candidato no publicado ni costeado | H4: Fuentes y revisión Producto/Cumplimiento; comprobar intención distinta y no duplicar URL existente | I4: v0.7 | J4: G02;C01 | K4: Only through mapped family; no extra traffic per article | L4: 2 | M4: Recommendation only; source calendar and baseline sensitivity unchanged
A5: ART-04 | B5: 2 | C5: Primer fondeo | D5: Cómo preparar la primera transferencia hacia tu cuenta | E5: Actuar | F5: Ayuda oficial/producto | G5: Candidato no publicado ni costeado | H5: Fuentes y revisión Producto/Cumplimiento; comprobar intención distinta y no duplicar URL existente | I5: v0.7 | K5: Support/activation/maintenance; no standalone search volume credited | L5: 2 | M5: Recommendation only; source calendar and baseline sensitivity unchanged
A6: ART-05 | B6: 3 | C6: Comparación | D6: Cómo comparar rendimiento, costos y liquidez | E6: Evaluar | F6: Comparador/pilar | G6: Candidato no publicado ni costeado | H6: Fuentes y revisión Producto/Cumplimiento; comprobar intención distinta y no duplicar URL existente | I6: v0.7 | J6: G03;C03;C04 | K6: Only through mapped family; no extra traffic per article | L6: 3 | M6: Recommendation only; source calendar and baseline sensitivity unchanged
A7: ART-06 | B7: 3 | C7: Ahorro disponible | D7: Cómo separar ahorro y dinero para pagos | E7: Comprender | F7: Pilar | G7: Candidato no publicado ni costeado | H7: Fuentes y revisión Producto/Cumplimiento; comprobar intención distinta y no duplicar URL existente | I7: v0.7 | J7: E04 | K7: Only through mapped family; no extra traffic per article | L7: 5 | M7: Recommendation only; source calendar and baseline sensitivity unchanged
A8: ART-07 | B8: 4 | C8: Comparación | D8: Cómo elegir entre cuentas con condiciones distintas | E8: Evaluar | F8: Comparador | G8: Candidato no publicado ni costeado | H8: Fuentes y revisión Producto/Cumplimiento; comprobar intención distinta y no duplicar URL existente | I8: v0.7 | K8: Support/activation/maintenance; no standalone search volume credited | L8: 7 | M8: Recommendation only; source calendar and baseline sensitivity unchanged
A9: ART-08 | B9: 4 | C9: Confianza | D9: Qué fuentes consultar para comprobar respaldo y condiciones | E9: Verificar | F9: Documentos/pilar | G9: Candidato no publicado ni costeado | H9: Fuentes y revisión Producto/Cumplimiento; comprobar intención distinta y no duplicar URL existente | I9: v0.7 | J9: E02 | K9: Only through mapped family; no extra traffic per article | L9: 4 | M9: Recommendation only; source calendar and baseline sensitivity unchanged
A10: ART-09 | B10: 5 | C10: Rendimiento | D10: Qué cambia al comparar tasa anunciada y rendimiento bajo condiciones | E10: Evaluar | F10: Calculadora | G10: Candidato no publicado ni costeado | H10: Fuentes y revisión Producto/Cumplimiento; comprobar intención distinta y no duplicar URL existente | I10: v0.7 | K10: Support/activation/maintenance; no standalone search volume credited | L10: 6 | M10: Recommendation only; source calendar and baseline sensitivity unchanged
A11: ART-10 | B11: 5 | C11: Comparación | D11: Alternativas de ahorro: Interbank sólo si se aprueba comparabilidad | E11: Evaluar | F11: Comparador/pilar | G11: Candidato no publicado ni costeado | H11: Fuentes y revisión Producto/Cumplimiento; comprobar intención distinta y no duplicar URL existente; aprobación específica de marcas; alternativa general sin marcas dentro del slot | I11: v0.7 | J11: B02 | K11: Only through mapped family; no extra traffic per article | L11: 3 | M11: Recommendation only; source calendar and baseline sensitivity unchanged
A12: ART-11 | B12: 6 | C12: Ahorro disponible | D12: Cómo definir una meta de ahorro y revisar sus supuestos | E12: Aplicar | F12: Planificador | G12: Candidato no publicado ni costeado | H12: Fuentes y revisión Producto/Cumplimiento; comprobar intención distinta y no duplicar URL existente | I12: v0.7 | K12: Support/activation/maintenance; no standalone search volume credited | L12: 8 | M12: Recommendation only; source calendar and baseline sensitivity unchanged
A13: ART-12 | B13: 6 | C13: Comparación | D13: Alternativas de ahorro: Scotiabank sólo con fuentes y aprobación | E13: Evaluar | F13: Comparador/pilar | G13: Candidato no publicado ni costeado | H13: Fuentes y revisión Producto/Cumplimiento; comprobar intención distinta y no duplicar URL existente; aprobación específica de marcas; alternativa general sin marcas dentro del slot | I13: v0.7 | J13: B03;B04 | K13: Only through mapped family; no extra traffic per article | L13: 5 | M13: Recommendation only; source calendar and baseline sensitivity unchanged
A14: ART-13 | B14: 7 | C14: Comparación | D14: Alternativas de ahorro: BCP sólo con intención y aprobación | E14: Evaluar | F14: Comparador/pilar | G14: Candidato no publicado ni costeado | H14: Fuentes y revisión Producto/Cumplimiento; comprobar intención distinta y no duplicar URL existente; aprobación específica de marcas; alternativa general sin marcas dentro del slot | I14: v0.7 | J14: B01 | K14: Only through mapped family; no extra traffic per article | L14: 4 | M14: Recommendation only; source calendar and baseline sensitivity unchanged
A15: ART-14 | B15: 7 | C15: Apertura | D15: Cómo resolver dudas entre elegir la cuenta y comenzar el registro | E15: Actuar | F15: Registro/ayuda | G15: Candidato no publicado ni costeado | H15: Fuentes y revisión Producto/Cumplimiento; comprobar intención distinta y no duplicar URL existente | I15: v0.7 | K15: Support/activation/maintenance; no standalone search volume credited | L15: 7 | M15: Recommendation only; source calendar and baseline sensitivity unchanged
A16: ART-15 | B16: 8 | C16: Ahorro disponible | D16: Cómo planificar ahorro disponible para imprevistos | E16: Aplicar | F16: Planificador | G16: Candidato no publicado ni costeado | H16: Fuentes y revisión Producto/Cumplimiento; comprobar intención distinta y no duplicar URL existente | I16: v0.7 | K16: Support/activation/maintenance; no standalone search volume credited | L16: 8 | M16: Recommendation only; source calendar and baseline sensitivity unchanged
A17: ART-16 | B17: 8 | C17: Comparación | D17: Alternativas de ahorro: BBVA sólo si confirma encaje y aprobación | E17: Evaluar | F17: Comparador/pilar | G17: Candidato no publicado ni costeado | H17: Fuentes y revisión Producto/Cumplimiento; comprobar intención distinta y no duplicar URL existente; aprobación específica de marcas; alternativa general sin marcas dentro del slot | I17: v0.7 | J17: B05 | K17: Only through mapped family; no extra traffic per article | L17: 6 | M17: Recommendation only; source calendar and baseline sensitivity unchanged
A18: ART-17 | B18: 9 | C18: Ahorro disponible | D18: Liquidez y plazo: preguntas para comparar necesidades | E18: Evaluar | F18: Guía/pilar | G18: Candidato no publicado ni costeado | H18: Fuentes y revisión Producto/Cumplimiento; comprobar intención distinta y no duplicar URL existente | I18: v0.7 | K18: Support/activation/maintenance; no standalone search volume credited | L18: 9 | M18: Recommendation only; source calendar and baseline sensitivity unchanged
A19: ART-18 | B19: 9 | C19: Primer fondeo | D19: Cómo identificar el canal oficial para resolver dudas de transferencias | E19: Actuar | F19: Ayuda/producto | G19: Candidato no publicado ni costeado | H19: Fuentes y revisión Producto/Cumplimiento; comprobar intención distinta y no duplicar URL existente | I19: v0.7 | K19: Support/activation/maintenance; no standalone search volume credited | L19: 9 | M19: Recommendation only; source calendar and baseline sensitivity unchanged
A20: ART-19 | B20: 10 | C20: Confianza | D20: Cómo reconocer la identidad y canales oficiales de Pibank | E20: Verificar | F20: Identidad/pilar | G20: Candidato no publicado ni costeado | H20: Fuentes y revisión Producto/Cumplimiento; comprobar intención distinta y no duplicar URL existente | I20: v0.7 | K20: Support/activation/maintenance; no standalone search volume credited | L20: 10 | M20: Recommendation only; source calendar and baseline sensitivity unchanged
A21: ART-20 | B21: 10 | C21: Rendimiento | D21: Cómo revisar condiciones cuando cambian las tasas | E21: Verificar | F21: Documentos/calculadora | G21: Candidato no publicado ni costeado | H21: Fuentes y revisión Producto/Cumplimiento; comprobar intención distinta y no duplicar URL existente | I21: v0.7 | K21: Support/activation/maintenance; no standalone search volume credited | L21: 10 | M21: Recommendation only; source calendar and baseline sensitivity unchanged
A22: ART-21 | B22: 11 | C22: Comparación | D22: Cómo actualizar una comparación manteniendo el mismo método | E22: Evaluar | F22: Comparador/pilar | G22: Candidato no publicado ni costeado | H22: Fuentes y revisión Producto/Cumplimiento; comprobar intención distinta y no duplicar URL existente | I22: v0.7 | K22: Support/activation/maintenance; no standalone search volume credited | L22: 11 | M22: Recommendation only; source calendar and baseline sensitivity unchanged
A23: ART-22 | B23: 11 | C23: Ahorro disponible | D23: Cómo revisar tu planificación de ahorro al cierre del año | E23: Aplicar | F23: Planificador | G23: Candidato no publicado ni costeado | H23: Fuentes y revisión Producto/Cumplimiento; comprobar intención distinta y no duplicar URL existente | I23: v0.7 | K23: Support/activation/maintenance; no standalone search volume credited | L23: 11 | M23: Recommendation only; source calendar and baseline sensitivity unchanged
A24: ART-23 | B24: 12 | C24: Apertura | D24: Preguntas de apertura priorizadas por evidencia del recorrido | E24: Decidir | F24: Pilar/registro | G24: Candidato no publicado ni costeado | H24: Fuentes y revisión Producto/Cumplimiento; comprobar intención distinta y no duplicar URL existente | I24: v0.7 | K24: Support/activation/maintenance; no standalone search volume credited | L24: 12 | M24: Recommendation only; source calendar and baseline sensitivity unchanged
A25: ART-24 | B25: 12 | C25: Primer fondeo | D25: Preguntas de primer depósito priorizadas por cohortes y comunidad | E25: Actuar | F25: Ayuda oficial | G25: Candidato no publicado ni costeado | H25: Fuentes y revisión Producto/Cumplimiento; comprobar intención distinta y no duplicar URL existente | I25: v0.7 | K25: Support/activation/maintenance; no standalone search volume credited | L25: 12 | M25: Recommendation only; source calendar and baseline sensitivity unchanged

Sheet Prioridad calendario
A1: scenario | B1: original_calendar_visit_equivalents | C1: proposed_calendar_visit_equivalents | D1: difference_from_timing_only | E1: funded_difference_test | F1: status
A2: prudente | B2: 2993.2 | C2: 3743.2 | D2: 750 | E2: 9.75 | F2: same_sources_and_capture; shift_four_comparatives_and_support_slots; no_new_articles
A3: trabajo | B3: 7483 | C3: 9358 | D3: 1875 | E3: 24.375 | F3: same_sources_and_capture; shift_four_comparatives_and_support_slots; no_new_articles
A4: expansion | B4: 14966 | C4: 18716 | D4: 3750 | E4: 48.75 | F4: same_sources_and_capture; shift_four_comparatives_and_support_slots; no_new_articles

Sheet Fuentes
A1: Archivo | B1: SHA256
A2: docs/commercial/prospects/banco-pichincha-peru-seo-2026/research/pibank-gap-closure-2026-10-06/plan-busquedas.csv | B2: 0731a5188dd1f54b642766b6390b7834ecd2f6bb70170b2582a4275f15919b79
A3: docs/commercial/prospects/banco-pichincha-peru-seo-2026/reconstruccion-2027/economia/inputs.json | B3: 6b380318e10f99fb2d2771339f5bf531d15b45174e08ace25e2e797549cf55fa
A4: docs/commercial/prospects/banco-pichincha-peru-seo-2026/reconstruccion-2027/economia/results.json | B4: f1744c61b7aa9e13ca8a6a397c47ee65481ad9d7edf3d65364f042fb0d3e7d2e
A5: docs/commercial/prospects/banco-pichincha-peru-seo-2026/reconstruccion-2027/economia/Pibank-decision-inversion-2027.xlsx | B5: d87c2aabdf7a3a04ff59a719c48a747ab19a3d689eaa14e6d22427d455f7207e
A6: docs/commercial/prospects/banco-pichincha-peru-seo-2026/reconstruccion-2027/meta-hacia-atras/resultados.json | B6: 3d93519189a3d32b56da7708016cb39ca8c4496add52bbe93d15e2b169268094
A7: docs/commercial/prospects/banco-pichincha-peru-seo-2026/reconstruccion-2027/PLAN-DE-CONTENIDOS-V0.7.csv | B7: 28485eeeb6b0e2de7879738df5890f94256e48efd3c6ef2b22ae2cc08651f84a
A8: docs/commercial/prospects/banco-pichincha-peru-seo-2026/reconstruccion-2027/CALENDARIO-CRECIMIENTO-V0.7.csv | B8: 1e3dbb23fb4b4e21f3f0a99cdafe2f0416b0e83f2a7ee7b57a3f3b233c0cbf2a
