Workbook

Sheet Resumen
C2: Pibank: programa anual 2027
C4: Escenario seleccionado | D4: =Supuestos!D5 -> Base
C5: 12 meses 2027. Hipótesis condicionadas para preparar la propuesta; no forecast bancario ni retorno garantizado.
C7: Resultado anual dentro de 2027 | D7: Caso activo | E7: Unidad
C8: Visitas adicionales | D8: =IF(COUNT(Mensual!F16:Q16)=12,SUM(Mensual!F16:Q16),"N/D") -> 3874.5 | E8: visitas
C9: Aperturas incrementales | D9: =IF(COUNT(Mensual!F21:Q21)=12,SUM(Mensual!F21:Q21),"N/D") -> 77.49 | E9: cuentas
C10: Primer fondeo incremental dentro de 2027 | D10: =IF(COUNT(Mensual!F28:Q28)=12,SUM(Mensual!F28:Q28),"N/D") -> 50.3685 | E10: cuentas
C11: Primer fondeo programado después de 2027 | D11: =IF(COUNT(Mensual!F25:Q25,Mensual!F28:Q28)=24,SUM(Mensual!F25:Q25)-SUM(Mensual!F28:Q28),"N/D") -> 0 | E11: cuentas
C12: Depósito inicial bruto dentro de 2027 | D12: =IF(COUNT(D10,Supuestos!D10)=2,D10*Supuestos!D10,"N/D") -> 125921.25 | E12: USD eq.
C13: Saldo mantenido al cierre 2027 | D13: =Mensual!Q35 -> 109054.68 | E13: USD eq.
C14: Saldo externo al cierre 2027 | D14: =Mensual!Q36 -> 76338.274 | E14: USD eq.
C15: Saldo medio externo en 2027 | D15: =IF(COUNT(Mensual!F38:Q38)=12,AVERAGE(Mensual!F38:Q38),"N/D") -> 23973.872 | E15: USD eq.
C16: Escala/meta cuentas provisional | D16: =IF(AND(COUNT(D10,Supuestos!D8)=2,Supuestos!D8>0),D10/Supuestos!D8,"N/D") -> 0.0033137171 | E16: %
C18: Inversión cliente anual pendiente | D18: =Supuestos!D23 -> N/D | E18: USD
C19: CAC de cuenta fondeada incremental | D19: =IF(AND(Supuestos!D16="Sí",COUNT(D18,D10)=2,D18>0,D10>0),D18/D10,"N/D") -> N/D | E19: USD
C20: ROI dentro de 2027 | D20: =Mensual!Q44 -> N/D | E20: %
C21: Payback dentro de 2027 | D21: =IF(COUNT(Mensual!F46:Q46)=12,IFERROR(MATCH(1,Mensual!F46:Q46,0),"No en2027"),"N/D") -> N/D | E21: mes
C23: Saldo no es revenue. ROI/payback requieren inversión y Finance validados. Ninguna cohorte aporta valor después del horizonte.
C25: Mes | D25: Visitas adicionales | E25: Primer fondeo inc. | F25: Saldo cierre USD eq. | G25: Saldo externo USD eq. | H25: Saldo medio externo
C26: =Mensual!F8 -> 46388 | D26: =Mensual!F16 -> 13.8375 | E26: =Mensual!F28 -> 0.1798875 | F26: =Mensual!F35 -> 437.72625 | G26: =Mensual!F36 -> 306.40837 | H26: =Mensual!F38 -> 170.33219
C27: =Mensual!G8 -> 46419 | D27: =Mensual!G16 -> 41.5125 | E27: =Mensual!G28 -> 0.5396625 | F27: =Mensual!G35 -> 1736.6639 | G27: =Mensual!G36 -> 1215.6647 | H27: =Mensual!G38 -> 766.15211
C28: =Mensual!H8 -> 46447 | D28: =Mensual!H16 -> 83.025 | E28: =Mensual!H28 -> 1.079325 | F28: =Mensual!H35 -> 4270.0795 | G28: =Mensual!H36 -> 2989.0557 | H28: =Mensual!H38 -> 2205.1282
C29: =Mensual!I8 -> 46478 | D29: =Mensual!I16 -> 138.375 | E29: =Mensual!I28 -> 1.798875 | F29: =Mensual!I35 -> 8437.4733 | G29: =Mensual!I36 -> 5906.2313 | H29: =Mensual!I38 -> 4570.9414
C30: =Mensual!J8 -> 46508 | D30: =Mensual!J16 -> 207.5625 | E30: =Mensual!J28 -> 2.6983125 | F30: =Mensual!J35 -> 14576.634 | G30: =Mensual!J36 -> 10203.644 | H30: =Mensual!J38 -> 8311.8575
C31: =Mensual!K8 -> 46539 | D31: =Mensual!K16 -> 276.75 | E31: =Mensual!K28 -> 3.59775 | F31: =Mensual!K35 -> 22670.072 | G31: =Mensual!K36 -> 15869.051 | H31: =Mensual!K38 -> 13282.943
C32: =Mensual!L8 -> 46569 | D32: =Mensual!L16 -> 345.9375 | E32: =Mensual!L28 -> 4.4971875 | F32: =Mensual!L35 -> 32577.309 | G32: =Mensual!L36 -> 22804.116 | H32: =Mensual!L38 -> 19764.783
C33: =Mensual!M8 -> 46600 | D33: =Mensual!M16 -> 415.125 | E33: =Mensual!M28 -> 5.396625 | F33: =Mensual!M35 -> 44305.501 | G33: =Mensual!M36 -> 31013.851 | H33: =Mensual!M38 -> 27422.823
C34: =Mensual!N8 -> 46631 | D34: =Mensual!N16 -> 484.3125 | E34: =Mensual!N28 -> 6.2960625 | F34: =Mensual!N35 -> 57903.288 | G34: =Mensual!N36 -> 40532.301 | H34: =Mensual!N38 -> 36204.619
C35: =Mensual!O8 -> 46661 | D35: =Mensual!O16 -> 553.5 | E35: =Mensual!O28 -> 7.1955 | F35: =Mensual!O35 -> 73184.17 | G35: =Mensual!O36 -> 51228.919 | H35: =Mensual!O38 -> 46565.73
C36: =Mensual!P8 -> 46692 | D36: =Mensual!P16 -> 622.6875 | E36: =Mensual!P28 -> 8.0949375 | F36: =Mensual!P35 -> 90323.317 | G36: =Mensual!P36 -> 63226.322 | H36: =Mensual!P38 -> 57782.461
C37: =Mensual!Q8 -> 46722 | D37: =Mensual!Q16 -> 691.875 | E37: =Mensual!Q28 -> 8.994375 | F37: =Mensual!Q35 -> 109054.68 | G37: =Mensual!Q36 -> 76338.274 | H37: =Mensual!Q38 -> 70638.698
C40: M 1: acceso/medición/delivery. M 3/6/9/12: optimización trimestral. No pilotoSEO ni juicio de viabilidad a 3 meses.
C41: Demanda histórica y alcance de investigación se leen en Demanda/Historia; los drivers 2027 continúan siendo hipótesis.
C42: US$38 m y ticketUS$2500 provisionales; anualidad de la meta aún no confirmada. USD eq.no significa productoUSD disponible.
C43: Origen externo fijo por cohorte. Saldo medio pondera días activos; diciembre tiene menos tiempo de contribución que enero.
C45: Cambiar selector en SupuestosD 4. Cambiar lagD 18/díaD 19 o tasas actualiza el mismo build; fuentes históricas permanecen intactas.

Sheet Supuestos
C2: Controles y drivers 2027
C4: Selector escenario (1 / 2 / 3) | D4: 2
C5: Caso activo | D5: =CHOOSE(D4,"Conservador","Base","Favorable") -> Base
C6: 1 Conservador, 2 Base, 3 Favorable. Casos de prueba; nombres no representan probabilidades.
C8: Meta cuentas provisional | D8: 15200
C9: Meta USD provisional | D9: 38000000
C10: Ticket USD equivalente provisional | D10: 2500
C11: Inicio ilustrativo | D11: 46388
C12: US$38 m es inferencia provisional. Programa anual 2027 no confirma periodo ni definición de la meta bancaria.
C13: Relevancia/elegibilidad ilustrativa | D13: 0.75
C14: Finance validó método neto | D14: No
C15: Valor neto anual / USD saldo externo
C16: Inversión completa validada | D16: No
C17: Capacidad total con reserva (horas) | D17: 2896
C18: Lag apertura a fondeo (meses) | D18: 0
C19: Día fondeo supuesto (1–28) | D19: 15
C20: Proxy mensual de fuente histórica | D20: =Demanda!J5 -> 3690
F21: =EDATE($D$11,0) -> 46388 | G21: =EDATE($D$11,1) -> 46419 | H21: =EDATE($D$11,2) -> 46447 | I21: =EDATE($D$11,3) -> 46478 | J21: =EDATE($D$11,4) -> 46508 | K21: =EDATE($D$11,5) -> 46539 | L21: =EDATE($D$11,6) -> 46569 | M21: =EDATE($D$11,7) -> 46600 | N21: =EDATE($D$11,8) -> 46631 | O21: =EDATE($D$11,9) -> 46661 | P21: =EDATE($D$11,10) -> 46692 | Q21: =EDATE($D$11,11) -> 46722
C22: Inversión cliente por mes USD (pendiente)
C23: Inversión anual si completa | D23: =IF(COUNT(F22:Q22)=12,IF(MIN(F22:Q22)>=0,SUM(F22:Q22),"N/D"),"N/D") -> N/D
C24: Coste interno Efeonce USD (pendiente)
C25: Multiplicador crecimiento 2027 supuesto | D25: 1
C26: Estacionalidad usada | D26: Plano
C27: Factor histórico observado / promedio | F27: =IF(COUNT(Historia!F11)=1,Historia!F11,"N/D") -> 1.0884184 | G27: =IF(COUNT(Historia!G11)=1,Historia!G11,"N/D") -> 0.91905355 | H27: =IF(COUNT(Historia!H11)=1,Historia!H11,"N/D") -> 1.2104608 | I27: =IF(COUNT(Historia!I11)=1,Historia!I11,"N/D") -> 1.1058531 | J27: =IF(COUNT(Historia!J11)=1,Historia!J11,"N/D") -> 0.92403487 | K27: =IF(COUNT(Historia!K11)=1,Historia!K11,"N/D") -> 0.73723537 | L27: =IF(COUNT(Historia!L11)=1,Historia!L11,"N/D") -> 0.87920299 | M27: =IF(COUNT(Historia!M11)=1,Historia!M11,"N/D") -> 0.86924035 | ... Q27: =IF(COUNT(Historia!Q11)=1,Historia!Q11,"N/D") -> 0.90161893
C28: Factor usado en hipótesis 2027 | F28: =IF($D$26="Plano",1,F27) -> 1 | G28: =IF($D$26="Plano",1,G27) -> 1 | H28: =IF($D$26="Plano",1,H27) -> 1 | I28: =IF($D$26="Plano",1,I27) -> 1 | J28: =IF($D$26="Plano",1,J27) -> 1 | K28: =IF($D$26="Plano",1,K27) -> 1 | L28: =IF($D$26="Plano",1,L27) -> 1 | M28: =IF($D$26="Plano",1,M27) -> 1 | ... Q28: =IF($D$26="Plano",1,Q27) -> 1
C30: Captura adicional activo | F30: =IF(CHOOSE($D$4,COUNT(F31),COUNT(F32),COUNT(F33))=1,CHOOSE($D$4,F31,F32,F33),"N/D") -> 0.005 | G30: =IF(CHOOSE($D$4,COUNT(G31),COUNT(G32),COUNT(G33))=1,CHOOSE($D$4,G31,G32,G33),"N/D") -> 0.015 | H30: =IF(CHOOSE($D$4,COUNT(H31),COUNT(H32),COUNT(H33))=1,CHOOSE($D$4,H31,H32,H33),"N/D") -> 0.03 | I30: =IF(CHOOSE($D$4,COUNT(I31),COUNT(I32),COUNT(I33))=1,CHOOSE($D$4,I31,I32,I33),"N/D") -> 0.05 | J30: =IF(CHOOSE($D$4,COUNT(J31),COUNT(J32),COUNT(J33))=1,CHOOSE($D$4,J31,J32,J33),"N/D") -> 0.075 | K30: =IF(CHOOSE($D$4,COUNT(K31),COUNT(K32),COUNT(K33))=1,CHOOSE($D$4,K31,K32,K33),"N/D") -> 0.1 | L30: =IF(CHOOSE($D$4,COUNT(L31),COUNT(L32),COUNT(L33))=1,CHOOSE($D$4,L31,L32,L33),"N/D") -> 0.125 | M30: =IF(CHOOSE($D$4,COUNT(M31),COUNT(M32),COUNT(M33))=1,CHOOSE($D$4,M31,M32,M33),"N/D") -> 0.15 | ... Q30: =IF(CHOOSE($D$4,COUNT(Q31),COUNT(Q32),COUNT(Q33))=1,CHOOSE($D$4,Q31,Q32,Q33),"N/D") -> 0.25
C31: Conservador | F31: 0.0025 | G31: 0.005 | H31: 0.01 | I31: 0.02 | J31: 0.035 | K31: 0.05 | L31: 0.065 | M31: 0.08 | N31: 0.095 | O31: 0.11 | P31: 0.12 | Q31: 0.13
C32: Base | F32: 0.005 | G32: 0.015 | H32: 0.03 | I32: 0.05 | J32: 0.075 | K32: 0.1 | L32: 0.125 | M32: 0.15 | N32: 0.175 | O32: 0.2 | P32: 0.225 | Q32: 0.25
C33: Favorable | F33: 0.01 | G33: 0.025 | H33: 0.05 | I33: 0.075 | J33: 0.1 | K33: 0.15 | L33: 0.2 | M33: 0.25 | N33: 0.3 | O33: 0.35 | P33: 0.4 | Q33: 0.45
C35: Captura referencia activo | F35: =IF(CHOOSE($D$4,COUNT(F36),COUNT(F37),COUNT(F38))=1,CHOOSE($D$4,F36,F37,F38),"N/D") -> 0.01 | G35: =IF(CHOOSE($D$4,COUNT(G36),COUNT(G37),COUNT(G38))=1,CHOOSE($D$4,G36,G37,G38),"N/D") -> 0.01 | H35: =IF(CHOOSE($D$4,COUNT(H36),COUNT(H37),COUNT(H38))=1,CHOOSE($D$4,H36,H37,H38),"N/D") -> 0.01 | I35: =IF(CHOOSE($D$4,COUNT(I36),COUNT(I37),COUNT(I38))=1,CHOOSE($D$4,I36,I37,I38),"N/D") -> 0.01 | J35: =IF(CHOOSE($D$4,COUNT(J36),COUNT(J37),COUNT(J38))=1,CHOOSE($D$4,J36,J37,J38),"N/D") -> 0.01 | K35: =IF(CHOOSE($D$4,COUNT(K36),COUNT(K37),COUNT(K38))=1,CHOOSE($D$4,K36,K37,K38),"N/D") -> 0.01 | L35: =IF(CHOOSE($D$4,COUNT(L36),COUNT(L37),COUNT(L38))=1,CHOOSE($D$4,L36,L37,L38),"N/D") -> 0.01 | M35: =IF(CHOOSE($D$4,COUNT(M36),COUNT(M37),COUNT(M38))=1,CHOOSE($D$4,M36,M37,M38),"N/D") -> 0.01 | ... Q35: =IF(CHOOSE($D$4,COUNT(Q36),COUNT(Q37),COUNT(Q38))=1,CHOOSE($D$4,Q36,Q37,Q38),"N/D") -> 0.01
C36: Conservador | F36: 0.01 | G36: 0.01 | H36: 0.01 | I36: 0.01 | J36: 0.01 | K36: 0.01 | L36: 0.01 | M36: 0.01 | N36: 0.01 | O36: 0.01 | P36: 0.01 | Q36: 0.01
C37: Base | F37: 0.01 | G37: 0.01 | H37: 0.01 | I37: 0.01 | J37: 0.01 | K37: 0.01 | L37: 0.01 | M37: 0.01 | N37: 0.01 | O37: 0.01 | P37: 0.01 | Q37: 0.01
C38: Favorable | F38: 0.01 | G38: 0.01 | H38: 0.01 | I38: 0.01 | J38: 0.01 | K38: 0.01 | L38: 0.01 | M38: 0.01 | N38: 0.01 | O38: 0.01 | P38: 0.01 | Q38: 0.01
C40: Visita a apertura activo | F40: =IF(CHOOSE($D$4,COUNT(F41),COUNT(F42),COUNT(F43))=1,CHOOSE($D$4,F41,F42,F43),"N/D") -> 0.02 | G40: =IF(CHOOSE($D$4,COUNT(G41),COUNT(G42),COUNT(G43))=1,CHOOSE($D$4,G41,G42,G43),"N/D") -> 0.02 | H40: =IF(CHOOSE($D$4,COUNT(H41),COUNT(H42),COUNT(H43))=1,CHOOSE($D$4,H41,H42,H43),"N/D") -> 0.02 | I40: =IF(CHOOSE($D$4,COUNT(I41),COUNT(I42),COUNT(I43))=1,CHOOSE($D$4,I41,I42,I43),"N/D") -> 0.02 | J40: =IF(CHOOSE($D$4,COUNT(J41),COUNT(J42),COUNT(J43))=1,CHOOSE($D$4,J41,J42,J43),"N/D") -> 0.02 | K40: =IF(CHOOSE($D$4,COUNT(K41),COUNT(K42),COUNT(K43))=1,CHOOSE($D$4,K41,K42,K43),"N/D") -> 0.02 | L40: =IF(CHOOSE($D$4,COUNT(L41),COUNT(L42),COUNT(L43))=1,CHOOSE($D$4,L41,L42,L43),"N/D") -> 0.02 | M40: =IF(CHOOSE($D$4,COUNT(M41),COUNT(M42),COUNT(M43))=1,CHOOSE($D$4,M41,M42,M43),"N/D") -> 0.02 | ... Q40: =IF(CHOOSE($D$4,COUNT(Q41),COUNT(Q42),COUNT(Q43))=1,CHOOSE($D$4,Q41,Q42,Q43),"N/D") -> 0.02
C41: Conservador | F41: 0.01 | G41: 0.01 | H41: 0.01 | I41: 0.01 | J41: 0.01 | K41: 0.01 | L41: 0.01 | M41: 0.01 | N41: 0.01 | O41: 0.01 | P41: 0.01 | Q41: 0.01
C42: Base | F42: 0.02 | G42: 0.02 | H42: 0.02 | I42: 0.02 | J42: 0.02 | K42: 0.02 | L42: 0.02 | M42: 0.02 | N42: 0.02 | O42: 0.02 | P42: 0.02 | Q42: 0.02
C43: Favorable | F43: 0.03 | G43: 0.03 | H43: 0.03 | I43: 0.03 | J43: 0.03 | K43: 0.03 | L43: 0.03 | M43: 0.03 | N43: 0.03 | O43: 0.03 | P43: 0.03 | Q43: 0.03
C45: Apertura a fondeo activo | F45: =IF(CHOOSE($D$4,COUNT(F46),COUNT(F47),COUNT(F48))=1,CHOOSE($D$4,F46,F47,F48),"N/D") -> 0.65 | G45: =IF(CHOOSE($D$4,COUNT(G46),COUNT(G47),COUNT(G48))=1,CHOOSE($D$4,G46,G47,G48),"N/D") -> 0.65 | H45: =IF(CHOOSE($D$4,COUNT(H46),COUNT(H47),COUNT(H48))=1,CHOOSE($D$4,H46,H47,H48),"N/D") -> 0.65 | I45: =IF(CHOOSE($D$4,COUNT(I46),COUNT(I47),COUNT(I48))=1,CHOOSE($D$4,I46,I47,I48),"N/D") -> 0.65 | J45: =IF(CHOOSE($D$4,COUNT(J46),COUNT(J47),COUNT(J48))=1,CHOOSE($D$4,J46,J47,J48),"N/D") -> 0.65 | K45: =IF(CHOOSE($D$4,COUNT(K46),COUNT(K47),COUNT(K48))=1,CHOOSE($D$4,K46,K47,K48),"N/D") -> 0.65 | L45: =IF(CHOOSE($D$4,COUNT(L46),COUNT(L47),COUNT(L48))=1,CHOOSE($D$4,L46,L47,L48),"N/D") -> 0.65 | M45: =IF(CHOOSE($D$4,COUNT(M46),COUNT(M47),COUNT(M48))=1,CHOOSE($D$4,M46,M47,M48),"N/D") -> 0.65 | ... Q45: =IF(CHOOSE($D$4,COUNT(Q46),COUNT(Q47),COUNT(Q48))=1,CHOOSE($D$4,Q46,Q47,Q48),"N/D") -> 0.65
C46: Conservador | F46: 0.5 | G46: 0.5 | H46: 0.5 | I46: 0.5 | J46: 0.5 | K46: 0.5 | L46: 0.5 | M46: 0.5 | N46: 0.5 | O46: 0.5 | P46: 0.5 | Q46: 0.5
C47: Base | F47: 0.65 | G47: 0.65 | H47: 0.65 | I47: 0.65 | J47: 0.65 | K47: 0.65 | L47: 0.65 | M47: 0.65 | N47: 0.65 | O47: 0.65 | P47: 0.65 | Q47: 0.65
...

Sheet Mensual
C2: Adquisición, fondeo y valor mensual
C4: Escenario seleccionado | D4: =Supuestos!D5 -> Base
C7: Indicador | D7: Unidad | F7: Mes 1 | G7: Mes 2 | H7: Mes 3 | I7: Mes 4 | J7: Mes 5 | K7: Mes 6 | L7: Mes 7 | M7: Mes 8 | N7: Mes 9 | O7: Mes 10 | P7: Mes 11 | Q7: Mes 12
F8: =Supuestos!F21 -> 46388 | G8: =Supuestos!G21 -> 46419 | H8: =Supuestos!H21 -> 46447 | I8: =Supuestos!I21 -> 46478 | J8: =Supuestos!J21 -> 46508 | K8: =Supuestos!K21 -> 46539 | L8: =Supuestos!L21 -> 46569 | M8: =Supuestos!M21 -> 46600 | ... Q8: =Supuestos!Q21 -> 46722
C9: Proxy mensual histórico trasladado | D9: búsquedas | F9: =Supuestos!F50 -> 3690 | G9: =Supuestos!G50 -> 3690 | H9: =Supuestos!H50 -> 3690 | I9: =Supuestos!I50 -> 3690 | J9: =Supuestos!J50 -> 3690 | K9: =Supuestos!K50 -> 3690 | L9: =Supuestos!L50 -> 3690 | M9: =Supuestos!M50 -> 3690 | ... Q9: =Supuestos!Q50 -> 3690
C10: Estacionalidad usada | D10: factor | F10: =Supuestos!F28 -> 1 | G10: =Supuestos!G28 -> 1 | H10: =Supuestos!H28 -> 1 | I10: =Supuestos!I28 -> 1 | J10: =Supuestos!J28 -> 1 | K10: =Supuestos!K28 -> 1 | L10: =Supuestos!L28 -> 1 | M10: =Supuestos!M28 -> 1 | ... Q10: =Supuestos!Q28 -> 1
C11: Crecimiento 2027 supuesto | D11: factor | F11: =IF(COUNT(Supuestos!$D$25)=1,Supuestos!$D$25,"N/D") -> 1 | G11: =IF(COUNT(Supuestos!$D$25)=1,Supuestos!$D$25,"N/D") -> 1 | H11: =IF(COUNT(Supuestos!$D$25)=1,Supuestos!$D$25,"N/D") -> 1 | I11: =IF(COUNT(Supuestos!$D$25)=1,Supuestos!$D$25,"N/D") -> 1 | J11: =IF(COUNT(Supuestos!$D$25)=1,Supuestos!$D$25,"N/D") -> 1 | K11: =IF(COUNT(Supuestos!$D$25)=1,Supuestos!$D$25,"N/D") -> 1 | L11: =IF(COUNT(Supuestos!$D$25)=1,Supuestos!$D$25,"N/D") -> 1 | M11: =IF(COUNT(Supuestos!$D$25)=1,Supuestos!$D$25,"N/D") -> 1 | ... Q11: =IF(COUNT(Supuestos!$D$25)=1,Supuestos!$D$25,"N/D") -> 1
C12: Demanda tras relevancia | D12: búsquedas | F12: =IF(COUNT(F9,F10,F11,Supuestos!$D$13)=4,F9*F10*F11*Supuestos!$D$13,"N/D") -> 2767.5 | G12: =IF(COUNT(G9,G10,G11,Supuestos!$D$13)=4,G9*G10*G11*Supuestos!$D$13,"N/D") -> 2767.5 | H12: =IF(COUNT(H9,H10,H11,Supuestos!$D$13)=4,H9*H10*H11*Supuestos!$D$13,"N/D") -> 2767.5 | I12: =IF(COUNT(I9,I10,I11,Supuestos!$D$13)=4,I9*I10*I11*Supuestos!$D$13,"N/D") -> 2767.5 | J12: =IF(COUNT(J9,J10,J11,Supuestos!$D$13)=4,J9*J10*J11*Supuestos!$D$13,"N/D") -> 2767.5 | K12: =IF(COUNT(K9,K10,K11,Supuestos!$D$13)=4,K9*K10*K11*Supuestos!$D$13,"N/D") -> 2767.5 | L12: =IF(COUNT(L9,L10,L11,Supuestos!$D$13)=4,L9*L10*L11*Supuestos!$D$13,"N/D") -> 2767.5 | M12: =IF(COUNT(M9,M10,M11,Supuestos!$D$13)=4,M9*M10*M11*Supuestos!$D$13,"N/D") -> 2767.5 | ... Q12: =IF(COUNT(Q9,Q10,Q11,Supuestos!$D$13)=4,Q9*Q10*Q11*Supuestos!$D$13,"N/D") -> 2767.5
C13: Captura referencia | D13: % | F13: =Supuestos!F35 -> 0.01 | G13: =Supuestos!G35 -> 0.01 | H13: =Supuestos!H35 -> 0.01 | I13: =Supuestos!I35 -> 0.01 | J13: =Supuestos!J35 -> 0.01 | K13: =Supuestos!K35 -> 0.01 | L13: =Supuestos!L35 -> 0.01 | M13: =Supuestos!M35 -> 0.01 | ... Q13: =Supuestos!Q35 -> 0.01
C14: Captura adicional programa | D14: % | F14: =Supuestos!F30 -> 0.005 | G14: =Supuestos!G30 -> 0.015 | H14: =Supuestos!H30 -> 0.03 | I14: =Supuestos!I30 -> 0.05 | J14: =Supuestos!J30 -> 0.075 | K14: =Supuestos!K30 -> 0.1 | L14: =Supuestos!L30 -> 0.125 | M14: =Supuestos!M30 -> 0.15 | ... Q14: =Supuestos!Q30 -> 0.25
C15: Visitas referencia | D15: visitas | F15: =IF(COUNT(F12,F13)=2,F12*F13,"N/D") -> 27.675 | G15: =IF(COUNT(G12,G13)=2,G12*G13,"N/D") -> 27.675 | H15: =IF(COUNT(H12,H13)=2,H12*H13,"N/D") -> 27.675 | I15: =IF(COUNT(I12,I13)=2,I12*I13,"N/D") -> 27.675 | J15: =IF(COUNT(J12,J13)=2,J12*J13,"N/D") -> 27.675 | K15: =IF(COUNT(K12,K13)=2,K12*K13,"N/D") -> 27.675 | L15: =IF(COUNT(L12,L13)=2,L12*L13,"N/D") -> 27.675 | M15: =IF(COUNT(M12,M13)=2,M12*M13,"N/D") -> 27.675 | ... Q15: =IF(COUNT(Q12,Q13)=2,Q12*Q13,"N/D") -> 27.675
C16: Visitas incrementales | D16: visitas | F16: =IF(COUNT(F12,F14)=2,F12*F14,"N/D") -> 13.8375 | G16: =IF(COUNT(G12,G14)=2,G12*G14,"N/D") -> 41.5125 | H16: =IF(COUNT(H12,H14)=2,H12*H14,"N/D") -> 83.025 | I16: =IF(COUNT(I12,I14)=2,I12*I14,"N/D") -> 138.375 | J16: =IF(COUNT(J12,J14)=2,J12*J14,"N/D") -> 207.5625 | K16: =IF(COUNT(K12,K14)=2,K12*K14,"N/D") -> 276.75 | L16: =IF(COUNT(L12,L14)=2,L12*L14,"N/D") -> 345.9375 | M16: =IF(COUNT(M12,M14)=2,M12*M14,"N/D") -> 415.125 | ... Q16: =IF(COUNT(Q12,Q14)=2,Q12*Q14,"N/D") -> 691.875
C17: Visitas programa | D17: visitas | F17: =IF(COUNT(F15:F16)=2,SUM(F15:F16),"N/D") -> 41.5125 | G17: =IF(COUNT(G15:G16)=2,SUM(G15:G16),"N/D") -> 69.1875 | H17: =IF(COUNT(H15:H16)=2,SUM(H15:H16),"N/D") -> 110.7 | I17: =IF(COUNT(I15:I16)=2,SUM(I15:I16),"N/D") -> 166.05 | J17: =IF(COUNT(J15:J16)=2,SUM(J15:J16),"N/D") -> 235.2375 | K17: =IF(COUNT(K15:K16)=2,SUM(K15:K16),"N/D") -> 304.425 | L17: =IF(COUNT(L15:L16)=2,SUM(L15:L16),"N/D") -> 373.6125 | M17: =IF(COUNT(M15:M16)=2,SUM(M15:M16),"N/D") -> 442.8 | ... Q17: =IF(COUNT(Q15:Q16)=2,SUM(Q15:Q16),"N/D") -> 719.55
C18: Visita a apertura | D18: % | F18: =Supuestos!F40 -> 0.02 | G18: =Supuestos!G40 -> 0.02 | H18: =Supuestos!H40 -> 0.02 | I18: =Supuestos!I40 -> 0.02 | J18: =Supuestos!J40 -> 0.02 | K18: =Supuestos!K40 -> 0.02 | L18: =Supuestos!L40 -> 0.02 | M18: =Supuestos!M40 -> 0.02 | ... Q18: =Supuestos!Q40 -> 0.02
C19: Aperturas referencia | D19: cuentas | F19: =IF(COUNT(F15,F18)=2,F15*F18,"N/D") -> 0.5535 | G19: =IF(COUNT(G15,G18)=2,G15*G18,"N/D") -> 0.5535 | H19: =IF(COUNT(H15,H18)=2,H15*H18,"N/D") -> 0.5535 | I19: =IF(COUNT(I15,I18)=2,I15*I18,"N/D") -> 0.5535 | J19: =IF(COUNT(J15,J18)=2,J15*J18,"N/D") -> 0.5535 | K19: =IF(COUNT(K15,K18)=2,K15*K18,"N/D") -> 0.5535 | L19: =IF(COUNT(L15,L18)=2,L15*L18,"N/D") -> 0.5535 | M19: =IF(COUNT(M15,M18)=2,M15*M18,"N/D") -> 0.5535 | ... Q19: =IF(COUNT(Q15,Q18)=2,Q15*Q18,"N/D") -> 0.5535
C20: Aperturas programa | D20: cuentas | F20: =IF(COUNT(F17,F18)=2,F17*F18,"N/D") -> 0.83025 | G20: =IF(COUNT(G17,G18)=2,G17*G18,"N/D") -> 1.38375 | H20: =IF(COUNT(H17,H18)=2,H17*H18,"N/D") -> 2.214 | I20: =IF(COUNT(I17,I18)=2,I17*I18,"N/D") -> 3.321 | J20: =IF(COUNT(J17,J18)=2,J17*J18,"N/D") -> 4.70475 | K20: =IF(COUNT(K17,K18)=2,K17*K18,"N/D") -> 6.0885 | L20: =IF(COUNT(L17,L18)=2,L17*L18,"N/D") -> 7.47225 | M20: =IF(COUNT(M17,M18)=2,M17*M18,"N/D") -> 8.856 | ... Q20: =IF(COUNT(Q17,Q18)=2,Q17*Q18,"N/D") -> 14.391
C21: Aperturas incrementales | D21: cuentas | F21: =IF(COUNT(F19:F20)=2,F20-F19,"N/D") -> 0.27675 | G21: =IF(COUNT(G19:G20)=2,G20-G19,"N/D") -> 0.83025 | H21: =IF(COUNT(H19:H20)=2,H20-H19,"N/D") -> 1.6605 | I21: =IF(COUNT(I19:I20)=2,I20-I19,"N/D") -> 2.7675 | J21: =IF(COUNT(J19:J20)=2,J20-J19,"N/D") -> 4.15125 | K21: =IF(COUNT(K19:K20)=2,K20-K19,"N/D") -> 5.535 | L21: =IF(COUNT(L19:L20)=2,L20-L19,"N/D") -> 6.91875 | M21: =IF(COUNT(M19:M20)=2,M20-M19,"N/D") -> 8.3025 | ... Q21: =IF(COUNT(Q19:Q20)=2,Q20-Q19,"N/D") -> 13.8375
C22: Apertura a fondeo | D22: % | F22: =Supuestos!F45 -> 0.65 | G22: =Supuestos!G45 -> 0.65 | H22: =Supuestos!H45 -> 0.65 | I22: =Supuestos!I45 -> 0.65 | J22: =Supuestos!J45 -> 0.65 | K22: =Supuestos!K45 -> 0.65 | L22: =Supuestos!L45 -> 0.65 | M22: =Supuestos!M45 -> 0.65 | ... Q22: =Supuestos!Q45 -> 0.65
C23: Fondeo potencial referencia | D23: cuentas | F23: =IF(COUNT(F19,F22)=2,F19*F22,"N/D") -> 0.359775 | G23: =IF(COUNT(G19,G22)=2,G19*G22,"N/D") -> 0.359775 | H23: =IF(COUNT(H19,H22)=2,H19*H22,"N/D") -> 0.359775 | I23: =IF(COUNT(I19,I22)=2,I19*I22,"N/D") -> 0.359775 | J23: =IF(COUNT(J19,J22)=2,J19*J22,"N/D") -> 0.359775 | K23: =IF(COUNT(K19,K22)=2,K19*K22,"N/D") -> 0.359775 | L23: =IF(COUNT(L19,L22)=2,L19*L22,"N/D") -> 0.359775 | M23: =IF(COUNT(M19,M22)=2,M19*M22,"N/D") -> 0.359775 | ... Q23: =IF(COUNT(Q19,Q22)=2,Q19*Q22,"N/D") -> 0.359775
C24: Fondeo potencial programa | D24: cuentas | F24: =IF(COUNT(F20,F22)=2,F20*F22,"N/D") -> 0.5396625 | G24: =IF(COUNT(G20,G22)=2,G20*G22,"N/D") -> 0.8994375 | H24: =IF(COUNT(H20,H22)=2,H20*H22,"N/D") -> 1.4391 | I24: =IF(COUNT(I20,I22)=2,I20*I22,"N/D") -> 2.15865 | J24: =IF(COUNT(J20,J22)=2,J20*J22,"N/D") -> 3.0580875 | K24: =IF(COUNT(K20,K22)=2,K20*K22,"N/D") -> 3.957525 | L24: =IF(COUNT(L20,L22)=2,L20*L22,"N/D") -> 4.8569625 | M24: =IF(COUNT(M20,M22)=2,M20*M22,"N/D") -> 5.7564 | ... Q24: =IF(COUNT(Q20,Q22)=2,Q20*Q22,"N/D") -> 9.35415
C25: Fondeo potencial incremental | D25: cuentas | F25: =IF(COUNT(F23:F24)=2,F24-F23,"N/D") -> 0.1798875 | G25: =IF(COUNT(G23:G24)=2,G24-G23,"N/D") -> 0.5396625 | H25: =IF(COUNT(H23:H24)=2,H24-H23,"N/D") -> 1.079325 | I25: =IF(COUNT(I23:I24)=2,I24-I23,"N/D") -> 1.798875 | J25: =IF(COUNT(J23:J24)=2,J24-J23,"N/D") -> 2.6983125 | K25: =IF(COUNT(K23:K24)=2,K24-K23,"N/D") -> 3.59775 | L25: =IF(COUNT(L23:L24)=2,L24-L23,"N/D") -> 4.4971875 | M25: =IF(COUNT(M23:M24)=2,M24-M23,"N/D") -> 5.396625 | ... Q25: =IF(COUNT(Q23:Q24)=2,Q24-Q23,"N/D") -> 8.994375
C26: Primer fondeo referencia dentro año | D26: cuentas | F26: =IF(COUNT(Supuestos!$D$18)=1,IF(Supuestos!$D$18<=0,INDEX($F$23:$Q$23,1,1-Supuestos!$D$18),0),"N/D") -> 0.359775 | G26: =IF(COUNT(Supuestos!$D$18)=1,IF(Supuestos!$D$18<=1,INDEX($F$23:$Q$23,1,2-Supuestos!$D$18),0),"N/D") -> 0.359775 | H26: =IF(COUNT(Supuestos!$D$18)=1,IF(Supuestos!$D$18<=2,INDEX($F$23:$Q$23,1,3-Supuestos!$D$18),0),"N/D") -> 0.359775 | I26: =IF(COUNT(Supuestos!$D$18)=1,IF(Supuestos!$D$18<=3,INDEX($F$23:$Q$23,1,4-Supuestos!$D$18),0),"N/D") -> 0.359775 | J26: =IF(COUNT(Supuestos!$D$18)=1,IF(Supuestos!$D$18<=4,INDEX($F$23:$Q$23,1,5-Supuestos!$D$18),0),"N/D") -> 0.359775 | K26: =IF(COUNT(Supuestos!$D$18)=1,IF(Supuestos!$D$18<=5,INDEX($F$23:$Q$23,1,6-Supuestos!$D$18),0),"N/D") -> 0.359775 | L26: =IF(COUNT(Supuestos!$D$18)=1,IF(Supuestos!$D$18<=6,INDEX($F$23:$Q$23,1,7-Supuestos!$D$18),0),"N/D") -> 0.359775 | M26: =IF(COUNT(Supuestos!$D$18)=1,IF(Supuestos!$D$18<=7,INDEX($F$23:$Q$23,1,8-Supuestos!$D$18),0),"N/D") -> 0.359775 | N26: =IF(COUNT(Supuestos!$D$18)=1,IF(Supuestos!$D$18<=8,INDEX($F$23:$Q$23,1,9-Supuestos!$D$18),0),"N/D") -> 0.359775 | O26: =IF(COUNT(Supuestos!$D$18)=1,IF(Supuestos!$D$18<=9,INDEX($F$23:$Q$23,1,10-Supuestos!$D$18),0),"N/D") -> 0.359775 | P26: =IF(COUNT(Supuestos!$D$18)=1,IF(Supuestos!$D$18<=10,INDEX($F$23:$Q$23,1,11-Supuestos!$D$18),0),"N/D") -> 0.359775 | Q26: =IF(COUNT(Supuestos!$D$18)=1,IF(Supuestos!$D$18<=11,INDEX($F$23:$Q$23,1,12-Supuestos!$D$18),0),"N/D") -> 0.359775
C27: Primer fondeo programa dentro año | D27: cuentas | F27: =IF(COUNT(Supuestos!$D$18)=1,IF(Supuestos!$D$18<=0,INDEX($F$24:$Q$24,1,1-Supuestos!$D$18),0),"N/D") -> 0.5396625 | G27: =IF(COUNT(Supuestos!$D$18)=1,IF(Supuestos!$D$18<=1,INDEX($F$24:$Q$24,1,2-Supuestos!$D$18),0),"N/D") -> 0.8994375 | H27: =IF(COUNT(Supuestos!$D$18)=1,IF(Supuestos!$D$18<=2,INDEX($F$24:$Q$24,1,3-Supuestos!$D$18),0),"N/D") -> 1.4391 | I27: =IF(COUNT(Supuestos!$D$18)=1,IF(Supuestos!$D$18<=3,INDEX($F$24:$Q$24,1,4-Supuestos!$D$18),0),"N/D") -> 2.15865 | J27: =IF(COUNT(Supuestos!$D$18)=1,IF(Supuestos!$D$18<=4,INDEX($F$24:$Q$24,1,5-Supuestos!$D$18),0),"N/D") -> 3.0580875 | K27: =IF(COUNT(Supuestos!$D$18)=1,IF(Supuestos!$D$18<=5,INDEX($F$24:$Q$24,1,6-Supuestos!$D$18),0),"N/D") -> 3.957525 | L27: =IF(COUNT(Supuestos!$D$18)=1,IF(Supuestos!$D$18<=6,INDEX($F$24:$Q$24,1,7-Supuestos!$D$18),0),"N/D") -> 4.8569625 | M27: =IF(COUNT(Supuestos!$D$18)=1,IF(Supuestos!$D$18<=7,INDEX($F$24:$Q$24,1,8-Supuestos!$D$18),0),"N/D") -> 5.7564 | N27: =IF(COUNT(Supuestos!$D$18)=1,IF(Supuestos!$D$18<=8,INDEX($F$24:$Q$24,1,9-Supuestos!$D$18),0),"N/D") -> 6.6558375 | O27: =IF(COUNT(Supuestos!$D$18)=1,IF(Supuestos!$D$18<=9,INDEX($F$24:$Q$24,1,10-Supuestos!$D$18),0),"N/D") -> 7.555275 | P27: =IF(COUNT(Supuestos!$D$18)=1,IF(Supuestos!$D$18<=10,INDEX($F$24:$Q$24,1,11-Supuestos!$D$18),0),"N/D") -> 8.4547125 | Q27: =IF(COUNT(Supuestos!$D$18)=1,IF(Supuestos!$D$18<=11,INDEX($F$24:$Q$24,1,12-Supuestos!$D$18),0),"N/D") -> 9.35415
C28: Primer fondeo incremental dentro año | D28: cuentas | F28: =IF(COUNT(F26:F27)=2,F27-F26,"N/D") -> 0.1798875 | G28: =IF(COUNT(G26:G27)=2,G27-G26,"N/D") -> 0.5396625 | H28: =IF(COUNT(H26:H27)=2,H27-H26,"N/D") -> 1.079325 | I28: =IF(COUNT(I26:I27)=2,I27-I26,"N/D") -> 1.798875 | J28: =IF(COUNT(J26:J27)=2,J27-J26,"N/D") -> 2.6983125 | K28: =IF(COUNT(K26:K27)=2,K27-K26,"N/D") -> 3.59775 | L28: =IF(COUNT(L26:L27)=2,L27-L26,"N/D") -> 4.4971875 | M28: =IF(COUNT(M26:M27)=2,M27-M26,"N/D") -> 5.396625 | ... Q28: =IF(COUNT(Q26:Q27)=2,Q27-Q26,"N/D") -> 8.994375
C30: Lag retrasa el primer fondeo. Fondeos programados después de diciembre no cuentan para outcome ni saldo/valor 2027.
C31: Referencia y captura son hipótesis, no baseline post-lanzamiento. La demanda de mercado tampoco equivale a personas.
C35: Saldo incremental al cierre | D35: USD eq. | F35: =Cohortes!L22 -> 437.72625 | G35: =Cohortes!M22 -> 1736.6639 | H35: =Cohortes!N22 -> 4270.0795 | I35: =Cohortes!O22 -> 8437.4733 | J35: =Cohortes!P22 -> 14576.634 | K35: =Cohortes!Q22 -> 22670.072 | L35: =Cohortes!R22 -> 32577.309 | M35: =Cohortes!S22 -> 44305.501 | ... Q35: =Cohortes!W22 -> 109054.68
C36: Saldo externo al cierre | D36: USD eq. | F36: =Cohortes!L43 -> 306.40837 | G36: =Cohortes!M43 -> 1215.6647 | H36: =Cohortes!N43 -> 2989.0557 | I36: =Cohortes!O43 -> 5906.2313 | J36: =Cohortes!P43 -> 10203.644 | K36: =Cohortes!Q43 -> 15869.051 | L36: =Cohortes!R43 -> 22804.116 | M36: =Cohortes!S43 -> 31013.851 | ... Q36: =Cohortes!W43 -> 76338.274
C37: Saldo medio mensual incremental | D37: USD eq. | F37: =Cohortes!L63 -> 243.33169 | G37: =Cohortes!M63 -> 1094.503 | H37: =Cohortes!N63 -> 3150.1831 | I37: =Cohortes!O63 -> 6529.9163 | J37: =Cohortes!P63 -> 11874.082 | K37: =Cohortes!Q63 -> 18975.633 | L37: =Cohortes!R63 -> 28235.405 | M37: =Cohortes!S63 -> 39175.462 | ... Q37: =Cohortes!W63 -> 100912.43
C38: Saldo medio mensual externo | D38: USD eq. | F38: =Cohortes!L83 -> 170.33219 | G38: =Cohortes!M83 -> 766.15211 | H38: =Cohortes!N83 -> 2205.1282 | I38: =Cohortes!O83 -> 4570.9414 | J38: =Cohortes!P83 -> 8311.8575 | K38: =Cohortes!Q83 -> 13282.943 | L38: =Cohortes!R83 -> 19764.783 | M38: =Cohortes!S83 -> 27422.823 | ... Q38: =Cohortes!W83 -> 70638.698
C40: Inversión cliente pendiente | D40: USD | F40: =IF(COUNT(Supuestos!F22)=1,IF(Supuestos!F22>=0,Supuestos!F22,"N/D"),"N/D") -> N/D | G40: =IF(COUNT(Supuestos!G22)=1,IF(Supuestos!G22>=0,Supuestos!G22,"N/D"),"N/D") -> N/D | H40: =IF(COUNT(Supuestos!H22)=1,IF(Supuestos!H22>=0,Supuestos!H22,"N/D"),"N/D") -> N/D | I40: =IF(COUNT(Supuestos!I22)=1,IF(Supuestos!I22>=0,Supuestos!I22,"N/D"),"N/D") -> N/D | J40: =IF(COUNT(Supuestos!J22)=1,IF(Supuestos!J22>=0,Supuestos!J22,"N/D"),"N/D") -> N/D | K40: =IF(COUNT(Supuestos!K22)=1,IF(Supuestos!K22>=0,Supuestos!K22,"N/D"),"N/D") -> N/D | L40: =IF(COUNT(Supuestos!L22)=1,IF(Supuestos!L22>=0,Supuestos!L22,"N/D"),"N/D") -> N/D | M40: =IF(COUNT(Supuestos!M22)=1,IF(Supuestos!M22>=0,Supuestos!M22,"N/D"),"N/D") -> N/D | ... Q40: =IF(COUNT(Supuestos!Q22)=1,IF(Supuestos!Q22>=0,Supuestos!Q22,"N/D"),"N/D") -> N/D
C41: Inversión acumulada | D41: USD | F41: =IF(COUNT($F40:F40)=1,SUM($F40:F40),"N/D") -> N/D | G41: =IF(COUNT($F40:G40)=2,SUM($F40:G40),"N/D") -> N/D | H41: =IF(COUNT($F40:H40)=3,SUM($F40:H40),"N/D") -> N/D | I41: =IF(COUNT($F40:I40)=4,SUM($F40:I40),"N/D") -> N/D | J41: =IF(COUNT($F40:J40)=5,SUM($F40:J40),"N/D") -> N/D | K41: =IF(COUNT($F40:K40)=6,SUM($F40:K40),"N/D") -> N/D | L41: =IF(COUNT($F40:L40)=7,SUM($F40:L40),"N/D") -> N/D | M41: =IF(COUNT($F40:M40)=8,SUM($F40:M40),"N/D") -> N/D | N41: =IF(COUNT($F40:N40)=9,SUM($F40:N40),"N/D") -> N/D | O41: =IF(COUNT($F40:O40)=10,SUM($F40:O40),"N/D") -> N/D | P41: =IF(COUNT($F40:P40)=11,SUM($F40:P40),"N/D") -> N/D | Q41: =IF(COUNT($F40:Q40)=12,SUM($F40:Q40),"N/D") -> N/D
C42: Valor neto mensual Finance | D42: USD | F42: =IF(AND(Supuestos!$D$14="Sí",COUNT(Supuestos!$D$15,F38)=2),F38*Supuestos!$D$15/12,"N/D") -> N/D | G42: =IF(AND(Supuestos!$D$14="Sí",COUNT(Supuestos!$D$15,G38)=2),G38*Supuestos!$D$15/12,"N/D") -> N/D | H42: =IF(AND(Supuestos!$D$14="Sí",COUNT(Supuestos!$D$15,H38)=2),H38*Supuestos!$D$15/12,"N/D") -> N/D | I42: =IF(AND(Supuestos!$D$14="Sí",COUNT(Supuestos!$D$15,I38)=2),I38*Supuestos!$D$15/12,"N/D") -> N/D | J42: =IF(AND(Supuestos!$D$14="Sí",COUNT(Supuestos!$D$15,J38)=2),J38*Supuestos!$D$15/12,"N/D") -> N/D | K42: =IF(AND(Supuestos!$D$14="Sí",COUNT(Supuestos!$D$15,K38)=2),K38*Supuestos!$D$15/12,"N/D") -> N/D | L42: =IF(AND(Supuestos!$D$14="Sí",COUNT(Supuestos!$D$15,L38)=2),L38*Supuestos!$D$15/12,"N/D") -> N/D | M42: =IF(AND(Supuestos!$D$14="Sí",COUNT(Supuestos!$D$15,M38)=2),M38*Supuestos!$D$15/12,"N/D") -> N/D | ... Q42: =IF(AND(Supuestos!$D$14="Sí",COUNT(Supuestos!$D$15,Q38)=2),Q38*Supuestos!$D$15/12,"N/D") -> N/D
C43: Valor acumulado Finance | D43: USD | F43: =IF(COUNT($F42:F42)=1,SUM($F42:F42),"N/D") -> N/D | G43: =IF(COUNT($F42:G42)=2,SUM($F42:G42),"N/D") -> N/D | H43: =IF(COUNT($F42:H42)=3,SUM($F42:H42),"N/D") -> N/D | I43: =IF(COUNT($F42:I42)=4,SUM($F42:I42),"N/D") -> N/D | J43: =IF(COUNT($F42:J42)=5,SUM($F42:J42),"N/D") -> N/D | K43: =IF(COUNT($F42:K42)=6,SUM($F42:K42),"N/D") -> N/D | L43: =IF(COUNT($F42:L42)=7,SUM($F42:L42),"N/D") -> N/D | M43: =IF(COUNT($F42:M42)=8,SUM($F42:M42),"N/D") -> N/D | N43: =IF(COUNT($F42:N42)=9,SUM($F42:N42),"N/D") -> N/D | O43: =IF(COUNT($F42:O42)=10,SUM($F42:O42),"N/D") -> N/D | P43: =IF(COUNT($F42:P42)=11,SUM($F42:P42),"N/D") -> N/D | Q43: =IF(COUNT($F42:Q42)=12,SUM($F42:Q42),"N/D") -> N/D
C44: ROI acumulado con gates Finance | D44: % | F44: =IF(AND(Supuestos!$D$14="Sí",Supuestos!$D$16="Sí",COUNT(F41,F43)=2,F41>0),(F43-F41)/F41,"N/D") -> N/D | G44: =IF(AND(Supuestos!$D$14="Sí",Supuestos!$D$16="Sí",COUNT(G41,G43)=2,G41>0),(G43-G41)/G41,"N/D") -> N/D | H44: =IF(AND(Supuestos!$D$14="Sí",Supuestos!$D$16="Sí",COUNT(H41,H43)=2,H41>0),(H43-H41)/H41,"N/D") -> N/D | I44: =IF(AND(Supuestos!$D$14="Sí",Supuestos!$D$16="Sí",COUNT(I41,I43)=2,I41>0),(I43-I41)/I41,"N/D") -> N/D | J44: =IF(AND(Supuestos!$D$14="Sí",Supuestos!$D$16="Sí",COUNT(J41,J43)=2,J41>0),(J43-J41)/J41,"N/D") -> N/D | K44: =IF(AND(Supuestos!$D$14="Sí",Supuestos!$D$16="Sí",COUNT(K41,K43)=2,K41>0),(K43-K41)/K41,"N/D") -> N/D | L44: =IF(AND(Supuestos!$D$14="Sí",Supuestos!$D$16="Sí",COUNT(L41,L43)=2,L41>0),(L43-L41)/L41,"N/D") -> N/D | M44: =IF(AND(Supuestos!$D$14="Sí",Supuestos!$D$16="Sí",COUNT(M41,M43)=2,M41>0),(M43-M41)/M41,"N/D") -> N/D | ... Q44: =IF(AND(Supuestos!$D$14="Sí",Supuestos!$D$16="Sí",COUNT(Q41,Q43)=2,Q41>0),(Q43-Q41)/Q41,"N/D") -> N/D
C45: Valor menos inversión acumulada | D45: USD | F45: =IF(AND(Supuestos!$D$14="Sí",Supuestos!$D$16="Sí",COUNT(F41,F43)=2,F41>0),F43-F41,"N/D") -> N/D | G45: =IF(AND(Supuestos!$D$14="Sí",Supuestos!$D$16="Sí",COUNT(G41,G43)=2,G41>0),G43-G41,"N/D") -> N/D | H45: =IF(AND(Supuestos!$D$14="Sí",Supuestos!$D$16="Sí",COUNT(H41,H43)=2,H41>0),H43-H41,"N/D") -> N/D | I45: =IF(AND(Supuestos!$D$14="Sí",Supuestos!$D$16="Sí",COUNT(I41,I43)=2,I41>0),I43-I41,"N/D") -> N/D | J45: =IF(AND(Supuestos!$D$14="Sí",Supuestos!$D$16="Sí",COUNT(J41,J43)=2,J41>0),J43-J41,"N/D") -> N/D | K45: =IF(AND(Supuestos!$D$14="Sí",Supuestos!$D$16="Sí",COUNT(K41,K43)=2,K41>0),K43-K41,"N/D") -> N/D | L45: =IF(AND(Supuestos!$D$14="Sí",Supuestos!$D$16="Sí",COUNT(L41,L43)=2,L41>0),L43-L41,"N/D") -> N/D | M45: =IF(AND(Supuestos!$D$14="Sí",Supuestos!$D$16="Sí",COUNT(M41,M43)=2,M41>0),M43-M41,"N/D") -> N/D | ... Q45: =IF(AND(Supuestos!$D$14="Sí",Supuestos!$D$16="Sí",COUNT(Q41,Q43)=2,Q41>0),Q43-Q41,"N/D") -> N/D
C46: Recuperación alcanzada | D46: 0/1 | F46: =IF(COUNT(F45)=1,IF(F45>=0,1,0),"N/D") -> N/D | G46: =IF(COUNT(G45)=1,IF(G45>=0,1,0),"N/D") -> N/D | H46: =IF(COUNT(H45)=1,IF(H45>=0,1,0),"N/D") -> N/D | I46: =IF(COUNT(I45)=1,IF(I45>=0,1,0),"N/D") -> N/D | J46: =IF(COUNT(J45)=1,IF(J45>=0,1,0),"N/D") -> N/D | K46: =IF(COUNT(K45)=1,IF(K45>=0,1,0),"N/D") -> N/D | L46: =IF(COUNT(L45)=1,IF(L45>=0,1,0),"N/D") -> N/D | M46: =IF(COUNT(M45)=1,IF(M45>=0,1,0),"N/D") -> N/D | ... Q46: =IF(COUNT(Q45)=1,IF(Q45>=0,1,0),"N/D") -> N/D
C48: Finance aplica tasa neta anual /12 al saldo medio mensual externo. Nueva cohorte se pondera por días activa dentro del mes.
C49: La cuenta creada en diciembre no aporta doce meses de valor. Valor 2028 no se contabiliza automáticamente.
C50: Revisiones trimestrales optimizan el programa anual; la ejecución y los accesos se comprueban desdeM 1.

Sheet Cohortes
C2: Cohortes: saldo, origen externo y maduración
C4: Escenario | D4: =Supuestos!D5 -> Base
C7: Primer fondeo | D7: Cuentas potenciales | E7: Ticket USD eq. | F7: Origen externo | G7: Ret 30 d | H7: Ret 60 d | I7: Ret 90 d | J7: Ret 180 d | K7: Ret 365 d | L7: M 1 | M7: M 2 | N7: M 3 | O7: M 4 | P7: M 5 | Q7: M 6 | R7: M 7 | S7: M 8 | T7: M 9 | U7: M 10 | V7: M 11 | W7: M 12
L8: =Supuestos!F21 -> 46388 | M8: =Supuestos!G21 -> 46419 | N8: =Supuestos!H21 -> 46447 | O8: =Supuestos!I21 -> 46478 | P8: =Supuestos!J21 -> 46508 | Q8: =Supuestos!K21 -> 46539 | R8: =Supuestos!L21 -> 46569 | S8: =Supuestos!M21 -> 46600 | ... W8: =Supuestos!Q21 -> 46722
C9: =IF(COUNT(Supuestos!$D$18,Supuestos!$D$19)=2,DATE(YEAR(EDATE(Supuestos!F21,Supuestos!$D$18)),MONTH(EDATE(Supuestos!F21,Supuestos!$D$18)),Supuestos!$D$19),"N/D") -> 46402 | D9: =Mensual!F25 -> 0.1798875 | E9: =IF(COUNT(Supuestos!$D$10)=1,Supuestos!$D$10,"N/D") -> 2500 | F9: =Supuestos!F80 -> 0.7 | G9: =Supuestos!F55 -> 0.95 | H9: =Supuestos!F60 -> 0.9 | I9: =Supuestos!F65 -> 0.85 | J9: =Supuestos!F70 -> 0.8 | K9: =Supuestos!F75 -> 0.75 | L9: =IF(COUNT($D9,$E9,L129)=3,$D9*$E9*L129,"N/D") -> 437.72625 | M9: =IF(COUNT($D9,$E9,M129)=3,$D9*$E9*M129,"N/D") -> 416.73937 | N9: =IF(COUNT($D9,$E9,N129)=3,$D9*$E9*N129,"N/D") -> 393.50391 | O9: =IF(COUNT($D9,$E9,O129)=3,$D9*$E9*O129,"N/D") -> 378.51328 | P9: =IF(COUNT($D9,$E9,P129)=3,$D9*$E9*P129,"N/D") -> 370.76812 | Q9: =IF(COUNT($D9,$E9,Q129)=3,$D9*$E9*Q129,"N/D") -> 363.27281 | R9: =IF(COUNT($D9,$E9,R129)=3,$D9*$E9*R129,"N/D") -> 357.70872 | S9: =IF(COUNT($D9,$E9,S129)=3,$D9*$E9*S129,"N/D") -> 353.94081 | ... W9: =IF(COUNT($D9,$E9,W129)=3,$D9*$E9*W129,"N/D") -> 339.11225
C10: =IF(COUNT(Supuestos!$D$18,Supuestos!$D$19)=2,DATE(YEAR(EDATE(Supuestos!G21,Supuestos!$D$18)),MONTH(EDATE(Supuestos!G21,Supuestos!$D$18)),Supuestos!$D$19),"N/D") -> 46433 | D10: =Mensual!G25 -> 0.5396625 | E10: =IF(COUNT(Supuestos!$D$10)=1,Supuestos!$D$10,"N/D") -> 2500 | F10: =Supuestos!G80 -> 0.7 | G10: =Supuestos!G55 -> 0.95 | H10: =Supuestos!G60 -> 0.9 | I10: =Supuestos!G65 -> 0.85 | J10: =Supuestos!G70 -> 0.8 | K10: =Supuestos!G75 -> 0.75 | L10: =IF(COUNT($D10,$E10,L130)=3,$D10*$E10*L130,"N/D") -> 0 | M10: =IF(COUNT($D10,$E10,M130)=3,$D10*$E10*M130,"N/D") -> 1319.9245 | N10: =IF(COUNT($D10,$E10,N130)=3,$D10*$E10*N130,"N/D") -> 1250.2181 | O10: =IF(COUNT($D10,$E10,O130)=3,$D10*$E10*O130,"N/D") -> 1182.7603 | P10: =IF(COUNT($D10,$E10,P130)=3,$D10*$E10*P130,"N/D") -> 1135.5398 | Q10: =IF(COUNT($D10,$E10,Q130)=3,$D10*$E10*Q130,"N/D") -> 1113.0539 | R10: =IF(COUNT($D10,$E10,R130)=3,$D10*$E10*R130,"N/D") -> 1089.8184 | S10: =IF(COUNT($D10,$E10,S130)=3,$D10*$E10*S130,"N/D") -> 1073.1262 | ... W10: =IF(COUNT($D10,$E10,W130)=3,$D10*$E10*W130,"N/D") -> 1028.6405
C11: =IF(COUNT(Supuestos!$D$18,Supuestos!$D$19)=2,DATE(YEAR(EDATE(Supuestos!H21,Supuestos!$D$18)),MONTH(EDATE(Supuestos!H21,Supuestos!$D$18)),Supuestos!$D$19),"N/D") -> 46461 | D11: =Mensual!H25 -> 1.079325 | E11: =IF(COUNT(Supuestos!$D$10)=1,Supuestos!$D$10,"N/D") -> 2500 | F11: =Supuestos!H80 -> 0.7 | G11: =Supuestos!H55 -> 0.95 | H11: =Supuestos!H60 -> 0.9 | I11: =Supuestos!H65 -> 0.85 | J11: =Supuestos!H70 -> 0.8 | K11: =Supuestos!H75 -> 0.75 | L11: =IF(COUNT($D11,$E11,L131)=3,$D11*$E11*L131,"N/D") -> 0 | M11: =IF(COUNT($D11,$E11,M131)=3,$D11*$E11*M131,"N/D") -> 0 | N11: =IF(COUNT($D11,$E11,N131)=3,$D11*$E11*N131,"N/D") -> 2626.3575 | O11: =IF(COUNT($D11,$E11,O131)=3,$D11*$E11*O131,"N/D") -> 2491.4419 | P11: =IF(COUNT($D11,$E11,P131)=3,$D11*$E11*P131,"N/D") -> 2352.0291 | Q11: =IF(COUNT($D11,$E11,Q131)=3,$D11*$E11*Q131,"N/D") -> 2268.0816 | R11: =IF(COUNT($D11,$E11,R131)=3,$D11*$E11*R131,"N/D") -> 2221.6106 | S11: =IF(COUNT($D11,$E11,S131)=3,$D11*$E11*S131,"N/D") -> 2175.1397 | ... W11: =IF(COUNT($D11,$E11,W131)=3,$D11*$E11*W131,"N/D") -> 2077.7006
C12: =IF(COUNT(Supuestos!$D$18,Supuestos!$D$19)=2,DATE(YEAR(EDATE(Supuestos!I21,Supuestos!$D$18)),MONTH(EDATE(Supuestos!I21,Supuestos!$D$18)),Supuestos!$D$19),"N/D") -> 46492 | D12: =Mensual!I25 -> 1.798875 | E12: =IF(COUNT(Supuestos!$D$10)=1,Supuestos!$D$10,"N/D") -> 2500 | F12: =Supuestos!I80 -> 0.7 | G12: =Supuestos!I55 -> 0.95 | H12: =Supuestos!I60 -> 0.9 | I12: =Supuestos!I65 -> 0.85 | J12: =Supuestos!I70 -> 0.8 | K12: =Supuestos!I75 -> 0.75 | L12: =IF(COUNT($D12,$E12,L132)=3,$D12*$E12*L132,"N/D") -> 0 | M12: =IF(COUNT($D12,$E12,M132)=3,$D12*$E12*M132,"N/D") -> 0 | N12: =IF(COUNT($D12,$E12,N132)=3,$D12*$E12*N132,"N/D") -> 0 | O12: =IF(COUNT($D12,$E12,O132)=3,$D12*$E12*O132,"N/D") -> 4384.7578 | P12: =IF(COUNT($D12,$E12,P132)=3,$D12*$E12*P132,"N/D") -> 4152.4031 | Q12: =IF(COUNT($D12,$E12,Q132)=3,$D12*$E12*Q132,"N/D") -> 3927.5437 | R12: =IF(COUNT($D12,$E12,R132)=3,$D12*$E12*R132,"N/D") -> 3780.1359 | S12: =IF(COUNT($D12,$E12,S132)=3,$D12*$E12*S132,"N/D") -> 3702.6844 | ... W12: =IF(COUNT($D12,$E12,W132)=3,$D12*$E12*W132,"N/D") -> 3500.5135
C13: =IF(COUNT(Supuestos!$D$18,Supuestos!$D$19)=2,DATE(YEAR(EDATE(Supuestos!J21,Supuestos!$D$18)),MONTH(EDATE(Supuestos!J21,Supuestos!$D$18)),Supuestos!$D$19),"N/D") -> 46522 | D13: =Mensual!J25 -> 2.6983125 | E13: =IF(COUNT(Supuestos!$D$10)=1,Supuestos!$D$10,"N/D") -> 2500 | F13: =Supuestos!J80 -> 0.7 | G13: =Supuestos!J55 -> 0.95 | H13: =Supuestos!J60 -> 0.9 | I13: =Supuestos!J65 -> 0.85 | J13: =Supuestos!J70 -> 0.8 | K13: =Supuestos!J75 -> 0.75 | L13: =IF(COUNT($D13,$E13,L133)=3,$D13*$E13*L133,"N/D") -> 0 | M13: =IF(COUNT($D13,$E13,M133)=3,$D13*$E13*M133,"N/D") -> 0 | N13: =IF(COUNT($D13,$E13,N133)=3,$D13*$E13*N133,"N/D") -> 0 | O13: =IF(COUNT($D13,$E13,O133)=3,$D13*$E13*O133,"N/D") -> 0 | P13: =IF(COUNT($D13,$E13,P133)=3,$D13*$E13*P133,"N/D") -> 6565.8938 | Q13: =IF(COUNT($D13,$E13,Q133)=3,$D13*$E13*Q133,"N/D") -> 6228.6047 | R13: =IF(COUNT($D13,$E13,R133)=3,$D13*$E13*R133,"N/D") -> 5880.0727 | S13: =IF(COUNT($D13,$E13,S133)=3,$D13*$E13*S133,"N/D") -> 5666.4563 | ... W13: =IF(COUNT($D13,$E13,W133)=3,$D13*$E13*W133,"N/D") -> 5305.4658
C14: =IF(COUNT(Supuestos!$D$18,Supuestos!$D$19)=2,DATE(YEAR(EDATE(Supuestos!K21,Supuestos!$D$18)),MONTH(EDATE(Supuestos!K21,Supuestos!$D$18)),Supuestos!$D$19),"N/D") -> 46553 | D14: =Mensual!K25 -> 3.59775 | E14: =IF(COUNT(Supuestos!$D$10)=1,Supuestos!$D$10,"N/D") -> 2500 | F14: =Supuestos!K80 -> 0.7 | G14: =Supuestos!K55 -> 0.95 | H14: =Supuestos!K60 -> 0.9 | I14: =Supuestos!K65 -> 0.85 | J14: =Supuestos!K70 -> 0.8 | K14: =Supuestos!K75 -> 0.75 | L14: =IF(COUNT($D14,$E14,L134)=3,$D14*$E14*L134,"N/D") -> 0 | M14: =IF(COUNT($D14,$E14,M134)=3,$D14*$E14*M134,"N/D") -> 0 | N14: =IF(COUNT($D14,$E14,N134)=3,$D14*$E14*N134,"N/D") -> 0 | O14: =IF(COUNT($D14,$E14,O134)=3,$D14*$E14*O134,"N/D") -> 0 | P14: =IF(COUNT($D14,$E14,P134)=3,$D14*$E14*P134,"N/D") -> 0 | Q14: =IF(COUNT($D14,$E14,Q134)=3,$D14*$E14*Q134,"N/D") -> 8769.5156 | R14: =IF(COUNT($D14,$E14,R134)=3,$D14*$E14*R134,"N/D") -> 8304.8062 | S14: =IF(COUNT($D14,$E14,S134)=3,$D14*$E14*S134,"N/D") -> 7840.0969 | ... W14: =IF(COUNT($D14,$E14,W134)=3,$D14*$E14*W134,"N/D") -> 7149.3127
C15: =IF(COUNT(Supuestos!$D$18,Supuestos!$D$19)=2,DATE(YEAR(EDATE(Supuestos!L21,Supuestos!$D$18)),MONTH(EDATE(Supuestos!L21,Supuestos!$D$18)),Supuestos!$D$19),"N/D") -> 46583 | D15: =Mensual!L25 -> 4.4971875 | E15: =IF(COUNT(Supuestos!$D$10)=1,Supuestos!$D$10,"N/D") -> 2500 | F15: =Supuestos!L80 -> 0.7 | G15: =Supuestos!L55 -> 0.95 | H15: =Supuestos!L60 -> 0.9 | I15: =Supuestos!L65 -> 0.85 | J15: =Supuestos!L70 -> 0.8 | K15: =Supuestos!L75 -> 0.75 | L15: =IF(COUNT($D15,$E15,L135)=3,$D15*$E15*L135,"N/D") -> 0 | M15: =IF(COUNT($D15,$E15,M135)=3,$D15*$E15*M135,"N/D") -> 0 | N15: =IF(COUNT($D15,$E15,N135)=3,$D15*$E15*N135,"N/D") -> 0 | O15: =IF(COUNT($D15,$E15,O135)=3,$D15*$E15*O135,"N/D") -> 0 | P15: =IF(COUNT($D15,$E15,P135)=3,$D15*$E15*P135,"N/D") -> 0 | Q15: =IF(COUNT($D15,$E15,Q135)=3,$D15*$E15*Q135,"N/D") -> 0 | R15: =IF(COUNT($D15,$E15,R135)=3,$D15*$E15*R135,"N/D") -> 10943.156 | S15: =IF(COUNT($D15,$E15,S135)=3,$D15*$E15*S135,"N/D") -> 10362.27 | ... W15: =IF(COUNT($D15,$E15,W135)=3,$D15*$E15*W135,"N/D") -> 9063.082
C16: =IF(COUNT(Supuestos!$D$18,Supuestos!$D$19)=2,DATE(YEAR(EDATE(Supuestos!M21,Supuestos!$D$18)),MONTH(EDATE(Supuestos!M21,Supuestos!$D$18)),Supuestos!$D$19),"N/D") -> 46614 | D16: =Mensual!M25 -> 5.396625 | E16: =IF(COUNT(Supuestos!$D$10)=1,Supuestos!$D$10,"N/D") -> 2500 | F16: =Supuestos!M80 -> 0.7 | G16: =Supuestos!M55 -> 0.95 | H16: =Supuestos!M60 -> 0.9 | I16: =Supuestos!M65 -> 0.85 | J16: =Supuestos!M70 -> 0.8 | K16: =Supuestos!M75 -> 0.75 | L16: =IF(COUNT($D16,$E16,L136)=3,$D16*$E16*L136,"N/D") -> 0 | M16: =IF(COUNT($D16,$E16,M136)=3,$D16*$E16*M136,"N/D") -> 0 | N16: =IF(COUNT($D16,$E16,N136)=3,$D16*$E16*N136,"N/D") -> 0 | O16: =IF(COUNT($D16,$E16,O136)=3,$D16*$E16*O136,"N/D") -> 0 | P16: =IF(COUNT($D16,$E16,P136)=3,$D16*$E16*P136,"N/D") -> 0 | Q16: =IF(COUNT($D16,$E16,Q136)=3,$D16*$E16*Q136,"N/D") -> 0 | R16: =IF(COUNT($D16,$E16,R136)=3,$D16*$E16*R136,"N/D") -> 0 | S16: =IF(COUNT($D16,$E16,S136)=3,$D16*$E16*S136,"N/D") -> 13131.788 | ... W16: =IF(COUNT($D16,$E16,W136)=3,$D16*$E16*W136,"N/D") -> 11108.053
C17: =IF(COUNT(Supuestos!$D$18,Supuestos!$D$19)=2,DATE(YEAR(EDATE(Supuestos!N21,Supuestos!$D$18)),MONTH(EDATE(Supuestos!N21,Supuestos!$D$18)),Supuestos!$D$19),"N/D") -> 46645 | D17: =Mensual!N25 -> 6.2960625 | E17: =IF(COUNT(Supuestos!$D$10)=1,Supuestos!$D$10,"N/D") -> 2500 | F17: =Supuestos!N80 -> 0.7 | G17: =Supuestos!N55 -> 0.95 | H17: =Supuestos!N60 -> 0.9 | I17: =Supuestos!N65 -> 0.85 | J17: =Supuestos!N70 -> 0.8 | K17: =Supuestos!N75 -> 0.75 | L17: =IF(COUNT($D17,$E17,L137)=3,$D17*$E17*L137,"N/D") -> 0 | M17: =IF(COUNT($D17,$E17,M137)=3,$D17*$E17*M137,"N/D") -> 0 | N17: =IF(COUNT($D17,$E17,N137)=3,$D17*$E17*N137,"N/D") -> 0 | O17: =IF(COUNT($D17,$E17,O137)=3,$D17*$E17*O137,"N/D") -> 0 | P17: =IF(COUNT($D17,$E17,P137)=3,$D17*$E17*P137,"N/D") -> 0 | Q17: =IF(COUNT($D17,$E17,Q137)=3,$D17*$E17*Q137,"N/D") -> 0 | R17: =IF(COUNT($D17,$E17,R137)=3,$D17*$E17*R137,"N/D") -> 0 | S17: =IF(COUNT($D17,$E17,S137)=3,$D17*$E17*S137,"N/D") -> 0 | ... W17: =IF(COUNT($D17,$E17,W137)=3,$D17*$E17*W137,"N/D") -> 13230.476
C18: =IF(COUNT(Supuestos!$D$18,Supuestos!$D$19)=2,DATE(YEAR(EDATE(Supuestos!O21,Supuestos!$D$18)),MONTH(EDATE(Supuestos!O21,Supuestos!$D$18)),Supuestos!$D$19),"N/D") -> 46675 | D18: =Mensual!O25 -> 7.1955 | E18: =IF(COUNT(Supuestos!$D$10)=1,Supuestos!$D$10,"N/D") -> 2500 | F18: =Supuestos!O80 -> 0.7 | G18: =Supuestos!O55 -> 0.95 | H18: =Supuestos!O60 -> 0.9 | I18: =Supuestos!O65 -> 0.85 | J18: =Supuestos!O70 -> 0.8 | K18: =Supuestos!O75 -> 0.75 | L18: =IF(COUNT($D18,$E18,L138)=3,$D18*$E18*L138,"N/D") -> 0 | M18: =IF(COUNT($D18,$E18,M138)=3,$D18*$E18*M138,"N/D") -> 0 | N18: =IF(COUNT($D18,$E18,N138)=3,$D18*$E18*N138,"N/D") -> 0 | O18: =IF(COUNT($D18,$E18,O138)=3,$D18*$E18*O138,"N/D") -> 0 | P18: =IF(COUNT($D18,$E18,P138)=3,$D18*$E18*P138,"N/D") -> 0 | Q18: =IF(COUNT($D18,$E18,Q138)=3,$D18*$E18*Q138,"N/D") -> 0 | R18: =IF(COUNT($D18,$E18,R138)=3,$D18*$E18*R138,"N/D") -> 0 | S18: =IF(COUNT($D18,$E18,S138)=3,$D18*$E18*S138,"N/D") -> 0 | ... W18: =IF(COUNT($D18,$E18,W138)=3,$D18*$E18*W138,"N/D") -> 15680.194
C19: =IF(COUNT(Supuestos!$D$18,Supuestos!$D$19)=2,DATE(YEAR(EDATE(Supuestos!P21,Supuestos!$D$18)),MONTH(EDATE(Supuestos!P21,Supuestos!$D$18)),Supuestos!$D$19),"N/D") -> 46706 | D19: =Mensual!P25 -> 8.0949375 | E19: =IF(COUNT(Supuestos!$D$10)=1,Supuestos!$D$10,"N/D") -> 2500 | F19: =Supuestos!P80 -> 0.7 | G19: =Supuestos!P55 -> 0.95 | H19: =Supuestos!P60 -> 0.9 | I19: =Supuestos!P65 -> 0.85 | J19: =Supuestos!P70 -> 0.8 | K19: =Supuestos!P75 -> 0.75 | L19: =IF(COUNT($D19,$E19,L139)=3,$D19*$E19*L139,"N/D") -> 0 | M19: =IF(COUNT($D19,$E19,M139)=3,$D19*$E19*M139,"N/D") -> 0 | N19: =IF(COUNT($D19,$E19,N139)=3,$D19*$E19*N139,"N/D") -> 0 | O19: =IF(COUNT($D19,$E19,O139)=3,$D19*$E19*O139,"N/D") -> 0 | P19: =IF(COUNT($D19,$E19,P139)=3,$D19*$E19*P139,"N/D") -> 0 | Q19: =IF(COUNT($D19,$E19,Q139)=3,$D19*$E19*Q139,"N/D") -> 0 | R19: =IF(COUNT($D19,$E19,R139)=3,$D19*$E19*R139,"N/D") -> 0 | S19: =IF(COUNT($D19,$E19,S139)=3,$D19*$E19*S139,"N/D") -> 0 | ... W19: =IF(COUNT($D19,$E19,W139)=3,$D19*$E19*W139,"N/D") -> 18685.814
C20: =IF(COUNT(Supuestos!$D$18,Supuestos!$D$19)=2,DATE(YEAR(EDATE(Supuestos!Q21,Supuestos!$D$18)),MONTH(EDATE(Supuestos!Q21,Supuestos!$D$18)),Supuestos!$D$19),"N/D") -> 46736 | D20: =Mensual!Q25 -> 8.994375 | E20: =IF(COUNT(Supuestos!$D$10)=1,Supuestos!$D$10,"N/D") -> 2500 | F20: =Supuestos!Q80 -> 0.7 | G20: =Supuestos!Q55 -> 0.95 | H20: =Supuestos!Q60 -> 0.9 | I20: =Supuestos!Q65 -> 0.85 | J20: =Supuestos!Q70 -> 0.8 | K20: =Supuestos!Q75 -> 0.75 | L20: =IF(COUNT($D20,$E20,L140)=3,$D20*$E20*L140,"N/D") -> 0 | M20: =IF(COUNT($D20,$E20,M140)=3,$D20*$E20*M140,"N/D") -> 0 | N20: =IF(COUNT($D20,$E20,N140)=3,$D20*$E20*N140,"N/D") -> 0 | O20: =IF(COUNT($D20,$E20,O140)=3,$D20*$E20*O140,"N/D") -> 0 | P20: =IF(COUNT($D20,$E20,P140)=3,$D20*$E20*P140,"N/D") -> 0 | Q20: =IF(COUNT($D20,$E20,Q140)=3,$D20*$E20*Q140,"N/D") -> 0 | R20: =IF(COUNT($D20,$E20,R140)=3,$D20*$E20*R140,"N/D") -> 0 | S20: =IF(COUNT($D20,$E20,S140)=3,$D20*$E20*S140,"N/D") -> 0 | ... W20: =IF(COUNT($D20,$E20,W140)=3,$D20*$E20*W140,"N/D") -> 21886.312
C22: Saldo cierre USD eq. | L22: =IF(COUNT(L9:L20)=12,SUM(L9:L20),"N/D") -> 437.72625 | M22: =IF(COUNT(M9:M20)=12,SUM(M9:M20),"N/D") -> 1736.6639 | N22: =IF(COUNT(N9:N20)=12,SUM(N9:N20),"N/D") -> 4270.0795 | O22: =IF(COUNT(O9:O20)=12,SUM(O9:O20),"N/D") -> 8437.4733 | P22: =IF(COUNT(P9:P20)=12,SUM(P9:P20),"N/D") -> 14576.634 | Q22: =IF(COUNT(Q9:Q20)=12,SUM(Q9:Q20),"N/D") -> 22670.072 | R22: =IF(COUNT(R9:R20)=12,SUM(R9:R20),"N/D") -> 32577.309 | S22: =IF(COUNT(S9:S20)=12,SUM(S9:S20),"N/D") -> 44305.501 | ... W22: =IF(COUNT(W9:W20)=12,SUM(W9:W20),"N/D") -> 109054.68
C28: Saldo externo al cierre, por cohorte | L28: M 1 | M28: M 2 | N28: M 3 | O28: M 4 | P28: M 5 | Q28: M 6 | R28: M 7 | S28: M 8 | T28: M 9 | U28: M 10 | V28: M 11 | W28: M 12
C30: =C9 -> 46402 | L30: =IF(COUNT(L9,$F9)=2,L9*$F9,"N/D") -> 306.40837 | M30: =IF(COUNT(M9,$F9)=2,M9*$F9,"N/D") -> 291.71756 | N30: =IF(COUNT(N9,$F9)=2,N9*$F9,"N/D") -> 275.45273 | O30: =IF(COUNT(O9,$F9)=2,O9*$F9,"N/D") -> 264.9593 | P30: =IF(COUNT(P9,$F9)=2,P9*$F9,"N/D") -> 259.53769 | Q30: =IF(COUNT(Q9,$F9)=2,Q9*$F9,"N/D") -> 254.29097 | R30: =IF(COUNT(R9,$F9)=2,R9*$F9,"N/D") -> 250.39611 | S30: =IF(COUNT(S9,$F9)=2,S9*$F9,"N/D") -> 247.75857 | ... W30: =IF(COUNT(W9,$F9)=2,W9*$F9,"N/D") -> 237.37857
C31: =C10 -> 46433 | L31: =IF(COUNT(L10,$F10)=2,L10*$F10,"N/D") -> 0 | M31: =IF(COUNT(M10,$F10)=2,M10*$F10,"N/D") -> 923.94717 | N31: =IF(COUNT(N10,$F10)=2,N10*$F10,"N/D") -> 875.15269 | O31: =IF(COUNT(O10,$F10)=2,O10*$F10,"N/D") -> 827.93222 | P31: =IF(COUNT(P10,$F10)=2,P10*$F10,"N/D") -> 794.87789 | Q31: =IF(COUNT(Q10,$F10)=2,Q10*$F10,"N/D") -> 779.13773 | R31: =IF(COUNT(R10,$F10)=2,R10*$F10,"N/D") -> 762.87291 | S31: =IF(COUNT(S10,$F10)=2,S10*$F10,"N/D") -> 751.18832 | ... W31: =IF(COUNT(W10,$F10)=2,W10*$F10,"N/D") -> 720.04834
C32: =C11 -> 46461 | L32: =IF(COUNT(L11,$F11)=2,L11*$F11,"N/D") -> 0 | M32: =IF(COUNT(M11,$F11)=2,M11*$F11,"N/D") -> 0 | N32: =IF(COUNT(N11,$F11)=2,N11*$F11,"N/D") -> 1838.4503 | O32: =IF(COUNT(O11,$F11)=2,O11*$F11,"N/D") -> 1744.0093 | P32: =IF(COUNT(P11,$F11)=2,P11*$F11,"N/D") -> 1646.4203 | Q32: =IF(COUNT(Q11,$F11)=2,Q11*$F11,"N/D") -> 1587.6571 | R32: =IF(COUNT(R11,$F11)=2,R11*$F11,"N/D") -> 1555.1274 | S32: =IF(COUNT(S11,$F11)=2,S11*$F11,"N/D") -> 1522.5978 | ... W32: =IF(COUNT(W11,$F11)=2,W11*$F11,"N/D") -> 1454.3904
C33: =C12 -> 46492 | L33: =IF(COUNT(L12,$F12)=2,L12*$F12,"N/D") -> 0 | M33: =IF(COUNT(M12,$F12)=2,M12*$F12,"N/D") -> 0 | N33: =IF(COUNT(N12,$F12)=2,N12*$F12,"N/D") -> 0 | O33: =IF(COUNT(O12,$F12)=2,O12*$F12,"N/D") -> 3069.3305 | P33: =IF(COUNT(P12,$F12)=2,P12*$F12,"N/D") -> 2906.6822 | Q33: =IF(COUNT(Q12,$F12)=2,Q12*$F12,"N/D") -> 2749.2806 | R33: =IF(COUNT(R12,$F12)=2,R12*$F12,"N/D") -> 2646.0952 | S33: =IF(COUNT(S12,$F12)=2,S12*$F12,"N/D") -> 2591.8791 | ... W33: =IF(COUNT(W12,$F12)=2,W12*$F12,"N/D") -> 2450.3595
C34: =C13 -> 46522 | L34: =IF(COUNT(L13,$F13)=2,L13*$F13,"N/D") -> 0 | M34: =IF(COUNT(M13,$F13)=2,M13*$F13,"N/D") -> 0 | N34: =IF(COUNT(N13,$F13)=2,N13*$F13,"N/D") -> 0 | O34: =IF(COUNT(O13,$F13)=2,O13*$F13,"N/D") -> 0 | P34: =IF(COUNT(P13,$F13)=2,P13*$F13,"N/D") -> 4596.1256 | Q34: =IF(COUNT(Q13,$F13)=2,Q13*$F13,"N/D") -> 4360.0233 | R34: =IF(COUNT(R13,$F13)=2,R13*$F13,"N/D") -> 4116.0509 | S34: =IF(COUNT(S13,$F13)=2,S13*$F13,"N/D") -> 3966.5194 | ... W34: =IF(COUNT(W13,$F13)=2,W13*$F13,"N/D") -> 3713.8261
C35: =C14 -> 46553 | L35: =IF(COUNT(L14,$F14)=2,L14*$F14,"N/D") -> 0 | M35: =IF(COUNT(M14,$F14)=2,M14*$F14,"N/D") -> 0 | N35: =IF(COUNT(N14,$F14)=2,N14*$F14,"N/D") -> 0 | O35: =IF(COUNT(O14,$F14)=2,O14*$F14,"N/D") -> 0 | P35: =IF(COUNT(P14,$F14)=2,P14*$F14,"N/D") -> 0 | Q35: =IF(COUNT(Q14,$F14)=2,Q14*$F14,"N/D") -> 6138.6609 | R35: =IF(COUNT(R14,$F14)=2,R14*$F14,"N/D") -> 5813.3644 | S35: =IF(COUNT(S14,$F14)=2,S14*$F14,"N/D") -> 5488.0678 | ... W35: =IF(COUNT(W14,$F14)=2,W14*$F14,"N/D") -> 5004.5189
C36: =C15 -> 46583 | L36: =IF(COUNT(L15,$F15)=2,L15*$F15,"N/D") -> 0 | M36: =IF(COUNT(M15,$F15)=2,M15*$F15,"N/D") -> 0 | N36: =IF(COUNT(N15,$F15)=2,N15*$F15,"N/D") -> 0 | O36: =IF(COUNT(O15,$F15)=2,O15*$F15,"N/D") -> 0 | P36: =IF(COUNT(P15,$F15)=2,P15*$F15,"N/D") -> 0 | Q36: =IF(COUNT(Q15,$F15)=2,Q15*$F15,"N/D") -> 0 | R36: =IF(COUNT(R15,$F15)=2,R15*$F15,"N/D") -> 7660.2094 | S36: =IF(COUNT(S15,$F15)=2,S15*$F15,"N/D") -> 7253.5887 | ... W36: =IF(COUNT(W15,$F15)=2,W15*$F15,"N/D") -> 6344.1574
C37: =C16 -> 46614 | L37: =IF(COUNT(L16,$F16)=2,L16*$F16,"N/D") -> 0 | M37: =IF(COUNT(M16,$F16)=2,M16*$F16,"N/D") -> 0 | N37: =IF(COUNT(N16,$F16)=2,N16*$F16,"N/D") -> 0 | O37: =IF(COUNT(O16,$F16)=2,O16*$F16,"N/D") -> 0 | P37: =IF(COUNT(P16,$F16)=2,P16*$F16,"N/D") -> 0 | Q37: =IF(COUNT(Q16,$F16)=2,Q16*$F16,"N/D") -> 0 | R37: =IF(COUNT(R16,$F16)=2,R16*$F16,"N/D") -> 0 | S37: =IF(COUNT(S16,$F16)=2,S16*$F16,"N/D") -> 9192.2512 | ... W37: =IF(COUNT(W16,$F16)=2,W16*$F16,"N/D") -> 7775.6372
C38: =C17 -> 46645 | L38: =IF(COUNT(L17,$F17)=2,L17*$F17,"N/D") -> 0 | M38: =IF(COUNT(M17,$F17)=2,M17*$F17,"N/D") -> 0 | N38: =IF(COUNT(N17,$F17)=2,N17*$F17,"N/D") -> 0 | O38: =IF(COUNT(O17,$F17)=2,O17*$F17,"N/D") -> 0 | P38: =IF(COUNT(P17,$F17)=2,P17*$F17,"N/D") -> 0 | Q38: =IF(COUNT(Q17,$F17)=2,Q17*$F17,"N/D") -> 0 | R38: =IF(COUNT(R17,$F17)=2,R17*$F17,"N/D") -> 0 | S38: =IF(COUNT(S17,$F17)=2,S17*$F17,"N/D") -> 0 | ... W38: =IF(COUNT(W17,$F17)=2,W17*$F17,"N/D") -> 9261.333
C39: =C18 -> 46675 | L39: =IF(COUNT(L18,$F18)=2,L18*$F18,"N/D") -> 0 | M39: =IF(COUNT(M18,$F18)=2,M18*$F18,"N/D") -> 0 | N39: =IF(COUNT(N18,$F18)=2,N18*$F18,"N/D") -> 0 | O39: =IF(COUNT(O18,$F18)=2,O18*$F18,"N/D") -> 0 | P39: =IF(COUNT(P18,$F18)=2,P18*$F18,"N/D") -> 0 | Q39: =IF(COUNT(Q18,$F18)=2,Q18*$F18,"N/D") -> 0 | R39: =IF(COUNT(R18,$F18)=2,R18*$F18,"N/D") -> 0 | S39: =IF(COUNT(S18,$F18)=2,S18*$F18,"N/D") -> 0 | ... W39: =IF(COUNT(W18,$F18)=2,W18*$F18,"N/D") -> 10976.136
C40: =C19 -> 46706 | L40: =IF(COUNT(L19,$F19)=2,L19*$F19,"N/D") -> 0 | M40: =IF(COUNT(M19,$F19)=2,M19*$F19,"N/D") -> 0 | N40: =IF(COUNT(N19,$F19)=2,N19*$F19,"N/D") -> 0 | O40: =IF(COUNT(O19,$F19)=2,O19*$F19,"N/D") -> 0 | P40: =IF(COUNT(P19,$F19)=2,P19*$F19,"N/D") -> 0 | Q40: =IF(COUNT(Q19,$F19)=2,Q19*$F19,"N/D") -> 0 | R40: =IF(COUNT(R19,$F19)=2,R19*$F19,"N/D") -> 0 | S40: =IF(COUNT(S19,$F19)=2,S19*$F19,"N/D") -> 0 | ... W40: =IF(COUNT(W19,$F19)=2,W19*$F19,"N/D") -> 13080.07
C41: =C20 -> 46736 | L41: =IF(COUNT(L20,$F20)=2,L20*$F20,"N/D") -> 0 | M41: =IF(COUNT(M20,$F20)=2,M20*$F20,"N/D") -> 0 | N41: =IF(COUNT(N20,$F20)=2,N20*$F20,"N/D") -> 0 | O41: =IF(COUNT(O20,$F20)=2,O20*$F20,"N/D") -> 0 | P41: =IF(COUNT(P20,$F20)=2,P20*$F20,"N/D") -> 0 | Q41: =IF(COUNT(Q20,$F20)=2,Q20*$F20,"N/D") -> 0 | R41: =IF(COUNT(R20,$F20)=2,R20*$F20,"N/D") -> 0 | S41: =IF(COUNT(S20,$F20)=2,S20*$F20,"N/D") -> 0 | ... W41: =IF(COUNT(W20,$F20)=2,W20*$F20,"N/D") -> 15320.419
C43: Saldo externo cierre | L43: =IF(COUNT(L30:L41)=12,SUM(L30:L41),"N/D") -> 306.40837 | M43: =IF(COUNT(M30:M41)=12,SUM(M30:M41),"N/D") -> 1215.6647 | N43: =IF(COUNT(N30:N41)=12,SUM(N30:N41),"N/D") -> 2989.0557 | O43: =IF(COUNT(O30:O41)=12,SUM(O30:O41),"N/D") -> 5906.2313 | P43: =IF(COUNT(P30:P41)=12,SUM(P30:P41),"N/D") -> 10203.644 | Q43: =IF(COUNT(Q30:Q41)=12,SUM(Q30:Q41),"N/D") -> 15869.051 | R43: =IF(COUNT(R30:R41)=12,SUM(R30:R41),"N/D") -> 22804.116 | S43: =IF(COUNT(S30:S41)=12,SUM(S30:S41),"N/D") -> 31013.851 | ... W43: =IF(COUNT(W30:W41)=12,SUM(W30:W41),"N/D") -> 76338.274
C48: Saldo medio mensual, por cohorte | L48: M 1 | M48: M 2 | N48: M 3 | O48: M 4 | P48: M 5 | Q48: M 6 | R48: M 7 | S48: M 8 | T48: M 9 | U48: M 10 | V48: M 11 | W48: M 12
C50: =C9 -> 46402 | L50: =IF(COUNT($C9,$D9,$E9,L9,0)=5,IF($C9>EOMONTH(L$8,0),0,IF($C9>=L$8,($D9*$E9+L9)/2*(EOMONTH(L$8,0)-$C9+1)/DAY(EOMONTH(L$8,0)),(0+L9)/2)),"N/D") -> 243.33169 | M50: =IF(COUNT($C9,$D9,$E9,M9,L9)=5,IF($C9>EOMONTH(M$8,0),0,IF($C9>=M$8,($D9*$E9+M9)/2*(EOMONTH(M$8,0)-$C9+1)/DAY(EOMONTH(M$8,0)),(L9+M9)/2)),"N/D") -> 427.23281 | N50: =IF(COUNT($C9,$D9,$E9,N9,M9)=5,IF($C9>EOMONTH(N$8,0),0,IF($C9>=N$8,($D9*$E9+N9)/2*(EOMONTH(N$8,0)-$C9+1)/DAY(EOMONTH(N$8,0)),(M9+N9)/2)),"N/D") -> 405.12164 | O50: =IF(COUNT($C9,$D9,$E9,O9,N9)=5,IF($C9>EOMONTH(O$8,0),0,IF($C9>=O$8,($D9*$E9+O9)/2*(EOMONTH(O$8,0)-$C9+1)/DAY(EOMONTH(O$8,0)),(N9+O9)/2)),"N/D") -> 386.00859 | P50: =IF(COUNT($C9,$D9,$E9,P9,O9)=5,IF($C9>EOMONTH(P$8,0),0,IF($C9>=P$8,($D9*$E9+P9)/2*(EOMONTH(P$8,0)-$C9+1)/DAY(EOMONTH(P$8,0)),(O9+P9)/2)),"N/D") -> 374.6407 | Q50: =IF(COUNT($C9,$D9,$E9,Q9,P9)=5,IF($C9>EOMONTH(Q$8,0),0,IF($C9>=Q$8,($D9*$E9+Q9)/2*(EOMONTH(Q$8,0)-$C9+1)/DAY(EOMONTH(Q$8,0)),(P9+Q9)/2)),"N/D") -> 367.02047 | R50: =IF(COUNT($C9,$D9,$E9,R9,Q9)=5,IF($C9>EOMONTH(R$8,0),0,IF($C9>=R$8,($D9*$E9+R9)/2*(EOMONTH(R$8,0)-$C9+1)/DAY(EOMONTH(R$8,0)),(Q9+R9)/2)),"N/D") -> 360.49077 | S50: =IF(COUNT($C9,$D9,$E9,S9,R9)=5,IF($C9>EOMONTH(S$8,0),0,IF($C9>=S$8,($D9*$E9+S9)/2*(EOMONTH(S$8,0)-$C9+1)/DAY(EOMONTH(S$8,0)),(R9+S9)/2)),"N/D") -> 355.82477 | T50: =IF(COUNT($C9,$D9,$E9,T9,S9)=5,IF($C9>EOMONTH(T$8,0),0,IF($C9>=T$8,($D9*$E9+T9)/2*(EOMONTH(T$8,0)-$C9+1)/DAY(EOMONTH(T$8,0)),(S9+T9)/2)),"N/D") -> 352.11763 | ... W50: =IF(COUNT($C9,$D9,$E9,W9,V9)=5,IF($C9>EOMONTH(W$8,0),0,IF($C9>=W$8,($D9*$E9+W9)/2*(EOMONTH(W$8,0)-$C9+1)/DAY(EOMONTH(W$8,0)),(V9+W9)/2)),"N/D") -> 340.9962
C51: =C10 -> 46433 | L51: =IF(COUNT($C10,$D10,$E10,L10,0)=5,IF($C10>EOMONTH(L$8,0),0,IF($C10>=L$8,($D10*$E10+L10)/2*(EOMONTH(L$8,0)-$C10+1)/DAY(EOMONTH(L$8,0)),(0+L10)/2)),"N/D") -> 0 | M51: =IF(COUNT($C10,$D10,$E10,M10,L10)=5,IF($C10>EOMONTH(M$8,0),0,IF($C10>=M$8,($D10*$E10+M10)/2*(EOMONTH(M$8,0)-$C10+1)/DAY(EOMONTH(M$8,0)),(L10+M10)/2)),"N/D") -> 667.2702 | N51: =IF(COUNT($C10,$D10,$E10,N10,M10)=5,IF($C10>EOMONTH(N$8,0),0,IF($C10>=N$8,($D10*$E10+N10)/2*(EOMONTH(N$8,0)-$C10+1)/DAY(EOMONTH(N$8,0)),(M10+N10)/2)),"N/D") -> 1285.0713 | O51: =IF(COUNT($C10,$D10,$E10,O10,N10)=5,IF($C10>EOMONTH(O$8,0),0,IF($C10>=O$8,($D10*$E10+O10)/2*(EOMONTH(O$8,0)-$C10+1)/DAY(EOMONTH(O$8,0)),(N10+O10)/2)),"N/D") -> 1216.4892 | P51: =IF(COUNT($C10,$D10,$E10,P10,O10)=5,IF($C10>EOMONTH(P$8,0),0,IF($C10>=P$8,($D10*$E10+P10)/2*(EOMONTH(P$8,0)-$C10+1)/DAY(EOMONTH(P$8,0)),(O10+P10)/2)),"N/D") -> 1159.1501 | Q51: =IF(COUNT($C10,$D10,$E10,Q10,P10)=5,IF($C10>EOMONTH(Q$8,0),0,IF($C10>=Q$8,($D10*$E10+Q10)/2*(EOMONTH(Q$8,0)-$C10+1)/DAY(EOMONTH(Q$8,0)),(P10+Q10)/2)),"N/D") -> 1124.2969 | R51: =IF(COUNT($C10,$D10,$E10,R10,Q10)=5,IF($C10>EOMONTH(R$8,0),0,IF($C10>=R$8,($D10*$E10+R10)/2*(EOMONTH(R$8,0)-$C10+1)/DAY(EOMONTH(R$8,0)),(Q10+R10)/2)),"N/D") -> 1101.4362 | S51: =IF(COUNT($C10,$D10,$E10,S10,R10)=5,IF($C10>EOMONTH(S$8,0),0,IF($C10>=S$8,($D10*$E10+S10)/2*(EOMONTH(S$8,0)-$C10+1)/DAY(EOMONTH(S$8,0)),(R10+S10)/2)),"N/D") -> 1081.4723 | T51: =IF(COUNT($C10,$D10,$E10,T10,S10)=5,IF($C10>EOMONTH(T$8,0),0,IF($C10>=T$8,($D10*$E10+T10)/2*(EOMONTH(T$8,0)-$C10+1)/DAY(EOMONTH(T$8,0)),(S10+T10)/2)),"N/D") -> 1067.6566 | ... W51: =IF(COUNT($C10,$D10,$E10,W10,V10)=5,IF($C10>EOMONTH(W$8,0),0,IF($C10>=W$8,($D10*$E10+W10)/2*(EOMONTH(W$8,0)-$C10+1)/DAY(EOMONTH(W$8,0)),(V10+W10)/2)),"N/D") -> 1034.2924
C52: =C11 -> 46461 | L52: =IF(COUNT($C11,$D11,$E11,L11,0)=5,IF($C11>EOMONTH(L$8,0),0,IF($C11>=L$8,($D11*$E11+L11)/2*(EOMONTH(L$8,0)-$C11+1)/DAY(EOMONTH(L$8,0)),(0+L11)/2)),"N/D") -> 0 | M52: =IF(COUNT($C11,$D11,$E11,M11,L11)=5,IF($C11>EOMONTH(M$8,0),0,IF($C11>=M$8,($D11*$E11+M11)/2*(EOMONTH(M$8,0)-$C11+1)/DAY(EOMONTH(M$8,0)),(L11+M11)/2)),"N/D") -> 0 | N52: =IF(COUNT($C11,$D11,$E11,N11,M11)=5,IF($C11>EOMONTH(N$8,0),0,IF($C11>=N$8,($D11*$E11+N11)/2*(EOMONTH(N$8,0)-$C11+1)/DAY(EOMONTH(N$8,0)),(M11+N11)/2)),"N/D") -> 1459.9902 | O52: =IF(COUNT($C11,$D11,$E11,O11,N11)=5,IF($C11>EOMONTH(O$8,0),0,IF($C11>=O$8,($D11*$E11+O11)/2*(EOMONTH(O$8,0)-$C11+1)/DAY(EOMONTH(O$8,0)),(N11+O11)/2)),"N/D") -> 2558.8997 | P52: =IF(COUNT($C11,$D11,$E11,P11,O11)=5,IF($C11>EOMONTH(P$8,0),0,IF($C11>=P$8,($D11*$E11+P11)/2*(EOMONTH(P$8,0)-$C11+1)/DAY(EOMONTH(P$8,0)),(O11+P11)/2)),"N/D") -> 2421.7355 | Q52: =IF(COUNT($C11,$D11,$E11,Q11,P11)=5,IF($C11>EOMONTH(Q$8,0),0,IF($C11>=Q$8,($D11*$E11+Q11)/2*(EOMONTH(Q$8,0)-$C11+1)/DAY(EOMONTH(Q$8,0)),(P11+Q11)/2)),"N/D") -> 2310.0553 | R52: =IF(COUNT($C11,$D11,$E11,R11,Q11)=5,IF($C11>EOMONTH(R$8,0),0,IF($C11>=R$8,($D11*$E11+R11)/2*(EOMONTH(R$8,0)-$C11+1)/DAY(EOMONTH(R$8,0)),(Q11+R11)/2)),"N/D") -> 2244.8461 | S52: =IF(COUNT($C11,$D11,$E11,S11,R11)=5,IF($C11>EOMONTH(S$8,0),0,IF($C11>=S$8,($D11*$E11+S11)/2*(EOMONTH(S$8,0)-$C11+1)/DAY(EOMONTH(S$8,0)),(R11+S11)/2)),"N/D") -> 2198.3752 | T52: =IF(COUNT($C11,$D11,$E11,T11,S11)=5,IF($C11>EOMONTH(T$8,0),0,IF($C11>=T$8,($D11*$E11+T11)/2*(EOMONTH(T$8,0)-$C11+1)/DAY(EOMONTH(T$8,0)),(S11+T11)/2)),"N/D") -> 2159.9667 | ... W52: =IF(COUNT($C11,$D11,$E11,W11,V11)=5,IF($C11>EOMONTH(W$8,0),0,IF($C11>=W$8,($D11*$E11+W11)/2*(EOMONTH(W$8,0)-$C11+1)/DAY(EOMONTH(W$8,0)),(V11+W11)/2)),"N/D") -> 2089.0044
