Workbook

Sheet Decision
C2: Pibank 2027: decisión de inversión, no forecast
C4: La decisión parte de requisitos y valor bancario. Los escenarios previos 10/50/147 se retiran del uso con cliente; archivos históricos intactos.
C6: Pregunta de inversión | D6: Resultado activo | E6: Unidad
C8: Contribución contextual requerida | D8: =Supuestos!D12 -> 152 | E8: cuentas
C9: Visitas requeridas bajo tasas de prueba | D9: =IF(COUNT(Requisitos!F13:Q13)=12,SUM(Requisitos!F13:Q13),"N/D") -> 7600 | E9: visitas
C10: Ratio requisito / panel parcial elegible | D10: =IF(COUNT(Requisitos!F13:Q13,Requisitos!F16:Q16)=24,IF(SUM(Requisitos!F16:Q16)>0,SUM(Requisitos!F13:Q13)/SUM(Requisitos!F16:Q16),"N/D"),"N/D") -> 0.22884673 | E10: ratio panel
C11: Saldo medio externo en ventana activa | D11: =IF(COUNT(Requisitos!F19:Q19,Supuestos!D45)=13,SUM(Requisitos!F19:Q19)/Supuestos!D45,"N/D") -> 74916.492 | E11: USD eq.
C12: Saldo externo al cierre de ventana | D12: =IF(COUNT(Supuestos!D45)=1,INDEX(Requisitos!F20:Q20,1,Supuestos!D45),"N/D") -> 142419.88 | E12: USD eq.
C14: Valor neto banco según método/horizonte | D14: =Economia!D8 -> N/D | E14: USD
C15: Techo de inversión según retorno exigido | D15: =Economia!D9 -> N/D | E15: USD
C16: Piso operativo enfocado según costeo | D16: =Economia!D15 -> N/D | E16: USD
C17: Horas compatibles con el techo bancario | D17: =Economia!D17 -> N/D | E17: horas
C18: ROI condicionado dentro de ventana | D18: =Requisitos!Q26 -> N/D | E18: %
C19: Payback condicionado dentro de ventana | D19: =IF(COUNT(Requisitos!F27:Q27)=12,IFERROR(MATCH(1,Requisitos!F27:Q27,0),"No en ventana"),"N/D") -> N/D | E19: mes
C20: Fondeadas dentro de ventana, calidad | D20: =IF(COUNT(Requisitos!F11:Q11)=12,SUM(Requisitos!F11:Q11),"N/D") -> 98.8 | E20: cuentas
C21: N/D conserva inputs faltantes. El techo es condicional a alcanzar la contribución; no es precio, presupuesto aprobado ni beneficio garantizado.
C22: Fondeo potencial posterior (excluido) | D22: =IF(COUNT(Requisitos!F12:Q12,Supuestos!D10,D20)=14,SUM(Requisitos!F12:Q12)*Supuestos!D10-D20,"N/D") -> 0
C24: Banda contextual | D24: Cuentas según definición | E24: Visitas necesarias | F24: Saldo medio externo condicionado | G24: Techo inversión condicionado
C25: 0.01 | D25: =C25*Supuestos!D6 -> 152 | E25: =IF(COUNT($D$8,$D$9)=2,IF($D$8>0,$D$9*D25/$D$8,"N/D"),"N/D") -> 7600 | F25: =IF(COUNT($D$8,$D$11)=2,IF($D$8>0,$D$11*D25/$D$8,"N/D"),"N/D") -> 74916.492 | G25: =IF(COUNT($D$8,$D$15)=2,IF($D$8>0,$D$15*D25/$D$8,"N/D"),"N/D") -> N/D
C26: 0.05 | D26: =C26*Supuestos!D6 -> 760 | E26: =IF(COUNT($D$8,$D$9)=2,IF($D$8>0,$D$9*D26/$D$8,"N/D"),"N/D") -> 38000 | F26: =IF(COUNT($D$8,$D$11)=2,IF($D$8>0,$D$11*D26/$D$8,"N/D"),"N/D") -> 374582.46 | G26: =IF(COUNT($D$8,$D$15)=2,IF($D$8>0,$D$15*D26/$D$8,"N/D"),"N/D") -> N/D
C27: 0.1 | D27: =C27*Supuestos!D6 -> 1520 | E27: =IF(COUNT($D$8,$D$9)=2,IF($D$8>0,$D$9*D27/$D$8,"N/D"),"N/D") -> 76000 | F27: =IF(COUNT($D$8,$D$11)=2,IF($D$8>0,$D$11*D27/$D$8,"N/D"),"N/D") -> 749164.92 | G27: =IF(COUNT($D$8,$D$15)=2,IF($D$8>0,$D$15*D27/$D$8,"N/D"),"N/D") -> N/D
C29: Comparación matemática bajo iguales tasas, calendario y origen; no son tres forecasts paralelos ni objetivos comerciales acordados.
C31: Programa enfocado candidato: 814h base +110h reserva=924h. Operations revisa carga, dependencias y disponibilidad; no se vende por horas.
C32: Si piso operativo supera techo bancario condicionado: revisar contribución/canales/alcance y evidencia; no inventar demanda o conversión.
C34: Una intervención de conversión puede mejorar tráfico de otros canales; requiere baseline y contrafactual propios para valorar incrementalidad.
C35: Educación/confianza y retención son mecanismos posibles, no ingresos adicionales sumables sin cohortes y deduplicación.
C37: M1 revisa accesos, medición y delivery. Las optimizaciones M3/6/9/12 sostienen el programa anual; no son cortes por ROI a tres meses.
C39: Riesgo central: tamaño/captura elegible y valor neto por saldo no están medidos. Cotización se prepara; la evidencia privada refina, no bloquea.

Sheet Supuestos
C2: Inputs: metas contextuales, pruebas y validaciones
C3: Selector banda (1 / 2 / 3) | D3: 1
C4: Bandas 1/5/10% son decisiones de contribución contextual. No objetivos acordados ni previsiones del canal.
C5: Participación contextual elegida | D5: =CHOOSE(D3,1%,5%,10%) -> 0.01
C6: Meta cuentas provisional | D6: 15200 | F6: Definición de la banda | G6: Aperturas
C7: Meta USD inferida, sin periodo confirmado | D7: 38000000
C8: Ticket USD equivalente provisional | D8: 2500
C9: Visita→apertura, prueba aritmética | D9: 0.02
C10: Apertura→fondeo, prueba aritmética | D10: 0.65
C11: Elegibilidad del panel, prueba | D11: 0.75
C12: Cuentas requeridas según definición elegida | D12: =D5*D6 -> 152
C13: Lag apertura→primer fondeo (meses) | D13: 0
C14: Día de primer fondeo (1–28) | D14: 15
C15: Inicio ilustrativo programa | D15: 46388
C16: Finance valida método/valor neto | D16: No
C17: Valor neto anual por USD saldo medio externo
C18: ROI mínimo exigido, prueba 0=equilibrio | D18: 0
C19: Inversión cliente completa validada | D19: No
C20: Costeo/margen Efeonce validado | D20: No
C21: Costo real blended USD/h (pendiente)
C22: Margen bruto autorizado (pendiente)
C23: Horas candidato enfocado (base+reserva) | D23: 924
C25: Otros costos enfocado USD (pendiente)
C27: Conversión, elegibilidad, ticket, retención, origen y distribución son hipótesis. Se calculan requisitos; no se predicen resultados.
C28: US$38m = 15.200×2.500: inferencia provisional. Programa anual no confirma definición/anualidad de meta ni producto USD.
C29: Contexto del análisis | D29: Programa2027
C30: Fecha retrolanzamiento (desconocida)
F31: =IF(COUNT($D$36)=1,EDATE($D$36,0),"N/D") -> 46388 | G31: =IF(COUNT($D$36)=1,EDATE($D$36,1),"N/D") -> 46419 | H31: =IF(COUNT($D$36)=1,EDATE($D$36,2),"N/D") -> 46447 | I31: =IF(COUNT($D$36)=1,EDATE($D$36,3),"N/D") -> 46478 | J31: =IF(COUNT($D$36)=1,EDATE($D$36,4),"N/D") -> 46508 | K31: =IF(COUNT($D$36)=1,EDATE($D$36,5),"N/D") -> 46539 | L31: =IF(COUNT($D$36)=1,EDATE($D$36,6),"N/D") -> 46569 | M31: =IF(COUNT($D$36)=1,EDATE($D$36,7),"N/D") -> 46600 | N31: =IF(COUNT($D$36)=1,EDATE($D$36,8),"N/D") -> 46631 | O31: =IF(COUNT($D$36)=1,EDATE($D$36,9),"N/D") -> 46661 | P31: =IF(COUNT($D$36)=1,EDATE($D$36,10),"N/D") -> 46692 | Q31: =IF(COUNT($D$36)=1,EDATE($D$36,11),"N/D") -> 46722
C32: Inversión cliente USD mensual, pendiente
C34: Peso del objetivo de fondeo, prueba | F34: 1 | G34: 1 | H34: 1 | I34: 1 | J34: 1 | K34: 1 | L34: 1 | M34: 1 | N34: 1 | O34: 1 | P34: 1 | Q34: 1
C35: Meses ventana retrospectiva (desconocidos)
C36: Inicio del cálculo activo | D36: =IF(D29="Programa2027",D15,IF(COUNT(D30)=1,D30,"N/D")) -> 46388
C37: Saldo relativo 30 días (hipótesis) | D37: 0.95
C38: Saldo relativo 60 días (hipótesis) | D38: 0.9
C39: Saldo relativo 90 días (hipótesis) | D39: 0.85
C40: Saldo relativo 180 días (hipótesis) | D40: 0.8
C41: Saldo relativo 365 días (hipótesis) | D41: 0.75
C44: Origen externo por cohorte, prueba | F44: 0.7 | G44: 0.7 | H44: 0.7 | I44: 0.7 | J44: 0.7 | K44: 0.7 | L44: 0.7 | M44: 0.7 | N44: 0.7 | O44: 0.7 | P44: 0.7 | Q44: 0.7
C45: Meses activos del cálculo | D45: =IF(D29="Programa2027",12,IF(COUNT(D35)=1,IF(AND(D35>=1,D35<=12),D35,"N/D"),"N/D")) -> 12
C46: Los pesos distribuyen una meta requerida, no una rampa SEO. Lag excluye fondeos que necesitarían aperturas anteriores al programa.
...

Sheet Requisitos
C2: Requisitos mensuales para la contribución elegida
C6: Requisito | D6: Unidad | F6: M1 | G6: M2 | H6: M3 | I6: M4 | J6: M5 | K6: M6 | L6: M7 | M6: M8 | N6: M9 | O6: M10 | P6: M11 | Q6: M12
F7: =Supuestos!F31 -> 46388 | G7: =Supuestos!G31 -> 46419 | H7: =Supuestos!H31 -> 46447 | I7: =Supuestos!I31 -> 46478 | J7: =Supuestos!J31 -> 46508 | K7: =Supuestos!K31 -> 46539 | L7: =Supuestos!L31 -> 46569 | M7: =Supuestos!M31 -> 46600 | ... Q7: =Supuestos!Q31 -> 46722
C9: Peso de fondeo indicado | D9: peso | F9: =IF(COUNT(Supuestos!F34)=1,Supuestos!F34,"N/D") -> 1 | G9: =IF(COUNT(Supuestos!G34)=1,Supuestos!G34,"N/D") -> 1 | H9: =IF(COUNT(Supuestos!H34)=1,Supuestos!H34,"N/D") -> 1 | I9: =IF(COUNT(Supuestos!I34)=1,Supuestos!I34,"N/D") -> 1 | J9: =IF(COUNT(Supuestos!J34)=1,Supuestos!J34,"N/D") -> 1 | K9: =IF(COUNT(Supuestos!K34)=1,Supuestos!K34,"N/D") -> 1 | L9: =IF(COUNT(Supuestos!L34)=1,Supuestos!L34,"N/D") -> 1 | M9: =IF(COUNT(Supuestos!M34)=1,Supuestos!M34,"N/D") -> 1 | ... Q9: =IF(COUNT(Supuestos!Q34)=1,Supuestos!Q34,"N/D") -> 1
C10: Peso elegible por inicio/lag | D10: peso | F10: =IF(COUNT(Supuestos!$D$13,Supuestos!$D$45,F9)=3,IF(0<Supuestos!$D$45,IF(Supuestos!$G$6="Fondeadas",IF(0+Supuestos!$D$13<Supuestos!$D$45,F9,0),F9),0),"N/D") -> 1 | G10: =IF(COUNT(Supuestos!$D$13,Supuestos!$D$45,G9)=3,IF(1<Supuestos!$D$45,IF(Supuestos!$G$6="Fondeadas",IF(1+Supuestos!$D$13<Supuestos!$D$45,G9,0),G9),0),"N/D") -> 1 | H10: =IF(COUNT(Supuestos!$D$13,Supuestos!$D$45,H9)=3,IF(2<Supuestos!$D$45,IF(Supuestos!$G$6="Fondeadas",IF(2+Supuestos!$D$13<Supuestos!$D$45,H9,0),H9),0),"N/D") -> 1 | I10: =IF(COUNT(Supuestos!$D$13,Supuestos!$D$45,I9)=3,IF(3<Supuestos!$D$45,IF(Supuestos!$G$6="Fondeadas",IF(3+Supuestos!$D$13<Supuestos!$D$45,I9,0),I9),0),"N/D") -> 1 | J10: =IF(COUNT(Supuestos!$D$13,Supuestos!$D$45,J9)=3,IF(4<Supuestos!$D$45,IF(Supuestos!$G$6="Fondeadas",IF(4+Supuestos!$D$13<Supuestos!$D$45,J9,0),J9),0),"N/D") -> 1 | K10: =IF(COUNT(Supuestos!$D$13,Supuestos!$D$45,K9)=3,IF(5<Supuestos!$D$45,IF(Supuestos!$G$6="Fondeadas",IF(5+Supuestos!$D$13<Supuestos!$D$45,K9,0),K9),0),"N/D") -> 1 | L10: =IF(COUNT(Supuestos!$D$13,Supuestos!$D$45,L9)=3,IF(6<Supuestos!$D$45,IF(Supuestos!$G$6="Fondeadas",IF(6+Supuestos!$D$13<Supuestos!$D$45,L9,0),L9),0),"N/D") -> 1 | M10: =IF(COUNT(Supuestos!$D$13,Supuestos!$D$45,M9)=3,IF(7<Supuestos!$D$45,IF(Supuestos!$G$6="Fondeadas",IF(7+Supuestos!$D$13<Supuestos!$D$45,M9,0),M9),0),"N/D") -> 1 | N10: =IF(COUNT(Supuestos!$D$13,Supuestos!$D$45,N9)=3,IF(8<Supuestos!$D$45,IF(Supuestos!$G$6="Fondeadas",IF(8+Supuestos!$D$13<Supuestos!$D$45,N9,0),N9),0),"N/D") -> 1 | O10: =IF(COUNT(Supuestos!$D$13,Supuestos!$D$45,O9)=3,IF(9<Supuestos!$D$45,IF(Supuestos!$G$6="Fondeadas",IF(9+Supuestos!$D$13<Supuestos!$D$45,O9,0),O9),0),"N/D") -> 1 | P10: =IF(COUNT(Supuestos!$D$13,Supuestos!$D$45,P9)=3,IF(10<Supuestos!$D$45,IF(Supuestos!$G$6="Fondeadas",IF(10+Supuestos!$D$13<Supuestos!$D$45,P9,0),P9),0),"N/D") -> 1 | Q10: =IF(COUNT(Supuestos!$D$13,Supuestos!$D$45,Q9)=3,IF(11<Supuestos!$D$45,IF(Supuestos!$G$6="Fondeadas",IF(11+Supuestos!$D$13<Supuestos!$D$45,Q9,0),Q9),0),"N/D") -> 1
C11: Primeras cuentas fondeadas requeridas | D11: cuentas | F11: =IF(COUNT(Supuestos!$D$13,Supuestos!$D$45,Supuestos!$D$10)=3,IF(AND(0<Supuestos!$D$45,0>=Supuestos!$D$13),IF(COUNT(INDEX($F$12:$Q$12,1,1-Supuestos!$D$13))=1,INDEX($F$12:$Q$12,1,1-Supuestos!$D$13)*Supuestos!$D$10,"N/D"),0),"N/D") -> 8.2333333 | G11: =IF(COUNT(Supuestos!$D$13,Supuestos!$D$45,Supuestos!$D$10)=3,IF(AND(1<Supuestos!$D$45,1>=Supuestos!$D$13),IF(COUNT(INDEX($F$12:$Q$12,1,2-Supuestos!$D$13))=1,INDEX($F$12:$Q$12,1,2-Supuestos!$D$13)*Supuestos!$D$10,"N/D"),0),"N/D") -> 8.2333333 | H11: =IF(COUNT(Supuestos!$D$13,Supuestos!$D$45,Supuestos!$D$10)=3,IF(AND(2<Supuestos!$D$45,2>=Supuestos!$D$13),IF(COUNT(INDEX($F$12:$Q$12,1,3-Supuestos!$D$13))=1,INDEX($F$12:$Q$12,1,3-Supuestos!$D$13)*Supuestos!$D$10,"N/D"),0),"N/D") -> 8.2333333 | I11: =IF(COUNT(Supuestos!$D$13,Supuestos!$D$45,Supuestos!$D$10)=3,IF(AND(3<Supuestos!$D$45,3>=Supuestos!$D$13),IF(COUNT(INDEX($F$12:$Q$12,1,4-Supuestos!$D$13))=1,INDEX($F$12:$Q$12,1,4-Supuestos!$D$13)*Supuestos!$D$10,"N/D"),0),"N/D") -> 8.2333333 | J11: =IF(COUNT(Supuestos!$D$13,Supuestos!$D$45,Supuestos!$D$10)=3,IF(AND(4<Supuestos!$D$45,4>=Supuestos!$D$13),IF(COUNT(INDEX($F$12:$Q$12,1,5-Supuestos!$D$13))=1,INDEX($F$12:$Q$12,1,5-Supuestos!$D$13)*Supuestos!$D$10,"N/D"),0),"N/D") -> 8.2333333 | K11: =IF(COUNT(Supuestos!$D$13,Supuestos!$D$45,Supuestos!$D$10)=3,IF(AND(5<Supuestos!$D$45,5>=Supuestos!$D$13),IF(COUNT(INDEX($F$12:$Q$12,1,6-Supuestos!$D$13))=1,INDEX($F$12:$Q$12,1,6-Supuestos!$D$13)*Supuestos!$D$10,"N/D"),0),"N/D") -> 8.2333333 | L11: =IF(COUNT(Supuestos!$D$13,Supuestos!$D$45,Supuestos!$D$10)=3,IF(AND(6<Supuestos!$D$45,6>=Supuestos!$D$13),IF(COUNT(INDEX($F$12:$Q$12,1,7-Supuestos!$D$13))=1,INDEX($F$12:$Q$12,1,7-Supuestos!$D$13)*Supuestos!$D$10,"N/D"),0),"N/D") -> 8.2333333 | M11: =IF(COUNT(Supuestos!$D$13,Supuestos!$D$45,Supuestos!$D$10)=3,IF(AND(7<Supuestos!$D$45,7>=Supuestos!$D$13),IF(COUNT(INDEX($F$12:$Q$12,1,8-Supuestos!$D$13))=1,INDEX($F$12:$Q$12,1,8-Supuestos!$D$13)*Supuestos!$D$10,"N/D"),0),"N/D") -> 8.2333333 | N11: =IF(COUNT(Supuestos!$D$13,Supuestos!$D$45,Supuestos!$D$10)=3,IF(AND(8<Supuestos!$D$45,8>=Supuestos!$D$13),IF(COUNT(INDEX($F$12:$Q$12,1,9-Supuestos!$D$13))=1,INDEX($F$12:$Q$12,1,9-Supuestos!$D$13)*Supuestos!$D$10,"N/D"),0),"N/D") -> 8.2333333 | O11: =IF(COUNT(Supuestos!$D$13,Supuestos!$D$45,Supuestos!$D$10)=3,IF(AND(9<Supuestos!$D$45,9>=Supuestos!$D$13),IF(COUNT(INDEX($F$12:$Q$12,1,10-Supuestos!$D$13))=1,INDEX($F$12:$Q$12,1,10-Supuestos!$D$13)*Supuestos!$D$10,"N/D"),0),"N/D") -> 8.2333333 | P11: =IF(COUNT(Supuestos!$D$13,Supuestos!$D$45,Supuestos!$D$10)=3,IF(AND(10<Supuestos!$D$45,10>=Supuestos!$D$13),IF(COUNT(INDEX($F$12:$Q$12,1,11-Supuestos!$D$13))=1,INDEX($F$12:$Q$12,1,11-Supuestos!$D$13)*Supuestos!$D$10,"N/D"),0),"N/D") -> 8.2333333 | Q11: =IF(COUNT(Supuestos!$D$13,Supuestos!$D$45,Supuestos!$D$10)=3,IF(AND(11<Supuestos!$D$45,11>=Supuestos!$D$13),IF(COUNT(INDEX($F$12:$Q$12,1,12-Supuestos!$D$13))=1,INDEX($F$12:$Q$12,1,12-Supuestos!$D$13)*Supuestos!$D$10,"N/D"),0),"N/D") -> 8.2333333
C12: Aperturas necesarias desde este mes | D12: cuentas | F12: =IF(COUNT($F$10:$Q$10)=12,IF(SUM($F$10:$Q$10)>0,IF(Supuestos!$G$6="Aperturas",Supuestos!$D$12*F10/SUM($F$10:$Q$10),IF(COUNT(Supuestos!$D$10)=1,IF(Supuestos!$D$10>0,Supuestos!$D$12*F10/SUM($F$10:$Q$10)/Supuestos!$D$10,"N/D"),"N/D")),"N/D"),"N/D") -> 12.666667 | G12: =IF(COUNT($F$10:$Q$10)=12,IF(SUM($F$10:$Q$10)>0,IF(Supuestos!$G$6="Aperturas",Supuestos!$D$12*G10/SUM($F$10:$Q$10),IF(COUNT(Supuestos!$D$10)=1,IF(Supuestos!$D$10>0,Supuestos!$D$12*G10/SUM($F$10:$Q$10)/Supuestos!$D$10,"N/D"),"N/D")),"N/D"),"N/D") -> 12.666667 | H12: =IF(COUNT($F$10:$Q$10)=12,IF(SUM($F$10:$Q$10)>0,IF(Supuestos!$G$6="Aperturas",Supuestos!$D$12*H10/SUM($F$10:$Q$10),IF(COUNT(Supuestos!$D$10)=1,IF(Supuestos!$D$10>0,Supuestos!$D$12*H10/SUM($F$10:$Q$10)/Supuestos!$D$10,"N/D"),"N/D")),"N/D"),"N/D") -> 12.666667 | I12: =IF(COUNT($F$10:$Q$10)=12,IF(SUM($F$10:$Q$10)>0,IF(Supuestos!$G$6="Aperturas",Supuestos!$D$12*I10/SUM($F$10:$Q$10),IF(COUNT(Supuestos!$D$10)=1,IF(Supuestos!$D$10>0,Supuestos!$D$12*I10/SUM($F$10:$Q$10)/Supuestos!$D$10,"N/D"),"N/D")),"N/D"),"N/D") -> 12.666667 | J12: =IF(COUNT($F$10:$Q$10)=12,IF(SUM($F$10:$Q$10)>0,IF(Supuestos!$G$6="Aperturas",Supuestos!$D$12*J10/SUM($F$10:$Q$10),IF(COUNT(Supuestos!$D$10)=1,IF(Supuestos!$D$10>0,Supuestos!$D$12*J10/SUM($F$10:$Q$10)/Supuestos!$D$10,"N/D"),"N/D")),"N/D"),"N/D") -> 12.666667 | K12: =IF(COUNT($F$10:$Q$10)=12,IF(SUM($F$10:$Q$10)>0,IF(Supuestos!$G$6="Aperturas",Supuestos!$D$12*K10/SUM($F$10:$Q$10),IF(COUNT(Supuestos!$D$10)=1,IF(Supuestos!$D$10>0,Supuestos!$D$12*K10/SUM($F$10:$Q$10)/Supuestos!$D$10,"N/D"),"N/D")),"N/D"),"N/D") -> 12.666667 | L12: =IF(COUNT($F$10:$Q$10)=12,IF(SUM($F$10:$Q$10)>0,IF(Supuestos!$G$6="Aperturas",Supuestos!$D$12*L10/SUM($F$10:$Q$10),IF(COUNT(Supuestos!$D$10)=1,IF(Supuestos!$D$10>0,Supuestos!$D$12*L10/SUM($F$10:$Q$10)/Supuestos!$D$10,"N/D"),"N/D")),"N/D"),"N/D") -> 12.666667 | M12: =IF(COUNT($F$10:$Q$10)=12,IF(SUM($F$10:$Q$10)>0,IF(Supuestos!$G$6="Aperturas",Supuestos!$D$12*M10/SUM($F$10:$Q$10),IF(COUNT(Supuestos!$D$10)=1,IF(Supuestos!$D$10>0,Supuestos!$D$12*M10/SUM($F$10:$Q$10)/Supuestos!$D$10,"N/D"),"N/D")),"N/D"),"N/D") -> 12.666667 | ... Q12: =IF(COUNT($F$10:$Q$10)=12,IF(SUM($F$10:$Q$10)>0,IF(Supuestos!$G$6="Aperturas",Supuestos!$D$12*Q10/SUM($F$10:$Q$10),IF(COUNT(Supuestos!$D$10)=1,IF(Supuestos!$D$10>0,Supuestos!$D$12*Q10/SUM($F$10:$Q$10)/Supuestos!$D$10,"N/D"),"N/D")),"N/D"),"N/D") -> 12.666667
C13: Visitas necesarias desde este mes | D13: visitas | F13: =IF(COUNT(Supuestos!$D$9,F12)=2,IF(Supuestos!$D$9>0,F12/Supuestos!$D$9,"N/D"),"N/D") -> 633.33333 | G13: =IF(COUNT(Supuestos!$D$9,G12)=2,IF(Supuestos!$D$9>0,G12/Supuestos!$D$9,"N/D"),"N/D") -> 633.33333 | H13: =IF(COUNT(Supuestos!$D$9,H12)=2,IF(Supuestos!$D$9>0,H12/Supuestos!$D$9,"N/D"),"N/D") -> 633.33333 | I13: =IF(COUNT(Supuestos!$D$9,I12)=2,IF(Supuestos!$D$9>0,I12/Supuestos!$D$9,"N/D"),"N/D") -> 633.33333 | J13: =IF(COUNT(Supuestos!$D$9,J12)=2,IF(Supuestos!$D$9>0,J12/Supuestos!$D$9,"N/D"),"N/D") -> 633.33333 | K13: =IF(COUNT(Supuestos!$D$9,K12)=2,IF(Supuestos!$D$9>0,K12/Supuestos!$D$9,"N/D"),"N/D") -> 633.33333 | L13: =IF(COUNT(Supuestos!$D$9,L12)=2,IF(Supuestos!$D$9>0,L12/Supuestos!$D$9,"N/D"),"N/D") -> 633.33333 | M13: =IF(COUNT(Supuestos!$D$9,M12)=2,IF(Supuestos!$D$9>0,M12/Supuestos!$D$9,"N/D"),"N/D") -> 633.33333 | ... Q13: =IF(COUNT(Supuestos!$D$9,Q12)=2,IF(Supuestos!$D$9>0,Q12/Supuestos!$D$9,"N/D"),"N/D") -> 633.33333
C15: Panel directo observado, contexto parcial | D15: búsquedas/mes | F15: =Evidencia!J5 -> 3690 | G15: =Evidencia!J5 -> 3690 | H15: =Evidencia!J5 -> 3690 | I15: =Evidencia!J5 -> 3690 | J15: =Evidencia!J5 -> 3690 | K15: =Evidencia!J5 -> 3690 | L15: =Evidencia!J5 -> 3690 | M15: =Evidencia!J5 -> 3690 | N15: =Evidencia!J5 -> 3690 | O15: =Evidencia!J5 -> 3690 | P15: =Evidencia!J5 -> 3690 | Q15: =Evidencia!J5 -> 3690
C16: Panel tras elegibilidad hipotética | D16: búsquedas/mes | F16: =IF(COUNT(F15,Supuestos!$D$11,Supuestos!$D$45)=3,IF(0<Supuestos!$D$45,F15*Supuestos!$D$11,0),"N/D") -> 2767.5 | G16: =IF(COUNT(G15,Supuestos!$D$11,Supuestos!$D$45)=3,IF(1<Supuestos!$D$45,G15*Supuestos!$D$11,0),"N/D") -> 2767.5 | H16: =IF(COUNT(H15,Supuestos!$D$11,Supuestos!$D$45)=3,IF(2<Supuestos!$D$45,H15*Supuestos!$D$11,0),"N/D") -> 2767.5 | I16: =IF(COUNT(I15,Supuestos!$D$11,Supuestos!$D$45)=3,IF(3<Supuestos!$D$45,I15*Supuestos!$D$11,0),"N/D") -> 2767.5 | J16: =IF(COUNT(J15,Supuestos!$D$11,Supuestos!$D$45)=3,IF(4<Supuestos!$D$45,J15*Supuestos!$D$11,0),"N/D") -> 2767.5 | K16: =IF(COUNT(K15,Supuestos!$D$11,Supuestos!$D$45)=3,IF(5<Supuestos!$D$45,K15*Supuestos!$D$11,0),"N/D") -> 2767.5 | L16: =IF(COUNT(L15,Supuestos!$D$11,Supuestos!$D$45)=3,IF(6<Supuestos!$D$45,L15*Supuestos!$D$11,0),"N/D") -> 2767.5 | M16: =IF(COUNT(M15,Supuestos!$D$11,Supuestos!$D$45)=3,IF(7<Supuestos!$D$45,M15*Supuestos!$D$11,0),"N/D") -> 2767.5 | N16: =IF(COUNT(N15,Supuestos!$D$11,Supuestos!$D$45)=3,IF(8<Supuestos!$D$45,N15*Supuestos!$D$11,0),"N/D") -> 2767.5 | O16: =IF(COUNT(O15,Supuestos!$D$11,Supuestos!$D$45)=3,IF(9<Supuestos!$D$45,O15*Supuestos!$D$11,0),"N/D") -> 2767.5 | P16: =IF(COUNT(P15,Supuestos!$D$11,Supuestos!$D$45)=3,IF(10<Supuestos!$D$45,P15*Supuestos!$D$11,0),"N/D") -> 2767.5 | Q16: =IF(COUNT(Q15,Supuestos!$D$11,Supuestos!$D$45)=3,IF(11<Supuestos!$D$45,Q15*Supuestos!$D$11,0),"N/D") -> 2767.5
C17: Visitas requeridas / panel elegible | D17: ratio panel | F17: =IF(COUNT(F13,F16)=2,IF(F16>0,F13/F16,"N/D"),"N/D") -> 0.22884673 | G17: =IF(COUNT(G13,G16)=2,IF(G16>0,G13/G16,"N/D"),"N/D") -> 0.22884673 | H17: =IF(COUNT(H13,H16)=2,IF(H16>0,H13/H16,"N/D"),"N/D") -> 0.22884673 | I17: =IF(COUNT(I13,I16)=2,IF(I16>0,I13/I16,"N/D"),"N/D") -> 0.22884673 | J17: =IF(COUNT(J13,J16)=2,IF(J16>0,J13/J16,"N/D"),"N/D") -> 0.22884673 | K17: =IF(COUNT(K13,K16)=2,IF(K16>0,K13/K16,"N/D"),"N/D") -> 0.22884673 | L17: =IF(COUNT(L13,L16)=2,IF(L16>0,L13/L16,"N/D"),"N/D") -> 0.22884673 | M17: =IF(COUNT(M13,M16)=2,IF(M16>0,M13/M16,"N/D"),"N/D") -> 0.22884673 | ... Q17: =IF(COUNT(Q13,Q16)=2,IF(Q16>0,Q13/Q16,"N/D"),"N/D") -> 0.22884673
C19: Saldo externo medio requerido | D19: USD eq. | F19: =Cohortes!L63 -> 7795.9928 | G19: =Cohortes!M63 -> 20814.038 | H19: =Cohortes!N63 -> 34499.437 | I19: =Cohortes!O63 -> 46610.958 | J19: =Cohortes!P63 -> 58785.484 | K19: =Cohortes!Q63 -> 70296.657 | L19: =Cohortes!R63 -> 82049.858 | M19: =Cohortes!S63 -> 93385.928 | ... Q19: =Cohortes!W63 -> 137807.3
C20: Saldo externo al cierre requerido | D20: USD eq. | F20: =Cohortes!L43 -> 14024.111 | G20: =Cohortes!M43 -> 27447.875 | H20: =Cohortes!N43 -> 39983.125 | I20: =Cohortes!O43 -> 52110.139 | J20: =Cohortes!P43 -> 63892.954 | K20: =Cohortes!Q43 -> 75571.708 | L20: =Cohortes!R43 -> 86960.133 | M20: =Cohortes!S43 -> 98243.848 | ... Q20: =Cohortes!W43 -> 142419.88
C22: Valor neto bancario condicionado | D22: USD | F22: =IF(COUNT(Supuestos!$D$45)=1,IF(0>=Supuestos!$D$45,0,IF(AND(Supuestos!$D$16="Sí",Supuestos!$D$52="Saldo medio externo",COUNT(Supuestos!$D$17,F19)=2),F19*Supuestos!$D$17/12,"N/D")),"N/D") -> N/D | G22: =IF(COUNT(Supuestos!$D$45)=1,IF(1>=Supuestos!$D$45,0,IF(AND(Supuestos!$D$16="Sí",Supuestos!$D$52="Saldo medio externo",COUNT(Supuestos!$D$17,G19)=2),G19*Supuestos!$D$17/12,"N/D")),"N/D") -> N/D | H22: =IF(COUNT(Supuestos!$D$45)=1,IF(2>=Supuestos!$D$45,0,IF(AND(Supuestos!$D$16="Sí",Supuestos!$D$52="Saldo medio externo",COUNT(Supuestos!$D$17,H19)=2),H19*Supuestos!$D$17/12,"N/D")),"N/D") -> N/D | I22: =IF(COUNT(Supuestos!$D$45)=1,IF(3>=Supuestos!$D$45,0,IF(AND(Supuestos!$D$16="Sí",Supuestos!$D$52="Saldo medio externo",COUNT(Supuestos!$D$17,I19)=2),I19*Supuestos!$D$17/12,"N/D")),"N/D") -> N/D | J22: =IF(COUNT(Supuestos!$D$45)=1,IF(4>=Supuestos!$D$45,0,IF(AND(Supuestos!$D$16="Sí",Supuestos!$D$52="Saldo medio externo",COUNT(Supuestos!$D$17,J19)=2),J19*Supuestos!$D$17/12,"N/D")),"N/D") -> N/D | K22: =IF(COUNT(Supuestos!$D$45)=1,IF(5>=Supuestos!$D$45,0,IF(AND(Supuestos!$D$16="Sí",Supuestos!$D$52="Saldo medio externo",COUNT(Supuestos!$D$17,K19)=2),K19*Supuestos!$D$17/12,"N/D")),"N/D") -> N/D | L22: =IF(COUNT(Supuestos!$D$45)=1,IF(6>=Supuestos!$D$45,0,IF(AND(Supuestos!$D$16="Sí",Supuestos!$D$52="Saldo medio externo",COUNT(Supuestos!$D$17,L19)=2),L19*Supuestos!$D$17/12,"N/D")),"N/D") -> N/D | M22: =IF(COUNT(Supuestos!$D$45)=1,IF(7>=Supuestos!$D$45,0,IF(AND(Supuestos!$D$16="Sí",Supuestos!$D$52="Saldo medio externo",COUNT(Supuestos!$D$17,M19)=2),M19*Supuestos!$D$17/12,"N/D")),"N/D") -> N/D | N22: =IF(COUNT(Supuestos!$D$45)=1,IF(8>=Supuestos!$D$45,0,IF(AND(Supuestos!$D$16="Sí",Supuestos!$D$52="Saldo medio externo",COUNT(Supuestos!$D$17,N19)=2),N19*Supuestos!$D$17/12,"N/D")),"N/D") -> N/D | O22: =IF(COUNT(Supuestos!$D$45)=1,IF(9>=Supuestos!$D$45,0,IF(AND(Supuestos!$D$16="Sí",Supuestos!$D$52="Saldo medio externo",COUNT(Supuestos!$D$17,O19)=2),O19*Supuestos!$D$17/12,"N/D")),"N/D") -> N/D | P22: =IF(COUNT(Supuestos!$D$45)=1,IF(10>=Supuestos!$D$45,0,IF(AND(Supuestos!$D$16="Sí",Supuestos!$D$52="Saldo medio externo",COUNT(Supuestos!$D$17,P19)=2),P19*Supuestos!$D$17/12,"N/D")),"N/D") -> N/D | Q22: =IF(COUNT(Supuestos!$D$45)=1,IF(11>=Supuestos!$D$45,0,IF(AND(Supuestos!$D$16="Sí",Supuestos!$D$52="Saldo medio externo",COUNT(Supuestos!$D$17,Q19)=2),Q19*Supuestos!$D$17/12,"N/D")),"N/D") -> N/D
C23: Inversión cliente pendiente | D23: USD | F23: =IF(COUNT(Supuestos!$D$45)=1,IF(0>=Supuestos!$D$45,0,IF(COUNT(Supuestos!F32)=1,IF(Supuestos!F32>=0,Supuestos!F32,"N/D"),"N/D")),"N/D") -> N/D | G23: =IF(COUNT(Supuestos!$D$45)=1,IF(1>=Supuestos!$D$45,0,IF(COUNT(Supuestos!G32)=1,IF(Supuestos!G32>=0,Supuestos!G32,"N/D"),"N/D")),"N/D") -> N/D | H23: =IF(COUNT(Supuestos!$D$45)=1,IF(2>=Supuestos!$D$45,0,IF(COUNT(Supuestos!H32)=1,IF(Supuestos!H32>=0,Supuestos!H32,"N/D"),"N/D")),"N/D") -> N/D | I23: =IF(COUNT(Supuestos!$D$45)=1,IF(3>=Supuestos!$D$45,0,IF(COUNT(Supuestos!I32)=1,IF(Supuestos!I32>=0,Supuestos!I32,"N/D"),"N/D")),"N/D") -> N/D | J23: =IF(COUNT(Supuestos!$D$45)=1,IF(4>=Supuestos!$D$45,0,IF(COUNT(Supuestos!J32)=1,IF(Supuestos!J32>=0,Supuestos!J32,"N/D"),"N/D")),"N/D") -> N/D | K23: =IF(COUNT(Supuestos!$D$45)=1,IF(5>=Supuestos!$D$45,0,IF(COUNT(Supuestos!K32)=1,IF(Supuestos!K32>=0,Supuestos!K32,"N/D"),"N/D")),"N/D") -> N/D | L23: =IF(COUNT(Supuestos!$D$45)=1,IF(6>=Supuestos!$D$45,0,IF(COUNT(Supuestos!L32)=1,IF(Supuestos!L32>=0,Supuestos!L32,"N/D"),"N/D")),"N/D") -> N/D | M23: =IF(COUNT(Supuestos!$D$45)=1,IF(7>=Supuestos!$D$45,0,IF(COUNT(Supuestos!M32)=1,IF(Supuestos!M32>=0,Supuestos!M32,"N/D"),"N/D")),"N/D") -> N/D | N23: =IF(COUNT(Supuestos!$D$45)=1,IF(8>=Supuestos!$D$45,0,IF(COUNT(Supuestos!N32)=1,IF(Supuestos!N32>=0,Supuestos!N32,"N/D"),"N/D")),"N/D") -> N/D | O23: =IF(COUNT(Supuestos!$D$45)=1,IF(9>=Supuestos!$D$45,0,IF(COUNT(Supuestos!O32)=1,IF(Supuestos!O32>=0,Supuestos!O32,"N/D"),"N/D")),"N/D") -> N/D | P23: =IF(COUNT(Supuestos!$D$45)=1,IF(10>=Supuestos!$D$45,0,IF(COUNT(Supuestos!P32)=1,IF(Supuestos!P32>=0,Supuestos!P32,"N/D"),"N/D")),"N/D") -> N/D | Q23: =IF(COUNT(Supuestos!$D$45)=1,IF(11>=Supuestos!$D$45,0,IF(COUNT(Supuestos!Q32)=1,IF(Supuestos!Q32>=0,Supuestos!Q32,"N/D"),"N/D")),"N/D") -> N/D
C24: Valor acumulado condicionado | D24: USD | F24: =IF(COUNT($F$22:F22)=1,SUM($F$22:F22),"N/D") -> N/D | G24: =IF(COUNT($F$22:G22)=2,SUM($F$22:G22),"N/D") -> N/D | H24: =IF(COUNT($F$22:H22)=3,SUM($F$22:H22),"N/D") -> N/D | I24: =IF(COUNT($F$22:I22)=4,SUM($F$22:I22),"N/D") -> N/D | J24: =IF(COUNT($F$22:J22)=5,SUM($F$22:J22),"N/D") -> N/D | K24: =IF(COUNT($F$22:K22)=6,SUM($F$22:K22),"N/D") -> N/D | L24: =IF(COUNT($F$22:L22)=7,SUM($F$22:L22),"N/D") -> N/D | M24: =IF(COUNT($F$22:M22)=8,SUM($F$22:M22),"N/D") -> N/D | N24: =IF(COUNT($F$22:N22)=9,SUM($F$22:N22),"N/D") -> N/D | O24: =IF(COUNT($F$22:O22)=10,SUM($F$22:O22),"N/D") -> N/D | P24: =IF(COUNT($F$22:P22)=11,SUM($F$22:P22),"N/D") -> N/D | Q24: =IF(COUNT($F$22:Q22)=12,SUM($F$22:Q22),"N/D") -> N/D
C25: Inversión acumulada | D25: USD | F25: =IF(COUNT($F$23:F23)=1,SUM($F$23:F23),"N/D") -> N/D | G25: =IF(COUNT($F$23:G23)=2,SUM($F$23:G23),"N/D") -> N/D | H25: =IF(COUNT($F$23:H23)=3,SUM($F$23:H23),"N/D") -> N/D | I25: =IF(COUNT($F$23:I23)=4,SUM($F$23:I23),"N/D") -> N/D | J25: =IF(COUNT($F$23:J23)=5,SUM($F$23:J23),"N/D") -> N/D | K25: =IF(COUNT($F$23:K23)=6,SUM($F$23:K23),"N/D") -> N/D | L25: =IF(COUNT($F$23:L23)=7,SUM($F$23:L23),"N/D") -> N/D | M25: =IF(COUNT($F$23:M23)=8,SUM($F$23:M23),"N/D") -> N/D | N25: =IF(COUNT($F$23:N23)=9,SUM($F$23:N23),"N/D") -> N/D | O25: =IF(COUNT($F$23:O23)=10,SUM($F$23:O23),"N/D") -> N/D | P25: =IF(COUNT($F$23:P23)=11,SUM($F$23:P23),"N/D") -> N/D | Q25: =IF(COUNT($F$23:Q23)=12,SUM($F$23:Q23),"N/D") -> N/D
C26: ROI condicional a logro de la banda | D26: % | F26: =IF(AND(Supuestos!$D$16="Sí",Supuestos!$D$19="Sí",COUNT(F24,F25)=2,F25>0),(F24-F25)/F25,"N/D") -> N/D | G26: =IF(AND(Supuestos!$D$16="Sí",Supuestos!$D$19="Sí",COUNT(G24,G25)=2,G25>0),(G24-G25)/G25,"N/D") -> N/D | H26: =IF(AND(Supuestos!$D$16="Sí",Supuestos!$D$19="Sí",COUNT(H24,H25)=2,H25>0),(H24-H25)/H25,"N/D") -> N/D | I26: =IF(AND(Supuestos!$D$16="Sí",Supuestos!$D$19="Sí",COUNT(I24,I25)=2,I25>0),(I24-I25)/I25,"N/D") -> N/D | J26: =IF(AND(Supuestos!$D$16="Sí",Supuestos!$D$19="Sí",COUNT(J24,J25)=2,J25>0),(J24-J25)/J25,"N/D") -> N/D | K26: =IF(AND(Supuestos!$D$16="Sí",Supuestos!$D$19="Sí",COUNT(K24,K25)=2,K25>0),(K24-K25)/K25,"N/D") -> N/D | L26: =IF(AND(Supuestos!$D$16="Sí",Supuestos!$D$19="Sí",COUNT(L24,L25)=2,L25>0),(L24-L25)/L25,"N/D") -> N/D | M26: =IF(AND(Supuestos!$D$16="Sí",Supuestos!$D$19="Sí",COUNT(M24,M25)=2,M25>0),(M24-M25)/M25,"N/D") -> N/D | ... Q26: =IF(AND(Supuestos!$D$16="Sí",Supuestos!$D$19="Sí",COUNT(Q24,Q25)=2,Q25>0),(Q24-Q25)/Q25,"N/D") -> N/D
C27: Recuperación alcanzada (condicional) | D27: 0/1 | F27: =IF(COUNT(F26)=1,IF(F26>=0,1,0),"N/D") -> N/D | G27: =IF(COUNT(G26)=1,IF(G26>=0,1,0),"N/D") -> N/D | H27: =IF(COUNT(H26)=1,IF(H26>=0,1,0),"N/D") -> N/D | I27: =IF(COUNT(I26)=1,IF(I26>=0,1,0),"N/D") -> N/D | J27: =IF(COUNT(J26)=1,IF(J26>=0,1,0),"N/D") -> N/D | K27: =IF(COUNT(K26)=1,IF(K26>=0,1,0),"N/D") -> N/D | L27: =IF(COUNT(L26)=1,IF(L26>=0,1,0),"N/D") -> N/D | M27: =IF(COUNT(M26)=1,IF(M26>=0,1,0),"N/D") -> N/D | ... Q27: =IF(COUNT(Q26)=1,IF(Q26>=0,1,0),"N/D") -> N/D
C30: Un ratio >100% significa que este panel no alcanza para el requisito bajo esos supuestos; no demuestra inviabilidad del mercado.
C31: El denominador es una canasta parcial de consultas, con overlap residual. No son personas únicas, TAM ni visitas Pibank.
C32: Marca, educación, activación y retención tienen recorridos distintos; sus retornos permanecen N/D sin baseline y deduplicación.
C33: Toda valoración/ROI es condicional al logro de la banda. No transforma requisitos en forecast ni atribuye todo al SEO/AEO.

Sheet Cohortes
C2: Saldo externo y valor dentro del horizonte 2027
C6: Primer fondeo | D6: Cuentas requeridas | E6: Ticket USD eq. | F6: Origen externo | G6: Ret30 | H6: Ret60 | I6: Ret90 | J6: Ret180 | K6: Ret365 | L6: M1 | M6: M2 | N6: M3 | O6: M4 | P6: M5 | Q6: M6 | R6: M7 | S6: M8 | T6: M9 | U6: M10 | V6: M11 | W6: M12
L7: =Supuestos!F31 -> 46388 | M7: =Supuestos!G31 -> 46419 | N7: =Supuestos!H31 -> 46447 | O7: =Supuestos!I31 -> 46478 | P7: =Supuestos!J31 -> 46508 | Q7: =Supuestos!K31 -> 46539 | R7: =Supuestos!L31 -> 46569 | S7: =Supuestos!M31 -> 46600 | ... W7: =Supuestos!Q31 -> 46722
C9: =IF(COUNT(Supuestos!F31,Supuestos!$D$14,Supuestos!$D$36)=3,MAX(Supuestos!$D$36,DATE(YEAR(Supuestos!F31),MONTH(Supuestos!F31),Supuestos!$D$14)),"N/D") -> 46402 | D9: =Requisitos!F11 -> 8.2333333 | E9: =Supuestos!$D$8 -> 2500 | F9: =IF(COUNT(Supuestos!F44)=1,Supuestos!F44,"N/D") -> 0.7 | G9: =IF(COUNT(Supuestos!$D$37)=1,Supuestos!$D$37,"N/D") -> 0.95 | H9: =IF(COUNT(Supuestos!$D$38)=1,Supuestos!$D$38,"N/D") -> 0.9 | I9: =IF(COUNT(Supuestos!$D$39)=1,Supuestos!$D$39,"N/D") -> 0.85 | J9: =IF(COUNT(Supuestos!$D$40)=1,Supuestos!$D$40,"N/D") -> 0.8 | K9: =IF(COUNT(Supuestos!$D$41)=1,Supuestos!$D$41,"N/D") -> 0.75 | L9: =IF(COUNT($D9,$E9,L95)=3,$D9*$E9*L95,"N/D") -> 20034.444 | M9: =IF(COUNT($D9,$E9,M95)=3,$D9*$E9*M95,"N/D") -> 19073.889 | N9: =IF(COUNT($D9,$E9,N95)=3,$D9*$E9*N95,"N/D") -> 18010.417 | O9: =IF(COUNT($D9,$E9,O95)=3,$D9*$E9*O95,"N/D") -> 17324.306 | P9: =IF(COUNT($D9,$E9,P95)=3,$D9*$E9*P95,"N/D") -> 16969.815 | Q9: =IF(COUNT($D9,$E9,Q95)=3,$D9*$E9*Q95,"N/D") -> 16626.759 | R9: =IF(COUNT($D9,$E9,R95)=3,$D9*$E9*R95,"N/D") -> 16372.095 | S9: =IF(COUNT($D9,$E9,S95)=3,$D9*$E9*S95,"N/D") -> 16199.64 | ... W9: =IF(COUNT($D9,$E9,W95)=3,$D9*$E9*W95,"N/D") -> 15520.946
C10: =IF(COUNT(Supuestos!G31,Supuestos!$D$14,Supuestos!$D$36)=3,MAX(Supuestos!$D$36,DATE(YEAR(Supuestos!G31),MONTH(Supuestos!G31),Supuestos!$D$14)),"N/D") -> 46433 | D10: =Requisitos!G11 -> 8.2333333 | E10: =Supuestos!$D$8 -> 2500 | F10: =IF(COUNT(Supuestos!G44)=1,Supuestos!G44,"N/D") -> 0.7 | G10: =IF(COUNT(Supuestos!$D$37)=1,Supuestos!$D$37,"N/D") -> 0.95 | H10: =IF(COUNT(Supuestos!$D$38)=1,Supuestos!$D$38,"N/D") -> 0.9 | I10: =IF(COUNT(Supuestos!$D$39)=1,Supuestos!$D$39,"N/D") -> 0.85 | J10: =IF(COUNT(Supuestos!$D$40)=1,Supuestos!$D$40,"N/D") -> 0.8 | K10: =IF(COUNT(Supuestos!$D$41)=1,Supuestos!$D$41,"N/D") -> 0.75 | L10: =IF(COUNT($D10,$E10,L96)=3,$D10*$E10*L96,"N/D") -> 0 | M10: =IF(COUNT($D10,$E10,M96)=3,$D10*$E10*M96,"N/D") -> 20137.361 | N10: =IF(COUNT($D10,$E10,N96)=3,$D10*$E10*N96,"N/D") -> 19073.889 | O10: =IF(COUNT($D10,$E10,O96)=3,$D10*$E10*O96,"N/D") -> 18044.722 | P10: =IF(COUNT($D10,$E10,P96)=3,$D10*$E10*P96,"N/D") -> 17324.306 | Q10: =IF(COUNT($D10,$E10,Q96)=3,$D10*$E10*Q96,"N/D") -> 16981.25 | R10: =IF(COUNT($D10,$E10,R96)=3,$D10*$E10*R96,"N/D") -> 16626.759 | S10: =IF(COUNT($D10,$E10,S96)=3,$D10*$E10*S96,"N/D") -> 16372.095 | ... W10: =IF(COUNT($D10,$E10,W96)=3,$D10*$E10*W96,"N/D") -> 15693.401
C11: =IF(COUNT(Supuestos!H31,Supuestos!$D$14,Supuestos!$D$36)=3,MAX(Supuestos!$D$36,DATE(YEAR(Supuestos!H31),MONTH(Supuestos!H31),Supuestos!$D$14)),"N/D") -> 46461 | D11: =Requisitos!H11 -> 8.2333333 | E11: =Supuestos!$D$8 -> 2500 | F11: =IF(COUNT(Supuestos!H44)=1,Supuestos!H44,"N/D") -> 0.7 | G11: =IF(COUNT(Supuestos!$D$37)=1,Supuestos!$D$37,"N/D") -> 0.95 | H11: =IF(COUNT(Supuestos!$D$38)=1,Supuestos!$D$38,"N/D") -> 0.9 | I11: =IF(COUNT(Supuestos!$D$39)=1,Supuestos!$D$39,"N/D") -> 0.85 | J11: =IF(COUNT(Supuestos!$D$40)=1,Supuestos!$D$40,"N/D") -> 0.8 | K11: =IF(COUNT(Supuestos!$D$41)=1,Supuestos!$D$41,"N/D") -> 0.75 | L11: =IF(COUNT($D11,$E11,L97)=3,$D11*$E11*L97,"N/D") -> 0 | M11: =IF(COUNT($D11,$E11,M97)=3,$D11*$E11*M97,"N/D") -> 0 | N11: =IF(COUNT($D11,$E11,N97)=3,$D11*$E11*N97,"N/D") -> 20034.444 | O11: =IF(COUNT($D11,$E11,O97)=3,$D11*$E11*O97,"N/D") -> 19005.278 | P11: =IF(COUNT($D11,$E11,P97)=3,$D11*$E11*P97,"N/D") -> 17941.806 | Q11: =IF(COUNT($D11,$E11,Q97)=3,$D11*$E11*Q97,"N/D") -> 17301.435 | R11: =IF(COUNT($D11,$E11,R97)=3,$D11*$E11*R97,"N/D") -> 16946.944 | S11: =IF(COUNT($D11,$E11,S97)=3,$D11*$E11*S97,"N/D") -> 16592.454 | ... W11: =IF(COUNT($D11,$E11,W97)=3,$D11*$E11*W97,"N/D") -> 15849.167
C12: =IF(COUNT(Supuestos!I31,Supuestos!$D$14,Supuestos!$D$36)=3,MAX(Supuestos!$D$36,DATE(YEAR(Supuestos!I31),MONTH(Supuestos!I31),Supuestos!$D$14)),"N/D") -> 46492 | D12: =Requisitos!I11 -> 8.2333333 | E12: =Supuestos!$D$8 -> 2500 | F12: =IF(COUNT(Supuestos!I44)=1,Supuestos!I44,"N/D") -> 0.7 | G12: =IF(COUNT(Supuestos!$D$37)=1,Supuestos!$D$37,"N/D") -> 0.95 | H12: =IF(COUNT(Supuestos!$D$38)=1,Supuestos!$D$38,"N/D") -> 0.9 | I12: =IF(COUNT(Supuestos!$D$39)=1,Supuestos!$D$39,"N/D") -> 0.85 | J12: =IF(COUNT(Supuestos!$D$40)=1,Supuestos!$D$40,"N/D") -> 0.8 | K12: =IF(COUNT(Supuestos!$D$41)=1,Supuestos!$D$41,"N/D") -> 0.75 | L12: =IF(COUNT($D12,$E12,L98)=3,$D12*$E12*L98,"N/D") -> 0 | M12: =IF(COUNT($D12,$E12,M98)=3,$D12*$E12*M98,"N/D") -> 0 | N12: =IF(COUNT($D12,$E12,N98)=3,$D12*$E12*N98,"N/D") -> 0 | O12: =IF(COUNT($D12,$E12,O98)=3,$D12*$E12*O98,"N/D") -> 20068.75 | P12: =IF(COUNT($D12,$E12,P98)=3,$D12*$E12*P98,"N/D") -> 19005.278 | Q12: =IF(COUNT($D12,$E12,Q98)=3,$D12*$E12*Q98,"N/D") -> 17976.111 | R12: =IF(COUNT($D12,$E12,R98)=3,$D12*$E12*R98,"N/D") -> 17301.435 | S12: =IF(COUNT($D12,$E12,S98)=3,$D12*$E12*S98,"N/D") -> 16946.944 | ... W12: =IF(COUNT($D12,$E12,W98)=3,$D12*$E12*W98,"N/D") -> 16021.622
C13: =IF(COUNT(Supuestos!J31,Supuestos!$D$14,Supuestos!$D$36)=3,MAX(Supuestos!$D$36,DATE(YEAR(Supuestos!J31),MONTH(Supuestos!J31),Supuestos!$D$14)),"N/D") -> 46522 | D13: =Requisitos!J11 -> 8.2333333 | E13: =Supuestos!$D$8 -> 2500 | F13: =IF(COUNT(Supuestos!J44)=1,Supuestos!J44,"N/D") -> 0.7 | G13: =IF(COUNT(Supuestos!$D$37)=1,Supuestos!$D$37,"N/D") -> 0.95 | H13: =IF(COUNT(Supuestos!$D$38)=1,Supuestos!$D$38,"N/D") -> 0.9 | I13: =IF(COUNT(Supuestos!$D$39)=1,Supuestos!$D$39,"N/D") -> 0.85 | J13: =IF(COUNT(Supuestos!$D$40)=1,Supuestos!$D$40,"N/D") -> 0.8 | K13: =IF(COUNT(Supuestos!$D$41)=1,Supuestos!$D$41,"N/D") -> 0.75 | L13: =IF(COUNT($D13,$E13,L99)=3,$D13*$E13*L99,"N/D") -> 0 | M13: =IF(COUNT($D13,$E13,M99)=3,$D13*$E13*M99,"N/D") -> 0 | N13: =IF(COUNT($D13,$E13,N99)=3,$D13*$E13*N99,"N/D") -> 0 | O13: =IF(COUNT($D13,$E13,O99)=3,$D13*$E13*O99,"N/D") -> 0 | P13: =IF(COUNT($D13,$E13,P99)=3,$D13*$E13*P99,"N/D") -> 20034.444 | Q13: =IF(COUNT($D13,$E13,Q99)=3,$D13*$E13*Q99,"N/D") -> 19005.278 | R13: =IF(COUNT($D13,$E13,R99)=3,$D13*$E13*R99,"N/D") -> 17941.806 | S13: =IF(COUNT($D13,$E13,S99)=3,$D13*$E13*S99,"N/D") -> 17290 | ... W13: =IF(COUNT($D13,$E13,W99)=3,$D13*$E13*W99,"N/D") -> 16188.514
C14: =IF(COUNT(Supuestos!K31,Supuestos!$D$14,Supuestos!$D$36)=3,MAX(Supuestos!$D$36,DATE(YEAR(Supuestos!K31),MONTH(Supuestos!K31),Supuestos!$D$14)),"N/D") -> 46553 | D14: =Requisitos!K11 -> 8.2333333 | E14: =Supuestos!$D$8 -> 2500 | F14: =IF(COUNT(Supuestos!K44)=1,Supuestos!K44,"N/D") -> 0.7 | G14: =IF(COUNT(Supuestos!$D$37)=1,Supuestos!$D$37,"N/D") -> 0.95 | H14: =IF(COUNT(Supuestos!$D$38)=1,Supuestos!$D$38,"N/D") -> 0.9 | I14: =IF(COUNT(Supuestos!$D$39)=1,Supuestos!$D$39,"N/D") -> 0.85 | J14: =IF(COUNT(Supuestos!$D$40)=1,Supuestos!$D$40,"N/D") -> 0.8 | K14: =IF(COUNT(Supuestos!$D$41)=1,Supuestos!$D$41,"N/D") -> 0.75 | L14: =IF(COUNT($D14,$E14,L100)=3,$D14*$E14*L100,"N/D") -> 0 | M14: =IF(COUNT($D14,$E14,M100)=3,$D14*$E14*M100,"N/D") -> 0 | N14: =IF(COUNT($D14,$E14,N100)=3,$D14*$E14*N100,"N/D") -> 0 | O14: =IF(COUNT($D14,$E14,O100)=3,$D14*$E14*O100,"N/D") -> 0 | P14: =IF(COUNT($D14,$E14,P100)=3,$D14*$E14*P100,"N/D") -> 0 | Q14: =IF(COUNT($D14,$E14,Q100)=3,$D14*$E14*Q100,"N/D") -> 20068.75 | R14: =IF(COUNT($D14,$E14,R100)=3,$D14*$E14*R100,"N/D") -> 19005.278 | S14: =IF(COUNT($D14,$E14,S100)=3,$D14*$E14*S100,"N/D") -> 17941.806 | ... W14: =IF(COUNT($D14,$E14,W100)=3,$D14*$E14*W100,"N/D") -> 16360.968
C15: =IF(COUNT(Supuestos!L31,Supuestos!$D$14,Supuestos!$D$36)=3,MAX(Supuestos!$D$36,DATE(YEAR(Supuestos!L31),MONTH(Supuestos!L31),Supuestos!$D$14)),"N/D") -> 46583 | D15: =Requisitos!L11 -> 8.2333333 | E15: =Supuestos!$D$8 -> 2500 | F15: =IF(COUNT(Supuestos!L44)=1,Supuestos!L44,"N/D") -> 0.7 | G15: =IF(COUNT(Supuestos!$D$37)=1,Supuestos!$D$37,"N/D") -> 0.95 | H15: =IF(COUNT(Supuestos!$D$38)=1,Supuestos!$D$38,"N/D") -> 0.9 | I15: =IF(COUNT(Supuestos!$D$39)=1,Supuestos!$D$39,"N/D") -> 0.85 | J15: =IF(COUNT(Supuestos!$D$40)=1,Supuestos!$D$40,"N/D") -> 0.8 | K15: =IF(COUNT(Supuestos!$D$41)=1,Supuestos!$D$41,"N/D") -> 0.75 | L15: =IF(COUNT($D15,$E15,L101)=3,$D15*$E15*L101,"N/D") -> 0 | M15: =IF(COUNT($D15,$E15,M101)=3,$D15*$E15*M101,"N/D") -> 0 | N15: =IF(COUNT($D15,$E15,N101)=3,$D15*$E15*N101,"N/D") -> 0 | O15: =IF(COUNT($D15,$E15,O101)=3,$D15*$E15*O101,"N/D") -> 0 | P15: =IF(COUNT($D15,$E15,P101)=3,$D15*$E15*P101,"N/D") -> 0 | Q15: =IF(COUNT($D15,$E15,Q101)=3,$D15*$E15*Q101,"N/D") -> 0 | R15: =IF(COUNT($D15,$E15,R101)=3,$D15*$E15*R101,"N/D") -> 20034.444 | S15: =IF(COUNT($D15,$E15,S101)=3,$D15*$E15*S101,"N/D") -> 18970.972 | ... W15: =IF(COUNT($D15,$E15,W101)=3,$D15*$E15*W101,"N/D") -> 16592.454
C16: =IF(COUNT(Supuestos!M31,Supuestos!$D$14,Supuestos!$D$36)=3,MAX(Supuestos!$D$36,DATE(YEAR(Supuestos!M31),MONTH(Supuestos!M31),Supuestos!$D$14)),"N/D") -> 46614 | D16: =Requisitos!M11 -> 8.2333333 | E16: =Supuestos!$D$8 -> 2500 | F16: =IF(COUNT(Supuestos!M44)=1,Supuestos!M44,"N/D") -> 0.7 | G16: =IF(COUNT(Supuestos!$D$37)=1,Supuestos!$D$37,"N/D") -> 0.95 | H16: =IF(COUNT(Supuestos!$D$38)=1,Supuestos!$D$38,"N/D") -> 0.9 | I16: =IF(COUNT(Supuestos!$D$39)=1,Supuestos!$D$39,"N/D") -> 0.85 | J16: =IF(COUNT(Supuestos!$D$40)=1,Supuestos!$D$40,"N/D") -> 0.8 | K16: =IF(COUNT(Supuestos!$D$41)=1,Supuestos!$D$41,"N/D") -> 0.75 | L16: =IF(COUNT($D16,$E16,L102)=3,$D16*$E16*L102,"N/D") -> 0 | M16: =IF(COUNT($D16,$E16,M102)=3,$D16*$E16*M102,"N/D") -> 0 | N16: =IF(COUNT($D16,$E16,N102)=3,$D16*$E16*N102,"N/D") -> 0 | O16: =IF(COUNT($D16,$E16,O102)=3,$D16*$E16*O102,"N/D") -> 0 | P16: =IF(COUNT($D16,$E16,P102)=3,$D16*$E16*P102,"N/D") -> 0 | Q16: =IF(COUNT($D16,$E16,Q102)=3,$D16*$E16*Q102,"N/D") -> 0 | R16: =IF(COUNT($D16,$E16,R102)=3,$D16*$E16*R102,"N/D") -> 0 | S16: =IF(COUNT($D16,$E16,S102)=3,$D16*$E16*S102,"N/D") -> 20034.444 | ... W16: =IF(COUNT($D16,$E16,W102)=3,$D16*$E16*W102,"N/D") -> 16946.944
C17: =IF(COUNT(Supuestos!N31,Supuestos!$D$14,Supuestos!$D$36)=3,MAX(Supuestos!$D$36,DATE(YEAR(Supuestos!N31),MONTH(Supuestos!N31),Supuestos!$D$14)),"N/D") -> 46645 | D17: =Requisitos!N11 -> 8.2333333 | E17: =Supuestos!$D$8 -> 2500 | F17: =IF(COUNT(Supuestos!N44)=1,Supuestos!N44,"N/D") -> 0.7 | G17: =IF(COUNT(Supuestos!$D$37)=1,Supuestos!$D$37,"N/D") -> 0.95 | H17: =IF(COUNT(Supuestos!$D$38)=1,Supuestos!$D$38,"N/D") -> 0.9 | I17: =IF(COUNT(Supuestos!$D$39)=1,Supuestos!$D$39,"N/D") -> 0.85 | J17: =IF(COUNT(Supuestos!$D$40)=1,Supuestos!$D$40,"N/D") -> 0.8 | K17: =IF(COUNT(Supuestos!$D$41)=1,Supuestos!$D$41,"N/D") -> 0.75 | L17: =IF(COUNT($D17,$E17,L103)=3,$D17*$E17*L103,"N/D") -> 0 | M17: =IF(COUNT($D17,$E17,M103)=3,$D17*$E17*M103,"N/D") -> 0 | N17: =IF(COUNT($D17,$E17,N103)=3,$D17*$E17*N103,"N/D") -> 0 | O17: =IF(COUNT($D17,$E17,O103)=3,$D17*$E17*O103,"N/D") -> 0 | P17: =IF(COUNT($D17,$E17,P103)=3,$D17*$E17*P103,"N/D") -> 0 | Q17: =IF(COUNT($D17,$E17,Q103)=3,$D17*$E17*Q103,"N/D") -> 0 | R17: =IF(COUNT($D17,$E17,R103)=3,$D17*$E17*R103,"N/D") -> 0 | S17: =IF(COUNT($D17,$E17,S103)=3,$D17*$E17*S103,"N/D") -> 0 | ... W17: =IF(COUNT($D17,$E17,W103)=3,$D17*$E17*W103,"N/D") -> 17301.435
C18: =IF(COUNT(Supuestos!O31,Supuestos!$D$14,Supuestos!$D$36)=3,MAX(Supuestos!$D$36,DATE(YEAR(Supuestos!O31),MONTH(Supuestos!O31),Supuestos!$D$14)),"N/D") -> 46675 | D18: =Requisitos!O11 -> 8.2333333 | E18: =Supuestos!$D$8 -> 2500 | F18: =IF(COUNT(Supuestos!O44)=1,Supuestos!O44,"N/D") -> 0.7 | G18: =IF(COUNT(Supuestos!$D$37)=1,Supuestos!$D$37,"N/D") -> 0.95 | H18: =IF(COUNT(Supuestos!$D$38)=1,Supuestos!$D$38,"N/D") -> 0.9 | I18: =IF(COUNT(Supuestos!$D$39)=1,Supuestos!$D$39,"N/D") -> 0.85 | J18: =IF(COUNT(Supuestos!$D$40)=1,Supuestos!$D$40,"N/D") -> 0.8 | K18: =IF(COUNT(Supuestos!$D$41)=1,Supuestos!$D$41,"N/D") -> 0.75 | L18: =IF(COUNT($D18,$E18,L104)=3,$D18*$E18*L104,"N/D") -> 0 | M18: =IF(COUNT($D18,$E18,M104)=3,$D18*$E18*M104,"N/D") -> 0 | N18: =IF(COUNT($D18,$E18,N104)=3,$D18*$E18*N104,"N/D") -> 0 | O18: =IF(COUNT($D18,$E18,O104)=3,$D18*$E18*O104,"N/D") -> 0 | P18: =IF(COUNT($D18,$E18,P104)=3,$D18*$E18*P104,"N/D") -> 0 | Q18: =IF(COUNT($D18,$E18,Q104)=3,$D18*$E18*Q104,"N/D") -> 0 | R18: =IF(COUNT($D18,$E18,R104)=3,$D18*$E18*R104,"N/D") -> 0 | S18: =IF(COUNT($D18,$E18,S104)=3,$D18*$E18*S104,"N/D") -> 0 | ... W18: =IF(COUNT($D18,$E18,W104)=3,$D18*$E18*W104,"N/D") -> 17941.806
C19: =IF(COUNT(Supuestos!P31,Supuestos!$D$14,Supuestos!$D$36)=3,MAX(Supuestos!$D$36,DATE(YEAR(Supuestos!P31),MONTH(Supuestos!P31),Supuestos!$D$14)),"N/D") -> 46706 | D19: =Requisitos!P11 -> 8.2333333 | E19: =Supuestos!$D$8 -> 2500 | F19: =IF(COUNT(Supuestos!P44)=1,Supuestos!P44,"N/D") -> 0.7 | G19: =IF(COUNT(Supuestos!$D$37)=1,Supuestos!$D$37,"N/D") -> 0.95 | H19: =IF(COUNT(Supuestos!$D$38)=1,Supuestos!$D$38,"N/D") -> 0.9 | I19: =IF(COUNT(Supuestos!$D$39)=1,Supuestos!$D$39,"N/D") -> 0.85 | J19: =IF(COUNT(Supuestos!$D$40)=1,Supuestos!$D$40,"N/D") -> 0.8 | K19: =IF(COUNT(Supuestos!$D$41)=1,Supuestos!$D$41,"N/D") -> 0.75 | L19: =IF(COUNT($D19,$E19,L105)=3,$D19*$E19*L105,"N/D") -> 0 | M19: =IF(COUNT($D19,$E19,M105)=3,$D19*$E19*M105,"N/D") -> 0 | N19: =IF(COUNT($D19,$E19,N105)=3,$D19*$E19*N105,"N/D") -> 0 | O19: =IF(COUNT($D19,$E19,O105)=3,$D19*$E19*O105,"N/D") -> 0 | P19: =IF(COUNT($D19,$E19,P105)=3,$D19*$E19*P105,"N/D") -> 0 | Q19: =IF(COUNT($D19,$E19,Q105)=3,$D19*$E19*Q105,"N/D") -> 0 | R19: =IF(COUNT($D19,$E19,R105)=3,$D19*$E19*R105,"N/D") -> 0 | S19: =IF(COUNT($D19,$E19,S105)=3,$D19*$E19*S105,"N/D") -> 0 | ... W19: =IF(COUNT($D19,$E19,W105)=3,$D19*$E19*W105,"N/D") -> 19005.278
C20: =IF(COUNT(Supuestos!Q31,Supuestos!$D$14,Supuestos!$D$36)=3,MAX(Supuestos!$D$36,DATE(YEAR(Supuestos!Q31),MONTH(Supuestos!Q31),Supuestos!$D$14)),"N/D") -> 46736 | D20: =Requisitos!Q11 -> 8.2333333 | E20: =Supuestos!$D$8 -> 2500 | F20: =IF(COUNT(Supuestos!Q44)=1,Supuestos!Q44,"N/D") -> 0.7 | G20: =IF(COUNT(Supuestos!$D$37)=1,Supuestos!$D$37,"N/D") -> 0.95 | H20: =IF(COUNT(Supuestos!$D$38)=1,Supuestos!$D$38,"N/D") -> 0.9 | I20: =IF(COUNT(Supuestos!$D$39)=1,Supuestos!$D$39,"N/D") -> 0.85 | J20: =IF(COUNT(Supuestos!$D$40)=1,Supuestos!$D$40,"N/D") -> 0.8 | K20: =IF(COUNT(Supuestos!$D$41)=1,Supuestos!$D$41,"N/D") -> 0.75 | L20: =IF(COUNT($D20,$E20,L106)=3,$D20*$E20*L106,"N/D") -> 0 | M20: =IF(COUNT($D20,$E20,M106)=3,$D20*$E20*M106,"N/D") -> 0 | N20: =IF(COUNT($D20,$E20,N106)=3,$D20*$E20*N106,"N/D") -> 0 | O20: =IF(COUNT($D20,$E20,O106)=3,$D20*$E20*O106,"N/D") -> 0 | P20: =IF(COUNT($D20,$E20,P106)=3,$D20*$E20*P106,"N/D") -> 0 | Q20: =IF(COUNT($D20,$E20,Q106)=3,$D20*$E20*Q106,"N/D") -> 0 | R20: =IF(COUNT($D20,$E20,R106)=3,$D20*$E20*R106,"N/D") -> 0 | S20: =IF(COUNT($D20,$E20,S106)=3,$D20*$E20*S106,"N/D") -> 0 | ... W20: =IF(COUNT($D20,$E20,W106)=3,$D20*$E20*W106,"N/D") -> 20034.444
C22: Saldo total al cierre | L22: =IF(COUNT(L9:L20)=12,SUM(L9:L20),"N/D") -> 20034.444 | M22: =IF(COUNT(M9:M20)=12,SUM(M9:M20),"N/D") -> 39211.25 | N22: =IF(COUNT(N9:N20)=12,SUM(N9:N20),"N/D") -> 57118.75 | O22: =IF(COUNT(O9:O20)=12,SUM(O9:O20),"N/D") -> 74443.056 | P22: =IF(COUNT(P9:P20)=12,SUM(P9:P20),"N/D") -> 91275.648 | Q22: =IF(COUNT(Q9:Q20)=12,SUM(Q9:Q20),"N/D") -> 107959.58 | R22: =IF(COUNT(R9:R20)=12,SUM(R9:R20),"N/D") -> 124228.76 | S22: =IF(COUNT(S9:S20)=12,SUM(S9:S20),"N/D") -> 140348.35 | ... W22: =IF(COUNT(W9:W20)=12,SUM(W9:W20),"N/D") -> 203456.98
C24: USD equivalentes provisionales. Depósito bruto y saldo son stock, no beneficio. Finanzas valora el saldo medio externo dentro de 2027.
C28: Saldo externo al cierre por cohorte | L28: M1 | M28: M2 | N28: M3 | O28: M4 | P28: M5 | Q28: M6 | R28: M7 | S28: M8 | T28: M9 | U28: M10 | V28: M11 | W28: M12
C30: =C9 -> 46402 | L30: =IF(COUNT(L9,$F9)=2,L9*$F9,"N/D") -> 14024.111 | M30: =IF(COUNT(M9,$F9)=2,M9*$F9,"N/D") -> 13351.722 | N30: =IF(COUNT(N9,$F9)=2,N9*$F9,"N/D") -> 12607.292 | O30: =IF(COUNT(O9,$F9)=2,O9*$F9,"N/D") -> 12127.014 | P30: =IF(COUNT(P9,$F9)=2,P9*$F9,"N/D") -> 11878.87 | Q30: =IF(COUNT(Q9,$F9)=2,Q9*$F9,"N/D") -> 11638.731 | R30: =IF(COUNT(R9,$F9)=2,R9*$F9,"N/D") -> 11460.466 | S30: =IF(COUNT(S9,$F9)=2,S9*$F9,"N/D") -> 11339.748 | ... W30: =IF(COUNT(W9,$F9)=2,W9*$F9,"N/D") -> 10864.662
C31: =C10 -> 46433 | L31: =IF(COUNT(L10,$F10)=2,L10*$F10,"N/D") -> 0 | M31: =IF(COUNT(M10,$F10)=2,M10*$F10,"N/D") -> 14096.153 | N31: =IF(COUNT(N10,$F10)=2,N10*$F10,"N/D") -> 13351.722 | O31: =IF(COUNT(O10,$F10)=2,O10*$F10,"N/D") -> 12631.306 | P31: =IF(COUNT(P10,$F10)=2,P10*$F10,"N/D") -> 12127.014 | Q31: =IF(COUNT(Q10,$F10)=2,Q10*$F10,"N/D") -> 11886.875 | R31: =IF(COUNT(R10,$F10)=2,R10*$F10,"N/D") -> 11638.731 | S31: =IF(COUNT(S10,$F10)=2,S10*$F10,"N/D") -> 11460.466 | ... W31: =IF(COUNT(W10,$F10)=2,W10*$F10,"N/D") -> 10985.381
C32: =C11 -> 46461 | L32: =IF(COUNT(L11,$F11)=2,L11*$F11,"N/D") -> 0 | M32: =IF(COUNT(M11,$F11)=2,M11*$F11,"N/D") -> 0 | N32: =IF(COUNT(N11,$F11)=2,N11*$F11,"N/D") -> 14024.111 | O32: =IF(COUNT(O11,$F11)=2,O11*$F11,"N/D") -> 13303.694 | P32: =IF(COUNT(P11,$F11)=2,P11*$F11,"N/D") -> 12559.264 | Q32: =IF(COUNT(Q11,$F11)=2,Q11*$F11,"N/D") -> 12111.005 | R32: =IF(COUNT(R11,$F11)=2,R11*$F11,"N/D") -> 11862.861 | S32: =IF(COUNT(S11,$F11)=2,S11*$F11,"N/D") -> 11614.718 | ... W32: =IF(COUNT(W11,$F11)=2,W11*$F11,"N/D") -> 11094.417
C33: =C12 -> 46492 | L33: =IF(COUNT(L12,$F12)=2,L12*$F12,"N/D") -> 0 | M33: =IF(COUNT(M12,$F12)=2,M12*$F12,"N/D") -> 0 | N33: =IF(COUNT(N12,$F12)=2,N12*$F12,"N/D") -> 0 | O33: =IF(COUNT(O12,$F12)=2,O12*$F12,"N/D") -> 14048.125 | P33: =IF(COUNT(P12,$F12)=2,P12*$F12,"N/D") -> 13303.694 | Q33: =IF(COUNT(Q12,$F12)=2,Q12*$F12,"N/D") -> 12583.278 | R33: =IF(COUNT(R12,$F12)=2,R12*$F12,"N/D") -> 12111.005 | S33: =IF(COUNT(S12,$F12)=2,S12*$F12,"N/D") -> 11862.861 | ... W33: =IF(COUNT(W12,$F12)=2,W12*$F12,"N/D") -> 11215.135
C34: =C13 -> 46522 | L34: =IF(COUNT(L13,$F13)=2,L13*$F13,"N/D") -> 0 | M34: =IF(COUNT(M13,$F13)=2,M13*$F13,"N/D") -> 0 | N34: =IF(COUNT(N13,$F13)=2,N13*$F13,"N/D") -> 0 | O34: =IF(COUNT(O13,$F13)=2,O13*$F13,"N/D") -> 0 | P34: =IF(COUNT(P13,$F13)=2,P13*$F13,"N/D") -> 14024.111 | Q34: =IF(COUNT(Q13,$F13)=2,Q13*$F13,"N/D") -> 13303.694 | R34: =IF(COUNT(R13,$F13)=2,R13*$F13,"N/D") -> 12559.264 | S34: =IF(COUNT(S13,$F13)=2,S13*$F13,"N/D") -> 12103 | ... W34: =IF(COUNT(W13,$F13)=2,W13*$F13,"N/D") -> 11331.959
C35: =C14 -> 46553 | L35: =IF(COUNT(L14,$F14)=2,L14*$F14,"N/D") -> 0 | M35: =IF(COUNT(M14,$F14)=2,M14*$F14,"N/D") -> 0 | N35: =IF(COUNT(N14,$F14)=2,N14*$F14,"N/D") -> 0 | O35: =IF(COUNT(O14,$F14)=2,O14*$F14,"N/D") -> 0 | P35: =IF(COUNT(P14,$F14)=2,P14*$F14,"N/D") -> 0 | Q35: =IF(COUNT(Q14,$F14)=2,Q14*$F14,"N/D") -> 14048.125 | R35: =IF(COUNT(R14,$F14)=2,R14*$F14,"N/D") -> 13303.694 | S35: =IF(COUNT(S14,$F14)=2,S14*$F14,"N/D") -> 12559.264 | ... W35: =IF(COUNT(W14,$F14)=2,W14*$F14,"N/D") -> 11452.678
C36: =C15 -> 46583 | L36: =IF(COUNT(L15,$F15)=2,L15*$F15,"N/D") -> 0 | M36: =IF(COUNT(M15,$F15)=2,M15*$F15,"N/D") -> 0 | N36: =IF(COUNT(N15,$F15)=2,N15*$F15,"N/D") -> 0 | O36: =IF(COUNT(O15,$F15)=2,O15*$F15,"N/D") -> 0 | P36: =IF(COUNT(P15,$F15)=2,P15*$F15,"N/D") -> 0 | Q36: =IF(COUNT(Q15,$F15)=2,Q15*$F15,"N/D") -> 0 | R36: =IF(COUNT(R15,$F15)=2,R15*$F15,"N/D") -> 14024.111 | S36: =IF(COUNT(S15,$F15)=2,S15*$F15,"N/D") -> 13279.681 | ... W36: =IF(COUNT(W15,$F15)=2,W15*$F15,"N/D") -> 11614.718
C37: =C16 -> 46614 | L37: =IF(COUNT(L16,$F16)=2,L16*$F16,"N/D") -> 0 | M37: =IF(COUNT(M16,$F16)=2,M16*$F16,"N/D") -> 0 | N37: =IF(COUNT(N16,$F16)=2,N16*$F16,"N/D") -> 0 | O37: =IF(COUNT(O16,$F16)=2,O16*$F16,"N/D") -> 0 | P37: =IF(COUNT(P16,$F16)=2,P16*$F16,"N/D") -> 0 | Q37: =IF(COUNT(Q16,$F16)=2,Q16*$F16,"N/D") -> 0 | R37: =IF(COUNT(R16,$F16)=2,R16*$F16,"N/D") -> 0 | S37: =IF(COUNT(S16,$F16)=2,S16*$F16,"N/D") -> 14024.111 | ... W37: =IF(COUNT(W16,$F16)=2,W16*$F16,"N/D") -> 11862.861
C38: =C17 -> 46645 | L38: =IF(COUNT(L17,$F17)=2,L17*$F17,"N/D") -> 0 | M38: =IF(COUNT(M17,$F17)=2,M17*$F17,"N/D") -> 0 | N38: =IF(COUNT(N17,$F17)=2,N17*$F17,"N/D") -> 0 | O38: =IF(COUNT(O17,$F17)=2,O17*$F17,"N/D") -> 0 | P38: =IF(COUNT(P17,$F17)=2,P17*$F17,"N/D") -> 0 | Q38: =IF(COUNT(Q17,$F17)=2,Q17*$F17,"N/D") -> 0 | R38: =IF(COUNT(R17,$F17)=2,R17*$F17,"N/D") -> 0 | S38: =IF(COUNT(S17,$F17)=2,S17*$F17,"N/D") -> 0 | ... W38: =IF(COUNT(W17,$F17)=2,W17*$F17,"N/D") -> 12111.005
C39: =C18 -> 46675 | L39: =IF(COUNT(L18,$F18)=2,L18*$F18,"N/D") -> 0 | M39: =IF(COUNT(M18,$F18)=2,M18*$F18,"N/D") -> 0 | N39: =IF(COUNT(N18,$F18)=2,N18*$F18,"N/D") -> 0 | O39: =IF(COUNT(O18,$F18)=2,O18*$F18,"N/D") -> 0 | P39: =IF(COUNT(P18,$F18)=2,P18*$F18,"N/D") -> 0 | Q39: =IF(COUNT(Q18,$F18)=2,Q18*$F18,"N/D") -> 0 | R39: =IF(COUNT(R18,$F18)=2,R18*$F18,"N/D") -> 0 | S39: =IF(COUNT(S18,$F18)=2,S18*$F18,"N/D") -> 0 | ... W39: =IF(COUNT(W18,$F18)=2,W18*$F18,"N/D") -> 12559.264
C40: =C19 -> 46706 | L40: =IF(COUNT(L19,$F19)=2,L19*$F19,"N/D") -> 0 | M40: =IF(COUNT(M19,$F19)=2,M19*$F19,"N/D") -> 0 | N40: =IF(COUNT(N19,$F19)=2,N19*$F19,"N/D") -> 0 | O40: =IF(COUNT(O19,$F19)=2,O19*$F19,"N/D") -> 0 | P40: =IF(COUNT(P19,$F19)=2,P19*$F19,"N/D") -> 0 | Q40: =IF(COUNT(Q19,$F19)=2,Q19*$F19,"N/D") -> 0 | R40: =IF(COUNT(R19,$F19)=2,R19*$F19,"N/D") -> 0 | S40: =IF(COUNT(S19,$F19)=2,S19*$F19,"N/D") -> 0 | ... W40: =IF(COUNT(W19,$F19)=2,W19*$F19,"N/D") -> 13303.694
C41: =C20 -> 46736 | L41: =IF(COUNT(L20,$F20)=2,L20*$F20,"N/D") -> 0 | M41: =IF(COUNT(M20,$F20)=2,M20*$F20,"N/D") -> 0 | N41: =IF(COUNT(N20,$F20)=2,N20*$F20,"N/D") -> 0 | O41: =IF(COUNT(O20,$F20)=2,O20*$F20,"N/D") -> 0 | P41: =IF(COUNT(P20,$F20)=2,P20*$F20,"N/D") -> 0 | Q41: =IF(COUNT(Q20,$F20)=2,Q20*$F20,"N/D") -> 0 | R41: =IF(COUNT(R20,$F20)=2,R20*$F20,"N/D") -> 0 | S41: =IF(COUNT(S20,$F20)=2,S20*$F20,"N/D") -> 0 | ... W41: =IF(COUNT(W20,$F20)=2,W20*$F20,"N/D") -> 14024.111
C43: Saldo externo al cierre | L43: =IF(COUNT(L30:L41)=12,SUM(L30:L41),"N/D") -> 14024.111 | M43: =IF(COUNT(M30:M41)=12,SUM(M30:M41),"N/D") -> 27447.875 | N43: =IF(COUNT(N30:N41)=12,SUM(N30:N41),"N/D") -> 39983.125 | O43: =IF(COUNT(O30:O41)=12,SUM(O30:O41),"N/D") -> 52110.139 | P43: =IF(COUNT(P30:P41)=12,SUM(P30:P41),"N/D") -> 63892.954 | Q43: =IF(COUNT(Q30:Q41)=12,SUM(Q30:Q41),"N/D") -> 75571.708 | R43: =IF(COUNT(R30:R41)=12,SUM(R30:R41),"N/D") -> 86960.133 | S43: =IF(COUNT(S30:S41)=12,SUM(S30:S41),"N/D") -> 98243.848 | ... W43: =IF(COUNT(W30:W41)=12,SUM(W30:W41),"N/D") -> 142419.88
C48: Saldo medio externo mensual por cohorte | L48: M1 | M48: M2 | N48: M3 | O48: M4 | P48: M5 | Q48: M6 | R48: M7 | S48: M8 | T48: M9 | U48: M10 | V48: M11 | W48: M12
C50: =C9 -> 46402 | L50: =IF(COUNT($D9,$E9,$F9,L9,0,Supuestos!$D$45)=6,IF(0>=Supuestos!$D$45,0,IF($C9>EOMONTH(L$7,0),0,IF($C9>=DATE(YEAR(L$7),MONTH(L$7),1),($D9*$E9+L9)/2*(EOMONTH(L$7,0)-$C9+1)/DAY(EOMONTH(L$7,0)),(0+L9)/2))*$F9),"N/D") -> 7795.9928 | M50: =IF(COUNT($D9,$E9,$F9,M9,L9,Supuestos!$D$45)=6,IF(1>=Supuestos!$D$45,0,IF($C9>EOMONTH(M$7,0),0,IF($C9>=DATE(YEAR(M$7),MONTH(M$7),1),($D9*$E9+M9)/2*(EOMONTH(M$7,0)-$C9+1)/DAY(EOMONTH(M$7,0)),(L9+M9)/2))*$F9),"N/D") -> 13687.917 | N50: =IF(COUNT($D9,$E9,$F9,N9,M9,Supuestos!$D$45)=6,IF(2>=Supuestos!$D$45,0,IF($C9>EOMONTH(N$7,0),0,IF($C9>=DATE(YEAR(N$7),MONTH(N$7),1),($D9*$E9+N9)/2*(EOMONTH(N$7,0)-$C9+1)/DAY(EOMONTH(N$7,0)),(M9+N9)/2))*$F9),"N/D") -> 12979.507 | O50: =IF(COUNT($D9,$E9,$F9,O9,N9,Supuestos!$D$45)=6,IF(3>=Supuestos!$D$45,0,IF($C9>EOMONTH(O$7,0),0,IF($C9>=DATE(YEAR(O$7),MONTH(O$7),1),($D9*$E9+O9)/2*(EOMONTH(O$7,0)-$C9+1)/DAY(EOMONTH(O$7,0)),(N9+O9)/2))*$F9),"N/D") -> 12367.153 | P50: =IF(COUNT($D9,$E9,$F9,P9,O9,Supuestos!$D$45)=6,IF(4>=Supuestos!$D$45,0,IF($C9>EOMONTH(P$7,0),0,IF($C9>=DATE(YEAR(P$7),MONTH(P$7),1),($D9*$E9+P9)/2*(EOMONTH(P$7,0)-$C9+1)/DAY(EOMONTH(P$7,0)),(O9+P9)/2))*$F9),"N/D") -> 12002.942 | Q50: =IF(COUNT($D9,$E9,$F9,Q9,P9,Supuestos!$D$45)=6,IF(5>=Supuestos!$D$45,0,IF($C9>EOMONTH(Q$7,0),0,IF($C9>=DATE(YEAR(Q$7),MONTH(Q$7),1),($D9*$E9+Q9)/2*(EOMONTH(Q$7,0)-$C9+1)/DAY(EOMONTH(Q$7,0)),(P9+Q9)/2))*$F9),"N/D") -> 11758.801 | R50: =IF(COUNT($D9,$E9,$F9,R9,Q9,Supuestos!$D$45)=6,IF(6>=Supuestos!$D$45,0,IF($C9>EOMONTH(R$7,0),0,IF($C9>=DATE(YEAR(R$7),MONTH(R$7),1),($D9*$E9+R9)/2*(EOMONTH(R$7,0)-$C9+1)/DAY(EOMONTH(R$7,0)),(Q9+R9)/2))*$F9),"N/D") -> 11549.599 | S50: =IF(COUNT($D9,$E9,$F9,S9,R9,Supuestos!$D$45)=6,IF(7>=Supuestos!$D$45,0,IF($C9>EOMONTH(S$7,0),0,IF($C9>=DATE(YEAR(S$7),MONTH(S$7),1),($D9*$E9+S9)/2*(EOMONTH(S$7,0)-$C9+1)/DAY(EOMONTH(S$7,0)),(R9+S9)/2))*$F9),"N/D") -> 11400.107 | T50: =IF(COUNT($D9,$E9,$F9,T9,S9,Supuestos!$D$45)=6,IF(8>=Supuestos!$D$45,0,IF($C9>EOMONTH(T$7,0),0,IF($C9>=DATE(YEAR(T$7),MONTH(T$7),1),($D9*$E9+T9)/2*(EOMONTH(T$7,0)-$C9+1)/DAY(EOMONTH(T$7,0)),(S9+T9)/2))*$F9),"N/D") -> 11281.336 | U50: =IF(COUNT($D9,$E9,$F9,U9,T9,Supuestos!$D$45)=6,IF(9>=Supuestos!$D$45,0,IF($C9>EOMONTH(U$7,0),0,IF($C9>=DATE(YEAR(U$7),MONTH(U$7),1),($D9*$E9+U9)/2*(EOMONTH(U$7,0)-$C9+1)/DAY(EOMONTH(U$7,0)),(T9+U9)/2))*$F9),"N/D") -> 11162.564 | V50: =IF(COUNT($D9,$E9,$F9,V9,U9,Supuestos!$D$45)=6,IF(10>=Supuestos!$D$45,0,IF($C9>EOMONTH(V$7,0),0,IF($C9>=DATE(YEAR(V$7),MONTH(V$7),1),($D9*$E9+V9)/2*(EOMONTH(V$7,0)-$C9+1)/DAY(EOMONTH(V$7,0)),(U9+V9)/2))*$F9),"N/D") -> 11043.793 | W50: =IF(COUNT($D9,$E9,$F9,W9,V9,Supuestos!$D$45)=6,IF(11>=Supuestos!$D$45,0,IF($C9>EOMONTH(W$7,0),0,IF($C9>=DATE(YEAR(W$7),MONTH(W$7),1),($D9*$E9+W9)/2*(EOMONTH(W$7,0)-$C9+1)/DAY(EOMONTH(W$7,0)),(V9+W9)/2))*$F9),"N/D") -> 10925.021
C51: =C10 -> 46433 | L51: =IF(COUNT($D10,$E10,$F10,L10,0,Supuestos!$D$45)=6,IF(0>=Supuestos!$D$45,0,IF($C10>EOMONTH(L$7,0),0,IF($C10>=DATE(YEAR(L$7),MONTH(L$7),1),($D10*$E10+L10)/2*(EOMONTH(L$7,0)-$C10+1)/DAY(EOMONTH(L$7,0)),(0+L10)/2))*$F10),"N/D") -> 0 | M51: =IF(COUNT($D10,$E10,$F10,M10,L10,Supuestos!$D$45)=6,IF(1>=Supuestos!$D$45,0,IF($C10>EOMONTH(M$7,0),0,IF($C10>=DATE(YEAR(M$7),MONTH(M$7),1),($D10*$E10+M10)/2*(EOMONTH(M$7,0)-$C10+1)/DAY(EOMONTH(M$7,0)),(L10+M10)/2))*$F10),"N/D") -> 7126.1215 | N51: =IF(COUNT($D10,$E10,$F10,N10,M10,Supuestos!$D$45)=6,IF(2>=Supuestos!$D$45,0,IF($C10>EOMONTH(N$7,0),0,IF($C10>=DATE(YEAR(N$7),MONTH(N$7),1),($D10*$E10+N10)/2*(EOMONTH(N$7,0)-$C10+1)/DAY(EOMONTH(N$7,0)),(M10+N10)/2))*$F10),"N/D") -> 13723.938 | O51: =IF(COUNT($D10,$E10,$F10,O10,N10,Supuestos!$D$45)=6,IF(3>=Supuestos!$D$45,0,IF($C10>EOMONTH(O$7,0),0,IF($C10>=DATE(YEAR(O$7),MONTH(O$7),1),($D10*$E10+O10)/2*(EOMONTH(O$7,0)-$C10+1)/DAY(EOMONTH(O$7,0)),(N10+O10)/2))*$F10),"N/D") -> 12991.514 | P51: =IF(COUNT($D10,$E10,$F10,P10,O10,Supuestos!$D$45)=6,IF(4>=Supuestos!$D$45,0,IF($C10>EOMONTH(P$7,0),0,IF($C10>=DATE(YEAR(P$7),MONTH(P$7),1),($D10*$E10+P10)/2*(EOMONTH(P$7,0)-$C10+1)/DAY(EOMONTH(P$7,0)),(O10+P10)/2))*$F10),"N/D") -> 12379.16 | Q51: =IF(COUNT($D10,$E10,$F10,Q10,P10,Supuestos!$D$45)=6,IF(5>=Supuestos!$D$45,0,IF($C10>EOMONTH(Q$7,0),0,IF($C10>=DATE(YEAR(Q$7),MONTH(Q$7),1),($D10*$E10+Q10)/2*(EOMONTH(Q$7,0)-$C10+1)/DAY(EOMONTH(Q$7,0)),(P10+Q10)/2))*$F10),"N/D") -> 12006.944 | R51: =IF(COUNT($D10,$E10,$F10,R10,Q10,Supuestos!$D$45)=6,IF(6>=Supuestos!$D$45,0,IF($C10>EOMONTH(R$7,0),0,IF($C10>=DATE(YEAR(R$7),MONTH(R$7),1),($D10*$E10+R10)/2*(EOMONTH(R$7,0)-$C10+1)/DAY(EOMONTH(R$7,0)),(Q10+R10)/2))*$F10),"N/D") -> 11762.803 | S51: =IF(COUNT($D10,$E10,$F10,S10,R10,Supuestos!$D$45)=6,IF(7>=Supuestos!$D$45,0,IF($C10>EOMONTH(S$7,0),0,IF($C10>=DATE(YEAR(S$7),MONTH(S$7),1),($D10*$E10+S10)/2*(EOMONTH(S$7,0)-$C10+1)/DAY(EOMONTH(S$7,0)),(R10+S10)/2))*$F10),"N/D") -> 11549.599 | T51: =IF(COUNT($D10,$E10,$F10,T10,S10,Supuestos!$D$45)=6,IF(8>=Supuestos!$D$45,0,IF($C10>EOMONTH(T$7,0),0,IF($C10>=DATE(YEAR(T$7),MONTH(T$7),1),($D10*$E10+T10)/2*(EOMONTH(T$7,0)-$C10+1)/DAY(EOMONTH(T$7,0)),(S10+T10)/2))*$F10),"N/D") -> 11402.054 | U51: =IF(COUNT($D10,$E10,$F10,U10,T10,Supuestos!$D$45)=6,IF(9>=Supuestos!$D$45,0,IF($C10>EOMONTH(U$7,0),0,IF($C10>=DATE(YEAR(U$7),MONTH(U$7),1),($D10*$E10+U10)/2*(EOMONTH(U$7,0)-$C10+1)/DAY(EOMONTH(U$7,0)),(T10+U10)/2))*$F10),"N/D") -> 11283.283 | V51: =IF(COUNT($D10,$E10,$F10,V10,U10,Supuestos!$D$45)=6,IF(10>=Supuestos!$D$45,0,IF($C10>EOMONTH(V$7,0),0,IF($C10>=DATE(YEAR(V$7),MONTH(V$7),1),($D10*$E10+V10)/2*(EOMONTH(V$7,0)-$C10+1)/DAY(EOMONTH(V$7,0)),(U10+V10)/2))*$F10),"N/D") -> 11164.511 | W51: =IF(COUNT($D10,$E10,$F10,W10,V10,Supuestos!$D$45)=6,IF(11>=Supuestos!$D$45,0,IF($C10>EOMONTH(W$7,0),0,IF($C10>=DATE(YEAR(W$7),MONTH(W$7),1),($D10*$E10+W10)/2*(EOMONTH(W$7,0)-$C10+1)/DAY(EOMONTH(W$7,0)),(V10+W10)/2))*$F10),"N/D") -> 11045.74
C52: =C11 -> 46461 | L52: =IF(COUNT($D11,$E11,$F11,L11,0,Supuestos!$D$45)=6,IF(0>=Supuestos!$D$45,0,IF($C11>EOMONTH(L$7,0),0,IF($C11>=DATE(YEAR(L$7),MONTH(L$7),1),($D11*$E11+L11)/2*(EOMONTH(L$7,0)-$C11+1)/DAY(EOMONTH(L$7,0)),(0+L11)/2))*$F11),"N/D") -> 0 | M52: =IF(COUNT($D11,$E11,$F11,M11,L11,Supuestos!$D$45)=6,IF(1>=Supuestos!$D$45,0,IF($C11>EOMONTH(M$7,0),0,IF($C11>=DATE(YEAR(M$7),MONTH(M$7),1),($D11*$E11+M11)/2*(EOMONTH(M$7,0)-$C11+1)/DAY(EOMONTH(M$7,0)),(L11+M11)/2))*$F11),"N/D") -> 0 | N52: =IF(COUNT($D11,$E11,$F11,N11,M11,Supuestos!$D$45)=6,IF(2>=Supuestos!$D$45,0,IF($C11>EOMONTH(N$7,0),0,IF($C11>=DATE(YEAR(N$7),MONTH(N$7),1),($D11*$E11+N11)/2*(EOMONTH(N$7,0)-$C11+1)/DAY(EOMONTH(N$7,0)),(M11+N11)/2))*$F11),"N/D") -> 7795.9928 | O52: =IF(COUNT($D11,$E11,$F11,O11,N11,Supuestos!$D$45)=6,IF(3>=Supuestos!$D$45,0,IF($C11>EOMONTH(O$7,0),0,IF($C11>=DATE(YEAR(O$7),MONTH(O$7),1),($D11*$E11+O11)/2*(EOMONTH(O$7,0)-$C11+1)/DAY(EOMONTH(O$7,0)),(N11+O11)/2))*$F11),"N/D") -> 13663.903 | P52: =IF(COUNT($D11,$E11,$F11,P11,O11,Supuestos!$D$45)=6,IF(4>=Supuestos!$D$45,0,IF($C11>EOMONTH(P$7,0),0,IF($C11>=DATE(YEAR(P$7),MONTH(P$7),1),($D11*$E11+P11)/2*(EOMONTH(P$7,0)-$C11+1)/DAY(EOMONTH(P$7,0)),(O11+P11)/2))*$F11),"N/D") -> 12931.479 | Q52: =IF(COUNT($D11,$E11,$F11,Q11,P11,Supuestos!$D$45)=6,IF(5>=Supuestos!$D$45,0,IF($C11>EOMONTH(Q$7,0),0,IF($C11>=DATE(YEAR(Q$7),MONTH(Q$7),1),($D11*$E11+Q11)/2*(EOMONTH(Q$7,0)-$C11+1)/DAY(EOMONTH(Q$7,0)),(P11+Q11)/2))*$F11),"N/D") -> 12335.134 | R52: =IF(COUNT($D11,$E11,$F11,R11,Q11,Supuestos!$D$45)=6,IF(6>=Supuestos!$D$45,0,IF($C11>EOMONTH(R$7,0),0,IF($C11>=DATE(YEAR(R$7),MONTH(R$7),1),($D11*$E11+R11)/2*(EOMONTH(R$7,0)-$C11+1)/DAY(EOMONTH(R$7,0)),(Q11+R11)/2))*$F11),"N/D") -> 11986.933 | S52: =IF(COUNT($D11,$E11,$F11,S11,R11,Supuestos!$D$45)=6,IF(7>=Supuestos!$D$45,0,IF($C11>EOMONTH(S$7,0),0,IF($C11>=DATE(YEAR(S$7),MONTH(S$7),1),($D11*$E11+S11)/2*(EOMONTH(S$7,0)-$C11+1)/DAY(EOMONTH(S$7,0)),(R11+S11)/2))*$F11),"N/D") -> 11738.789 | T52: =IF(COUNT($D11,$E11,$F11,T11,S11,Supuestos!$D$45)=6,IF(8>=Supuestos!$D$45,0,IF($C11>EOMONTH(T$7,0),0,IF($C11>=DATE(YEAR(T$7),MONTH(T$7),1),($D11*$E11+T11)/2*(EOMONTH(T$7,0)-$C11+1)/DAY(EOMONTH(T$7,0)),(S11+T11)/2))*$F11),"N/D") -> 11533.698 | U52: =IF(COUNT($D11,$E11,$F11,U11,T11,Supuestos!$D$45)=6,IF(9>=Supuestos!$D$45,0,IF($C11>EOMONTH(U$7,0),0,IF($C11>=DATE(YEAR(U$7),MONTH(U$7),1),($D11*$E11+U11)/2*(EOMONTH(U$7,0)-$C11+1)/DAY(EOMONTH(U$7,0)),(T11+U11)/2))*$F11),"N/D") -> 11392.319 | V52: =IF(COUNT($D11,$E11,$F11,V11,U11,Supuestos!$D$45)=6,IF(10>=Supuestos!$D$45,0,IF($C11>EOMONTH(V$7,0),0,IF($C11>=DATE(YEAR(V$7),MONTH(V$7),1),($D11*$E11+V11)/2*(EOMONTH(V$7,0)-$C11+1)/DAY(EOMONTH(V$7,0)),(U11+V11)/2))*$F11),"N/D") -> 11273.547 | W52: =IF(COUNT($D11,$E11,$F11,W11,V11,Supuestos!$D$45)=6,IF(11>=Supuestos!$D$45,0,IF($C11>EOMONTH(W$7,0),0,IF($C11>=DATE(YEAR(W$7),MONTH(W$7),1),($D11*$E11+W11)/2*(EOMONTH(W$7,0)-$C11+1)/DAY(EOMONTH(W$7,0)),(V11+W11)/2))*$F11),"N/D") -> 11154.776
